Workbook
Name LISTA_COLORES: COLORES!$A$4:$A$53
Name LISTA_CLIENTES: CLIENTES!$A$4:$A$18
Name LISTA_PRODUCTOS: PRODUCTOS!$A$4:$A$28

Sheet COBROS_DIARIOS
A1: COBROS DIARIOS — Una fila por entrega/cobro
A2: Cantidades en columnas S/M/L/XL, el TOTAL se suma automático. COLOR dropdown.
A3: FECHA | B3: N° CORTE | C3: N° FACTURA | D3: CLIENTE | E3: PRODUCTO | F3: COLOR | G3: S | H3: M | I3: L | J3: XL | K3: TOTAL (auto) | L3: PRECIO UNIT (auto) | M3: BRUTO (auto) | N3: DETRACCIÓN 10% | O3: DISPONIBLE 90% | P3: ESTADO | Q3: NOTAS
A4: 46146 | B4: q | C4: 1234 | D4: OverShark | E4: baby ty ml | F4: Perla | G4: 32 | H4: 62 | K4: 94 | L4: =IFERROR(VLOOKUP(E4,PRODUCTOS!$A$4:$F$28,6,FALSE()),0) -> 1.7 | M4: =IFERROR(K4*L4,0) -> 159.8 | N4: =IFERROR(M4*CONFIG!$B$4,0) -> 15.98 | O4: =IFERROR(M4-N4,0) -> 143.82 | P4: PENDIENTE
A5: 46146 | B5: q | C5: 1234 | D5: OverShark | E5: baby ty ml | F5: Vino | G5: 54 | I5: 56 | K5: 110 | L5: =IFERROR(VLOOKUP(E5,PRODUCTOS!$A$4:$F$28,6,FALSE()),0) -> 1.7 | M5: =IFERROR(K5*L5,0) -> 187 | N5: =IFERROR(M5*CONFIG!$B$4,0) -> 18.7 | O5: =IFERROR(M5-N5,0) -> 168.3 | P5: PENDIENTE
A6: 46146 | B6: q | C6: 1234 | D6: OverShark | E6: pique camisero | F6: Azul Marino | H6: 8 | I6: 25 | J6: 5 | K6: 38 | L6: =IFERROR(VLOOKUP(E6,PRODUCTOS!$A$4:$F$28,6,FALSE()),0) -> 4 | M6: =IFERROR(K6*L6,0) -> 152 | N6: =IFERROR(M6*CONFIG!$B$4,0) -> 15.2 | O6: =IFERROR(M6-N6,0) -> 136.8 | P6: PENDIENTE
A7: 46146 | B7: q | C7: 1234 | D7: OverShark | E7: jersey manga corta | F7: Denim | G7: 82 | H7: 165 | J7: 80 | K7: 327 | L7: =IFERROR(VLOOKUP(E7,PRODUCTOS!$A$4:$F$28,6,FALSE()),0) -> 1.7 | M7: =IFERROR(K7*L7,0) -> 555.9 | N7: =IFERROR(M7*CONFIG!$B$4,0) -> 55.59 | O7: =IFERROR(M7-N7,0) -> 500.31 | P7: PENDIENTE
A8: 46146 | B8: q | C8: 1234 | D8: OverShark | E8: wafle clasico | F8: Beige | G8: 64 | H8: 137 | I8: 134 | J8: 69 | K8: 404 | L8: =IFERROR(VLOOKUP(E8,PRODUCTOS!$A$4:$F$28,6,FALSE()),0) -> 1.7 | M8: =IFERROR(K8*L8,0) -> 686.8 | N8: =IFERROR(M8*CONFIG!$B$4,0) -> 68.68 | O8: =IFERROR(M8-N8,0) -> 618.12 | P8: PENDIENTE
A9: 46146 | B9: q | C9: 1234 | D9: Bravos | E9: polera neru | F9: Perla | G9: 80 | K9: 80 | L9: =IFERROR(VLOOKUP(E9,PRODUCTOS!$A$4:$F$28,6,FALSE()),0) -> 6 | M9: =IFERROR(K9*L9,0) -> 480 | N9: =IFERROR(M9*CONFIG!$B$4,0) -> 48 | O9: =IFERROR(M9-N9,0) -> 432 | P9: PENDIENTE
A10: 46146 | B10: q | C10: 1234 | D10: Bravos | E10: Polera Boxy | F10: Negro | G10: 58 | H10: 62 | I10: 49 | K10: 169 | L10: =IFERROR(VLOOKUP(E10,PRODUCTOS!$A$4:$F$28,6,FALSE()),0) -> 4 | M10: =IFERROR(K10*L10,0) -> 676 | N10: =IFERROR(M10*CONFIG!$B$4,0) -> 67.6 | O10: =IFERROR(M10-N10,0) -> 608.4 | P10: PENDIENTE
A11: 46146 | B11: q | C11: 1234 | D11: Bravos | E11: polera neru | F11: Perla | G11: 10 | K11: 10 | L11: =IFERROR(VLOOKUP(E11,PRODUCTOS!$A$4:$F$28,6,FALSE()),0) -> 6 | M11: =IFERROR(K11*L11,0) -> 60 | N11: =IFERROR(M11*CONFIG!$B$4,0) -> 6 | O11: =IFERROR(M11-N11,0) -> 54 | P11: PENDIENTE
A12: 46146 | B12: q | C12: 1234 | D12: Bravos | E12: polera neru | F12: Negro | G12: 1 | K12: 1 | L12: =IFERROR(VLOOKUP(E12,PRODUCTOS!$A$4:$F$28,6,FALSE()),0) -> 6 | M12: =IFERROR(K12*L12,0) -> 6 | N12: =IFERROR(M12*CONFIG!$B$4,0) -> 0.6 | O12: =IFERROR(M12-N12,0) -> 5.4 | P12: PENDIENTE
A13: 46146 | B13: q | C13: 1234 | D13: OverShark | E13: jersey manga corta | F13: Denim | I13: 156 | K13: 156 | L13: =IFERROR(VLOOKUP(E13,PRODUCTOS!$A$4:$F$28,6,FALSE()),0) -> 1.7 | M13: =IFERROR(K13*L13,0) -> 265.2 | N13: =IFERROR(M13*CONFIG!$B$4,0) -> 26.52 | O13: =IFERROR(M13-N13,0) -> 238.68 | P13: PENDIENTE
A14: 46146 | B14: q | C14: 1234 | D14: OverShark | E14: wafle clasico | F14: P. Rosa | G14: 17 | H14: 36 | I14: 34 | J14: 18 | K14: 105 | L14: =IFERROR(VLOOKUP(E14,PRODUCTOS!$A$4:$F$28,6,FALSE()),0) -> 1.7 | M14: =IFERROR(K14*L14,0) -> 178.5 | N14: =IFERROR(M14*CONFIG!$B$4,0) -> 17.85 | O14: =IFERROR(M14-N14,0) -> 160.65 | P14: PENDIENTE
A15: 46146 | B15: q | C15: 1234 | D15: OverShark | E15: wafle clasico | F15: Denim | G15: 33 | I15: 68 | J15: 34 | K15: 135 | L15: =IFERROR(VLOOKUP(E15,PRODUCTOS!$A$4:$F$28,6,FALSE()),0) -> 1.7 | M15: =IFERROR(K15*L15,0) -> 229.5 | N15: =IFERROR(M15*CONFIG!$B$4,0) -> 22.95 | O15: =IFERROR(M15-N15,0) -> 206.55 | P15: PENDIENTE
A16: 46147 | B16: q | C16: 1234 | D16: Bravos | E16: Polera Boxy | F16: Vino | H16: 60 | K16: 60 | L16: =IFERROR(VLOOKUP(E16,PRODUCTOS!$A$4:$F$28,6,FALSE()),0) -> 4 | M16: =IFERROR(K16*L16,0) -> 240 | N16: =IFERROR(M16*CONFIG!$B$4,0) -> 24 | O16: =IFERROR(M16-N16,0) -> 216 | P16: PENDIENTE
A17: 46147 | B17: q | C17: 1234 | D17: Bravos | E17: Polera Boxy | F17: Negro | G17: 2 | H17: 2 | I17: 1 | K17: 5 | L17: =IFERROR(VLOOKUP(E17,PRODUCTOS!$A$4:$F$28,6,FALSE()),0) -> 4 | M17: =IFERROR(K17*L17,0) -> 20 | N17: =IFERROR(M17*CONFIG!$B$4,0) -> 2 | O17: =IFERROR(M17-N17,0) -> 18 | P17: PENDIENTE
A18: 46147 | B18: q | C18: 1234 | D18: OverShark | E18: jersey manga corta | F18: Vino | G18: 59 | H18: 118 | I18: 118 | J18: 58 | K18: 353 | L18: =IFERROR(VLOOKUP(E18,PRODUCTOS!$A$4:$F$28,6,FALSE()),0) -> 1.7 | M18: =IFERROR(K18*L18,0) -> 600.1 | N18: =IFERROR(M18*CONFIG!$B$4,0) -> 60.01 | O18: =IFERROR(M18-N18,0) -> 540.09 | P18: PENDIENTE
A19: 46147 | B19: q | C19: 1234 | D19: OverShark | E19: jersey manga corta | F19: Topo | I19: 152 | K19: 152 | L19: =IFERROR(VLOOKUP(E19,PRODUCTOS!$A$4:$F$28,6,FALSE()),0) -> 1.7 | M19: =IFERROR(K19*L19,0) -> 258.4 | N19: =IFERROR(M19*CONFIG!$B$4,0) -> 25.84 | O19: =IFERROR(M19-N19,0) -> 232.56 | P19: PENDIENTE
A20: 46147 | B20: q | C20: 1234 | D20: OverShark | E20: jersey manga corta | F20: Azul Marino | H20: 71 | I20: 72 | J20: 35 | K20: 178 | L20: =IFERROR(VLOOKUP(E20,PRODUCTOS!$A$4:$F$28,6,FALSE()),0) -> 1.7 | M20: =IFERROR(K20*L20,0) -> 302.6 | N20: =IFERROR(M20*CONFIG!$B$4,0) -> 30.26 | O20: =IFERROR(M20-N20,0) -> 272.34 | P20: PENDIENTE
A21: 46147 | B21: q | C21: 1234 | D21: OverShark | E21: pique camisero | F21: Negro | I21: 123 | J21: 90 | K21: 213 | L21: =IFERROR(VLOOKUP(E21,PRODUCTOS!$A$4:$F$28,6,FALSE()),0) -> 4 | M21: =IFERROR(K21*L21,0) -> 852 | N21: =IFERROR(M21*CONFIG!$B$4,0) -> 85.2 | O21: =IFERROR(M21-N21,0) -> 766.8 | P21: PENDIENTE
A22: 46147 | B22: q | C22: 1234 | D22: OverShark | E22: Baby Tee con S | F22: Negro | G22: 47 | H22: 48 | I22: 47 | K22: 142 | L22: =IFERROR(VLOOKUP(E22,PRODUCTOS!$A$4:$F$28,6,FALSE()),0) -> 1.7 | M22: =IFERROR(K22*L22,0) -> 241.4 | N22: =IFERROR(M22*CONFIG!$B$4,0) -> 24.14 | O22: =IFERROR(M22-N22,0) -> 217.26 | P22: PENDIENTE
A23: 46147 | B23: q | C23: 1234 | D23: OverShark | E23: Baby Tee M/L S | F23: Negro | G23: 48 | H23: 48 | I23: 48 | K23: 144 | L23: =IFERROR(VLOOKUP(E23,PRODUCTOS!$A$4:$F$28,6,FALSE()),0) -> 1.7 | M23: =IFERROR(K23*L23,0) -> 244.8 | N23: =IFERROR(M23*CONFIG!$B$4,0) -> 24.48 | O23: =IFERROR(M23-N23,0) -> 220.32 | P23: PENDIENTE
A24: 46147 | B24: q | C24: 1234 | D24: OverShark | E24: pique camisero | F24: Negro | H24: 118 | K24: 118 | L24: =IFERROR(VLOOKUP(E24,PRODUCTOS!$A$4:$F$28,6,FALSE()),0) -> 4 | M24: =IFERROR(K24*L24,0) -> 472 | N24: =IFERROR(M24*CONFIG!$B$4,0) -> 47.2 | O24: =IFERROR(M24-N24,0) -> 424.8 | P24: PENDIENTE
A25: 46147 | B25: q | C25: 1234 | D25: OverShark | E25: Baby Tee con S | F25: Azul Marino | I25: 69 | K25: 69 | L25: =IFERROR(VLOOKUP(E25,PRODUCTOS!$A$4:$F$28,6,FALSE()),0) -> 1.7 | M25: =IFERROR(K25*L25,0) -> 117.3 | N25: =IFERROR(M25*CONFIG!$B$4,0) -> 11.73 | O25: =IFERROR(M25-N25,0) -> 105.57 | P25: PENDIENTE
A26: 46147 | B26: q | C26: 1234 | D26: OverShark | E26: jersey manga corta | F26: Negro | G26: 50 | H26: 85 | K26: 135 | L26: =IFERROR(VLOOKUP(E26,PRODUCTOS!$A$4:$F$28,6,FALSE()),0) -> 1.7 | M26: =IFERROR(K26*L26,0) -> 229.5 | N26: =IFERROR(M26*CONFIG!$B$4,0) -> 22.95 | O26: =IFERROR(M26-N26,0) -> 206.55 | P26: PENDIENTE
A27: 46147 | B27: q | C27: 1234 | D27: OverShark | E27: Baby Tee con S | F27: Vino | H27: 55 | K27: 55 | L27: =IFERROR(VLOOKUP(E27,PRODUCTOS!$A$4:$F$28,6,FALSE()),0) -> 1.7 | M27: =IFERROR(K27*L27,0) -> 93.5 | N27: =IFERROR(M27*CONFIG!$B$4,0) -> 9.35 | O27: =IFERROR(M27-N27,0) -> 84.15 | P27: PENDIENTE
A28: 46147 | B28: q | C28: 1234 | D28: OverShark | E28: Baby Tee M/L S | F28: Azul Marino | H28: 69 | K28: 69 | L28: =IFERROR(VLOOKUP(E28,PRODUCTOS!$A$4:$F$28,6,FALSE()),0) -> 1.7 | M28: =IFERROR(K28*L28,0) -> 117.3 | N28: =IFERROR(M28*CONFIG!$B$4,0) -> 11.73 | O28: =IFERROR(M28-N28,0) -> 105.57 | P28: PENDIENTE
A29: 46147 | B29: q | C29: 1234 | D29: OverShark | E29: Baby Tee con S | F29: Colegial | H29: 55 | K29: 55 | L29: =IFERROR(VLOOKUP(E29,PRODUCTOS!$A$4:$F$28,6,FALSE()),0) -> 1.7 | M29: =IFERROR(K29*L29,0) -> 93.5 | N29: =IFERROR(M29*CONFIG!$B$4,0) -> 9.35 | O29: =IFERROR(M29-N29,0) -> 84.15 | P29: PENDIENTE
A30: 46147 | B30: q | C30: 1234 | D30: OverShark | E30: Baby Tee M/L S | F30: Azul Marino | G30: 70 | K30: 70 | L30: =IFERROR(VLOOKUP(E30,PRODUCTOS!$A$4:$F$28,6,FALSE()),0) -> 1.7 | M30: =IFERROR(K30*L30,0) -> 119 | N30: =IFERROR(M30*CONFIG!$B$4,0) -> 11.9 | O30: =IFERROR(M30-N30,0) -> 107.1 | P30: PENDIENTE
A31: 46147 | B31: q | C31: 1234 | D31: OverShark | E31: Baby Tee M/L S | F31: V. Pacay | G31: 26 | H31: 23 | I31: 27 | K31: 76 | L31: =IFERROR(VLOOKUP(E31,PRODUCTOS!$A$4:$F$28,6,FALSE()),0) -> 1.7 | M31: =IFERROR(K31*L31,0) -> 129.2 | N31: =IFERROR(M31*CONFIG!$B$4,0) -> 12.92 | O31: =IFERROR(M31-N31,0) -> 116.28 | P31: PENDIENTE
A32: 46147 | B32: q | C32: 1234 | D32: OverShark | E32: Baby Tee con S | F32: Azul Marino | G32: 68 | H32: 67 | K32: 135 | L32: =IFERROR(VLOOKUP(E32,PRODUCTOS!$A$4:$F$28,6,FALSE()),0) -> 1.7 | M32: =IFERROR(K32*L32,0) -> 229.5 | N32: =IFERROR(M32*CONFIG!$B$4,0) -> 22.95 | O32: =IFERROR(M32-N32,0) -> 206.55 | P32: PENDIENTE
A33: 46147 | B33: q | C33: 1234 | D33: OverShark | E33: Baby Tee M/L S | F33: Vino | G33: 55 | H33: 55 | I33: 54 | K33: 164 | L33: =IFERROR(VLOOKUP(E33,PRODUCTOS!$A$4:$F$28,6,FALSE()),0) -> 1.7 | M33: =IFERROR(K33*L33,0) -> 278.8 | N33: =IFERROR(M33*CONFIG!$B$4,0) -> 27.88 | O33: =IFERROR(M33-N33,0) -> 250.92 | P33: PENDIENTE
A34: 46147 | B34: q | C34: 1234 | D34: OverShark | E34: Baby Tee con S | F34: V. Pacay | G34: 25 | H34: 25 | I34: 26 | K34: 76 | L34: =IFERROR(VLOOKUP(E34,PRODUCTOS!$A$4:$F$28,6,FALSE()),0) -> 1.7 | M34: =IFERROR(K34*L34,0) -> 129.2 | N34: =IFERROR(M34*CONFIG!$B$4,0) -> 12.92 | O34: =IFERROR(M34-N34,0) -> 116.28 | P34: PENDIENTE
A35: 46147 | B35: q | C35: 1234 | D35: OverShark | E35: wafle clasico | F35: Denim | H35: 68 | K35: 68 | L35: =IFERROR(VLOOKUP(E35,PRODUCTOS!$A$4:$F$28,6,FALSE()),0) -> 1.7 | M35: =IFERROR(K35*L35,0) -> 115.6 | N35: =IFERROR(M35*CONFIG!$B$4,0) -> 11.56 | O35: =IFERROR(M35-N35,0) -> 104.04 | P35: PENDIENTE
A36: 46147 | B36: q | C36: 1234 | D36: OverShark | E36: Baby Tee M/L S | F36: Colegial | H36: 58 | K36: 58 | L36: =IFERROR(VLOOKUP(E36,PRODUCTOS!$A$4:$F$28,6,FALSE()),0) -> 1.7 | M36: =IFERROR(K36*L36,0) -> 98.6 | N36: =IFERROR(M36*CONFIG!$B$4,0) -> 9.86 | O36: =IFERROR(M36-N36,0) -> 88.74 | P36: PENDIENTE
A37: 46147 | B37: q | C37: 1234 | D37: OverShark | E37: Baby Tee con S | F37: Colegial | I37: 54 | K37: 54 | L37: =IFERROR(VLOOKUP(E37,PRODUCTOS!$A$4:$F$28,6,FALSE()),0) -> 1.7 | M37: =IFERROR(K37*L37,0) -> 91.8 | N37: =IFERROR(M37*CONFIG!$B$4,0) -> 9.18 | O37: =IFERROR(M37-N37,0) -> 82.62 | P37: PENDIENTE
A38: 46147 | B38: q | C38: 1234 | D38: OverShark | E38: Baby Tee con S | F38: Vino | G38: 55 | I38: 56 | K38: 111 | L38: =IFERROR(VLOOKUP(E38,PRODUCTOS!$A$4:$F$28,6,FALSE()),0) -> 1.7 | M38: =IFERROR(K38*L38,0) -> 188.7 | N38: =IFERROR(M38*CONFIG!$B$4,0) -> 18.87 | O38: =IFERROR(M38-N38,0) -> 169.83 | P38: PENDIENTE
A39: 46147 | B39: q | C39: 1234 | D39: OverShark | E39: Baby Tee M/L S | F39: Perla | H39: 62 | K39: 62 | L39: =IFERROR(VLOOKUP(E39,PRODUCTOS!$A$4:$F$28,6,FALSE()),0) -> 1.7 | M39: =IFERROR(K39*L39,0) -> 105.4 | N39: =IFERROR(M39*CONFIG!$B$4,0) -> 10.54 | O39: =IFERROR(M39-N39,0) -> 94.86 | P39: PENDIENTE
A40: 46147 | B40: q | C40: 1234 | D40: OverShark | E40: Baby Tee con S | F40: Perla | G40: 60 | H40: 60 | K40: 120 | L40: =IFERROR(VLOOKUP(E40,PRODUCTOS!$A$4:$F$28,6,FALSE()),0) -> 1.7 | M40: =IFERROR(K40*L40,0) -> 204 | N40: =IFERROR(M40*CONFIG!$B$4,0) -> 20.4 | O40: =IFERROR(M40-N40,0) -> 183.6 | P40: PENDIENTE
...

Sheet Hoja 1

Sheet INSTRUCCIONES
A1: COBROS TALLER — Cuánto cobrar al cliente x prenda
A3: PROPÓSITO:
A4: Saber cuánto debes cobrar al cliente por cada prenda que confeccionas,
A5: considerando tu costo de mano de obra interno, el margen que quieres ganar
A6: y la detracción del 10% que se aplica en Perú.
A8: CÓMO USAR:
A9: 1) PRODUCTOS — tabla con todos los productos del taller.
A10: • Llena COSTO MO (lo que pagas a los costureros por hacer 1 prenda)
A11: • Llena PRECIO VENTA ACTUAL (lo que estás cobrando hoy al cliente)
A12: • El sistema calcula PRECIO RECOMENDADO según margen + detracción.
A14: 2) COBROS_DIARIOS — registro diario.
A15: • Una fila por entrega/cobro. Pones fecha, cliente, producto, cantidad.
... A33: • "DISPONIBLE INMEDIATO" = 90% que entra a tu cuenta corriente al toque

Sheet CONFIG
A1: CONFIGURACIÓN
A2: Parámetro | B2: Valor | C2: Descripción
A3: Margen objetivo (sobre costo MO) | B3: 0.4 | C3: Margen deseado: 40% sobre costo MO
A4: Detracción (%) | B4: 0.1 | C4: 10% se retiene para cuenta de detracción
A5: IGV (%) | B5: 0.18 | C5: 18% en Perú (opcional, si emites factura)
A6: Incluir IGV en precio sugerido | B6: NO | C6: SÍ/NO. Si SÍ, suma 18% al precio sugerido

Sheet PRODUCTOS
A1: PRODUCTOS — Costos y precios de confección
A2: COSTO MO = lo que pagas en mano de obra por hacer 1 prenda. PRECIO VENTA = lo que cobras al cliente.
A3: PRODUCTO | B3: COSTO MO (interno) S/. | C3: MARGEN % | D3: PRECIO BASE (auto) | E3: PRECIO SUGERIDO (costo + margen) | F3: PRECIO VENTA ACTUAL S/. | G3: + Detracc. (auto) | H3: DISPONIBLE INMEDIATO 90% | I3: MARGEN REAL (vs costo)
A4: jersey manga corta | B4: 0.95 | C4: =CONFIG!$B$3 -> 0.4 | D4: =IFERROR(B4*(1+C4),0) -> 1.33 | E4: =IFERROR(IF(B4="","",IF(CONFIG!$B$6="SÍ",D4*(1+CONFIG!$B$5),D4)),"") -> 1.33 | F4: 1.7 | G4: =IFERROR(F4*CONFIG!$B$4,0) -> 0.17 | H4: =IFERROR(F4-G4,0) -> 1.53 | I4: =IFERROR(IF(F4>0,(F4-B4)/F4,""),"") -> 0.44117647
A5: jersey manga larga | B5: 1 | C5: =CONFIG!$B$3 -> 0.4 | D5: =IFERROR(B5*(1+C5),0) -> 1.4 | E5: =IFERROR(IF(B5="","",IF(CONFIG!$B$6="SÍ",D5*(1+CONFIG!$B$5),D5)),"") -> 1.4 | F5: 2 | G5: =IFERROR(F5*CONFIG!$B$4,0) -> 0.2 | H5: =IFERROR(F5-G5,0) -> 1.8 | I5: =IFERROR(IF(F5>0,(F5-B5)/F5,""),"") -> 0.5
A6: wafle clasico | B6: 0.95 | C6: =CONFIG!$B$3 -> 0.4 | D6: =IFERROR(B6*(1+C6),0) -> 1.33 | E6: =IFERROR(IF(B6="","",IF(CONFIG!$B$6="SÍ",D6*(1+CONFIG!$B$5),D6)),"") -> 1.33 | F6: 1.7 | G6: =IFERROR(F6*CONFIG!$B$4,0) -> 0.17 | H6: =IFERROR(F6-G6,0) -> 1.53 | I6: =IFERROR(IF(F6>0,(F6-B6)/F6,""),"") -> 0.44117647
A7: wafle manga larga | B7: 1 | C7: =CONFIG!$B$3 -> 0.4 | D7: =IFERROR(B7*(1+C7),0) -> 1.4 | E7: =IFERROR(IF(B7="","",IF(CONFIG!$B$6="SÍ",D7*(1+CONFIG!$B$5),D7)),"") -> 1.4 | F7: 2 | G7: =IFERROR(F7*CONFIG!$B$4,0) -> 0.2 | H7: =IFERROR(F7-G7,0) -> 1.8 | I7: =IFERROR(IF(F7>0,(F7-B7)/F7,""),"") -> 0.5
A8: wafle camisero | B8: 1.96 | C8: =CONFIG!$B$3 -> 0.4 | D8: =IFERROR(B8*(1+C8),0) -> 2.744 | E8: =IFERROR(IF(B8="","",IF(CONFIG!$B$6="SÍ",D8*(1+CONFIG!$B$5),D8)),"") -> 2.744 | F8: 4 | G8: =IFERROR(F8*CONFIG!$B$4,0) -> 0.4 | H8: =IFERROR(F8-G8,0) -> 3.6 | I8: =IFERROR(IF(F8>0,(F8-B8)/F8,""),"") -> 0.51
A9: pique camisero | B9: 1.96 | C9: =CONFIG!$B$3 -> 0.4 | D9: =IFERROR(B9*(1+C9),0) -> 2.744 | E9: =IFERROR(IF(B9="","",IF(CONFIG!$B$6="SÍ",D9*(1+CONFIG!$B$5),D9)),"") -> 2.744 | F9: 4 | G9: =IFERROR(F9*CONFIG!$B$4,0) -> 0.4 | H9: =IFERROR(F9-G9,0) -> 3.6 | I9: =IFERROR(IF(F9>0,(F9-B9)/F9,""),"") -> 0.51
A10: top cero rib | B10: 0.74 | C10: =CONFIG!$B$3 -> 0.4 | D10: =IFERROR(B10*(1+C10),0) -> 1.036 | E10: =IFERROR(IF(B10="","",IF(CONFIG!$B$6="SÍ",D10*(1+CONFIG!$B$5),D10)),"") -> 1.036 | F10: 1.1 | G10: =IFERROR(F10*CONFIG!$B$4,0) -> 0.11 | H10: =IFERROR(F10-G10,0) -> 0.99 | I10: =IFERROR(IF(F10>0,(F10-B10)/F10,""),"") -> 0.32727273
A11: top mc rib | B11: 0.8 | C11: =CONFIG!$B$3 -> 0.4 | D11: =IFERROR(B11*(1+C11),0) -> 1.12 | E11: =IFERROR(IF(B11="","",IF(CONFIG!$B$6="SÍ",D11*(1+CONFIG!$B$5),D11)),"") -> 1.12 | F11: 1.7 | G11: =IFERROR(F11*CONFIG!$B$4,0) -> 0.17 | H11: =IFERROR(F11-G11,0) -> 1.53 | I11: =IFERROR(IF(F11>0,(F11-B11)/F11,""),"") -> 0.52941176
A12: top ml rib | B12: 0.85 | C12: =CONFIG!$B$3 -> 0.4 | D12: =IFERROR(B12*(1+C12),0) -> 1.19 | E12: =IFERROR(IF(B12="","",IF(CONFIG!$B$6="SÍ",D12*(1+CONFIG!$B$5),D12)),"") -> 1.19 | F12: 1.7 | G12: =IFERROR(F12*CONFIG!$B$4,0) -> 0.17 | H12: =IFERROR(F12-G12,0) -> 1.53 | I12: =IFERROR(IF(F12>0,(F12-B12)/F12,""),"") -> 0.5
A13: baby ty mc | B13: 0.76 | C13: =CONFIG!$B$3 -> 0.4 | D13: =IFERROR(B13*(1+C13),0) -> 1.064 | E13: =IFERROR(IF(B13="","",IF(CONFIG!$B$6="SÍ",D13*(1+CONFIG!$B$5),D13)),"") -> 1.064 | F13: 1.7 | G13: =IFERROR(F13*CONFIG!$B$4,0) -> 0.17 | H13: =IFERROR(F13-G13,0) -> 1.53 | I13: =IFERROR(IF(F13>0,(F13-B13)/F13,""),"") -> 0.55294118
A14: baby ty ml | B14: 0.83 | C14: =CONFIG!$B$3 -> 0.4 | D14: =IFERROR(B14*(1+C14),0) -> 1.162 | E14: =IFERROR(IF(B14="","",IF(CONFIG!$B$6="SÍ",D14*(1+CONFIG!$B$5),D14)),"") -> 1.162 | F14: 1.7 | G14: =IFERROR(F14*CONFIG!$B$4,0) -> 0.17 | H14: =IFERROR(F14-G14,0) -> 1.53 | I14: =IFERROR(IF(F14>0,(F14-B14)/F14,""),"") -> 0.51176471
A15: Baby Tee con S | B15: 0.64 | C15: =CONFIG!$B$3 -> 0.4 | D15: =IFERROR(B15*(1+C15),0) -> 0.896 | E15: =IFERROR(IF(B15="","",IF(CONFIG!$B$6="SÍ",D15*(1+CONFIG!$B$5),D15)),"") -> 0.896 | F15: 1.7 | G15: =IFERROR(F15*CONFIG!$B$4,0) -> 0.17 | H15: =IFERROR(F15-G15,0) -> 1.53 | I15: =IFERROR(IF(F15>0,(F15-B15)/F15,""),"") -> 0.62352941
... A18: polera boxy | B18: 1.66 | C18: =CONFIG!$B$3 -> 0.4 | D18: =IFERROR(B18*(1+C18),0) -> 2.324 | E18: =IFERROR(IF(B18="","",IF(CONFIG!$B$6="SÍ",D18*(1+CONFIG!$B$5),D18)),"") -> 2.324 | F18: 4 | G18: =IFERROR(F18*CONFIG!$B$4,0) -> 0.4 | H18: =IFERROR(F18-G18,0) -> 3.6 | I18: =IFERROR(IF(F18>0,(F18-B18)/F18,""),"") -> 0.585
A19: pique cuello chino | B19: 1.53 | C19: =CONFIG!$B$3 -> 0.4 | D19: =IFERROR(B19*(1+C19),0) -> 2.142 | E19: =IFERROR(IF(B19="","",IF(CONFIG!$B$6="SÍ",D19*(1+CONFIG!$B$5),D19)),"") -> 2.142 | G19: =IFERROR(F19*CONFIG!$B$4,0) -> 0 | H19: =IFERROR(F19-G19,0) -> 0 | I19: =IFERROR(IF(F19>0,(F19-B19)/F19,""),"")
A20: wafle camisa | B20: 1.91 | C20: =CONFIG!$B$3 -> 0.4 | D20: =IFERROR(B20*(1+C20),0) -> 2.674 | E20: =IFERROR(IF(B20="","",IF(CONFIG!$B$6="SÍ",D20*(1+CONFIG!$B$5),D20)),"") -> 2.674 | G20: =IFERROR(F20*CONFIG!$B$4,0) -> 0 | H20: =IFERROR(F20-G20,0) -> 0 | I20: =IFERROR(IF(F20>0,(F20-B20)/F20,""),"")
C21: =CONFIG!$B$3 -> 0.4 | D21: =IFERROR(B21*(1+C21),0) -> 0 | E21: =IFERROR(IF(B21="","",IF(CONFIG!$B$6="SÍ",D21*(1+CONFIG!$B$5),D21)),"") | G21: =IFERROR(F21*CONFIG!$B$4,0) -> 0 | H21: =IFERROR(F21-G21,0) -> 0 | I21: =IFERROR(IF(F21>0,(F21-B21)/F21,""),"")
C22: =CONFIG!$B$3 -> 0.4 | D22: =IFERROR(B22*(1+C22),0) -> 0 | E22: =IFERROR(IF(B22="","",IF(CONFIG!$B$6="SÍ",D22*(1+CONFIG!$B$5),D22)),"") | G22: =IFERROR(F22*CONFIG!$B$4,0) -> 0 | H22: =IFERROR(F22-G22,0) -> 0 | I22: =IFERROR(IF(F22>0,(F22-B22)/F22,""),"")
C23: =CONFIG!$B$3 -> 0.4 | D23: =IFERROR(B23*(1+C23),0) -> 0 | E23: =IFERROR(IF(B23="","",IF(CONFIG!$B$6="SÍ",D23*(1+CONFIG!$B$5),D23)),"") | G23: =IFERROR(F23*CONFIG!$B$4,0) -> 0 | H23: =IFERROR(F23-G23,0) -> 0 | I23: =IFERROR(IF(F23>0,(F23-B23)/F23,""),"")
C24: =CONFIG!$B$3 -> 0.4 | D24: =IFERROR(B24*(1+C24),0) -> 0 | E24: =IFERROR(IF(B24="","",IF(CONFIG!$B$6="SÍ",D24*(1+CONFIG!$B$5),D24)),"") | G24: =IFERROR(F24*CONFIG!$B$4,0) -> 0 | H24: =IFERROR(F24-G24,0) -> 0 | I24: =IFERROR(IF(F24>0,(F24-B24)/F24,""),"")
C25: =CONFIG!$B$3 -> 0.4 | D25: =IFERROR(B25*(1+C25),0) -> 0 | E25: =IFERROR(IF(B25="","",IF(CONFIG!$B$6="SÍ",D25*(1+CONFIG!$B$5),D25)),"") | G25: =IFERROR(F25*CONFIG!$B$4,0) -> 0 | H25: =IFERROR(F25-G25,0) -> 0 | I25: =IFERROR(IF(F25>0,(F25-B25)/F25,""),"")
C26: =CONFIG!$B$3 -> 0.4 | D26: =IFERROR(B26*(1+C26),0) -> 0 | E26: =IFERROR(IF(B26="","",IF(CONFIG!$B$6="SÍ",D26*(1+CONFIG!$B$5),D26)),"") | G26: =IFERROR(F26*CONFIG!$B$4,0) -> 0 | H26: =IFERROR(F26-G26,0) -> 0 | I26: =IFERROR(IF(F26>0,(F26-B26)/F26,""),"")
C27: =CONFIG!$B$3 -> 0.4 | D27: =IFERROR(B27*(1+C27),0) -> 0 | E27: =IFERROR(IF(B27="","",IF(CONFIG!$B$6="SÍ",D27*(1+CONFIG!$B$5),D27)),"") | G27: =IFERROR(F27*CONFIG!$B$4,0) -> 0 | H27: =IFERROR(F27-G27,0) -> 0 | I27: =IFERROR(IF(F27>0,(F27-B27)/F27,""),"")
C28: =CONFIG!$B$3 -> 0.4 | D28: =IFERROR(B28*(1+C28),0) -> 0 | E28: =IFERROR(IF(B28="","",IF(CONFIG!$B$6="SÍ",D28*(1+CONFIG!$B$5),D28)),"") | G28: =IFERROR(F28*CONFIG!$B$4,0) -> 0 | H28: =IFERROR(F28-G28,0) -> 0 | I28: =IFERROR(IF(F28>0,(F28-B28)/F28,""),"")

Sheet CLIENTES
A1: CLIENTES — Catálogo
A3: CLIENTE | B3: CONTACTO | C3: TELÉFONO/EMAIL | D3: NOTAS
A4: OverShark | D4: Cliente principal
A5: Bravos | D5: Cliente principal

Sheet COLORES
A1: COLORES — Catálogo
A3: COLOR | B3: NOTAS
A4: Negro
A5: Perla
A6: Blanco
A7: Azul
A8: Beige
A9: Melange
A10: Botella
A11: Pacay
A12: V. Pacay
A13: Cemento
A14: Camote
A15: Denim
... A33: Vino Tinto

Sheet DASHBOARD
A1: DASHBOARD — Cobros del Taller (mes filtrable)
A2: Filtro Mes: | B2: =EOMONTH(TODAY(),-1)+1 -> 46143 | C2: (escribe el 1ro del mes, ej: 01/05/2026)
A4: COBRADO (mes) | C4: CUENTAS POR COBRAR | E4: ENTREGADO SIN COBRAR | G4: BRUTO TOTAL (mes)
A5: =SUMIFS(COBROS_DIARIOS!$M$4:$M$505,COBROS_DIARIOS!$A$4:$A$505,">="&$B$2,COBROS_DIARIOS!$A$4:$A$505,"<="&EOMONTH($B$2,0),COBROS_DIARIOS!$P$4:$P$505,"PAGADO") -> 0 | C5: =SUMIFS(COBROS_DIARIOS!$M$4:$M$505,COBROS_DIARIOS!$A$4:$A$505,">="&$B$2,COBROS_DIARIOS!$A$4:$A$505,"<="&EOMONTH($B$2,0),COBROS_DIARIOS!$P$4:$P$505,"PENDIENTE")+SUMIFS(COBROS_DIARIOS!$M$4:$M$505,COBROS_DIARIOS!$A$4:$A$505,">="&$B$2,COBROS_DIARIOS!$A$4:$A$505,"<="&EOMONTH($B$2,0),COBROS_DIARIOS!$P$4:$P$505,"PARCIAL") -> 80793.1 | E5: =SUMIFS(COBROS_DIARIOS!$M$4:$M$505,COBROS_DIARIOS!$A$4:$A$505,">="&$B$2,COBROS_DIARIOS!$A$4:$A$505,"<="&EOMONTH($B$2,0),COBROS_DIARIOS!$P$4:$P$505,"ENTREGADO SIN FACTURAR") -> 0 | G5: =SUMIFS(COBROS_DIARIOS!$M$4:$M$505,COBROS_DIARIOS!$A$4:$A$505,">="&$B$2,COBROS_DIARIOS!$A$4:$A$505,"<="&EOMONTH($B$2,0)) -> 82583.2
A6: DETRACCIÓN MES | C6: DISPONIBLE INMEDIATO | E6: # PRENDAS COBRADAS | G6: # OPERACIONES MES
A7: =SUMIFS(COBROS_DIARIOS!$N$4:$N$505,COBROS_DIARIOS!$A$4:$A$505,">="&$B$2,COBROS_DIARIOS!$A$4:$A$505,"<="&EOMONTH($B$2,0),COBROS_DIARIOS!$P$4:$P$505,"PAGADO") -> 0 | C7: =SUMIFS(COBROS_DIARIOS!$O$4:$O$505,COBROS_DIARIOS!$A$4:$A$505,">="&$B$2,COBROS_DIARIOS!$A$4:$A$505,"<="&EOMONTH($B$2,0),COBROS_DIARIOS!$P$4:$P$505,"PAGADO") -> 0 | E7: =SUMIFS(COBROS_DIARIOS!$K$4:$K$505,COBROS_DIARIOS!$A$4:$A$505,">="&$B$2,COBROS_DIARIOS!$A$4:$A$505,"<="&EOMONTH($B$2,0),COBROS_DIARIOS!$P$4:$P$505,"PAGADO") -> 0 | G7: =COUNTIFS(COBROS_DIARIOS!$A$4:$A$505,">="&$B$2,COBROS_DIARIOS!$A$4:$A$505,"<="&EOMONTH($B$2,0)) -> 253
A9: PRODUCCIÓN POR PRODUCTO (mes filtrado, todas las prendas)
A10: PRODUCTO | B10: S | C10: M | D10: L | E10: XL | F10: TOTAL PRENDAS | G10: BRUTO S/.
A11: =IFERROR(IF(PRODUCTOS!A4="","",PRODUCTOS!A4),"") -> jersey manga corta | B11: =IF(A11="","",SUMIFS(COBROS_DIARIOS!$G$4:$G$505,COBROS_DIARIOS!$E$4:$E$505,A11,COBROS_DIARIOS!$A$4:$A$505,">="&$B$2,COBROS_DIARIOS!$A$4:$A$505,"<="&EOMONTH($B$2,0))) -> 959 | C11: =IF(A11="","",SUMIFS(COBROS_DIARIOS!$H$4:$H$505,COBROS_DIARIOS!$E$4:$E$505,A11,COBROS_DIARIOS!$A$4:$A$505,">="&$B$2,COBROS_DIARIOS!$A$4:$A$505,"<="&EOMONTH($B$2,0))) -> 1969 | D11: =IF(A11="","",SUMIFS(COBROS_DIARIOS!$I$4:$I$505,COBROS_DIARIOS!$E$4:$E$505,A11,COBROS_DIARIOS!$A$4:$A$505,">="&$B$2,COBROS_DIARIOS!$A$4:$A$505,"<="&EOMONTH($B$2,0))) -> 1577 | E11: =IF(A11="","",SUMIFS(COBROS_DIARIOS!$J$4:$J$505,COBROS_DIARIOS!$E$4:$E$505,A11,COBROS_DIARIOS!$A$4:$A$505,">="&$B$2,COBROS_DIARIOS!$A$4:$A$505,"<="&EOMONTH($B$2,0))) -> 1016 | F11: =IF(A11="","",B11+C11+D11+E11) -> 5521 | G11: =IF(A11="","",SUMIFS(COBROS_DIARIOS!$M$4:$M$505,COBROS_DIARIOS!$E$4:$E$505,A11,COBROS_DIARIOS!$A$4:$A$505,">="&$B$2,COBROS_DIARIOS!$A$4:$A$505,"<="&EOMONTH($B$2,0))) -> 9385.7
A12: =IFERROR(IF(PRODUCTOS!A5="","",PRODUCTOS!A5),"") -> jersey manga larga | B12: =IF(A12="","",SUMIFS(COBROS_DIARIOS!$G$4:$G$505,COBROS_DIARIOS!$E$4:$E$505,A12,COBROS_DIARIOS!$A$4:$A$505,">="&$B$2,COBROS_DIARIOS!$A$4:$A$505,"<="&EOMONTH($B$2,0))) -> 513 | C12: =IF(A12="","",SUMIFS(COBROS_DIARIOS!$H$4:$H$505,COBROS_DIARIOS!$E$4:$E$505,A12,COBROS_DIARIOS!$A$4:$A$505,">="&$B$2,COBROS_DIARIOS!$A$4:$A$505,"<="&EOMONTH($B$2,0))) -> 830 | D12: =IF(A12="","",SUMIFS(COBROS_DIARIOS!$I$4:$I$505,COBROS_DIARIOS!$E$4:$E$505,A12,COBROS_DIARIOS!$A$4:$A$505,">="&$B$2,COBROS_DIARIOS!$A$4:$A$505,"<="&EOMONTH($B$2,0))) -> 990 | E12: =IF(A12="","",SUMIFS(COBROS_DIARIOS!$J$4:$J$505,COBROS_DIARIOS!$E$4:$E$505,A12,COBROS_DIARIOS!$A$4:$A$505,">="&$B$2,COBROS_DIARIOS!$A$4:$A$505,"<="&EOMONTH($B$2,0))) -> 514 | F12: =IF(A12="","",B12+C12+D12+E12) -> 2847 | G12: =IF(A12="","",SUMIFS(COBROS_DIARIOS!$M$4:$M$505,COBROS_DIARIOS!$E$4:$E$505,A12,COBROS_DIARIOS!$A$4:$A$505,">="&$B$2,COBROS_DIARIOS!$A$4:$A$505,"<="&EOMONTH($B$2,0))) -> 5694
A13: =IFERROR(IF(PRODUCTOS!A6="","",PRODUCTOS!A6),"") -> wafle clasico | B13: =IF(A13="","",SUMIFS(COBROS_DIARIOS!$G$4:$G$505,COBROS_DIARIOS!$E$4:$E$505,A13,COBROS_DIARIOS!$A$4:$A$505,">="&$B$2,COBROS_DIARIOS!$A$4:$A$505,"<="&EOMONTH($B$2,0))) -> 1520 | C13: =IF(A13="","",SUMIFS(COBROS_DIARIOS!$H$4:$H$505,COBROS_DIARIOS!$E$4:$E$505,A13,COBROS_DIARIOS!$A$4:$A$505,">="&$B$2,COBROS_DIARIOS!$A$4:$A$505,"<="&EOMONTH($B$2,0))) -> 2386 | D13: =IF(A13="","",SUMIFS(COBROS_DIARIOS!$I$4:$I$505,COBROS_DIARIOS!$E$4:$E$505,A13,COBROS_DIARIOS!$A$4:$A$505,">="&$B$2,COBROS_DIARIOS!$A$4:$A$505,"<="&EOMONTH($B$2,0))) -> 2565 | E13: =IF(A13="","",SUMIFS(COBROS_DIARIOS!$J$4:$J$505,COBROS_DIARIOS!$E$4:$E$505,A13,COBROS_DIARIOS!$A$4:$A$505,">="&$B$2,COBROS_DIARIOS!$A$4:$A$505,"<="&EOMONTH($B$2,0))) -> 1477 | F13: =IF(A13="","",B13+C13+D13+E13) -> 7948 | G13: =IF(A13="","",SUMIFS(COBROS_DIARIOS!$M$4:$M$505,COBROS_DIARIOS!$E$4:$E$505,A13,COBROS_DIARIOS!$A$4:$A$505,">="&$B$2,COBROS_DIARIOS!$A$4:$A$505,"<="&EOMONTH($B$2,0))) -> 13511.6
A14: =IFERROR(IF(PRODUCTOS!A7="","",PRODUCTOS!A7),"") -> wafle manga larga | B14: =IF(A14="","",SUMIFS(COBROS_DIARIOS!$G$4:$G$505,COBROS_DIARIOS!$E$4:$E$505,A14,COBROS_DIARIOS!$A$4:$A$505,">="&$B$2,COBROS_DIARIOS!$A$4:$A$505,"<="&EOMONTH($B$2,0))) -> 134 | C14: =IF(A14="","",SUMIFS(COBROS_DIARIOS!$H$4:$H$505,COBROS_DIARIOS!$E$4:$E$505,A14,COBROS_DIARIOS!$A$4:$A$505,">="&$B$2,COBROS_DIARIOS!$A$4:$A$505,"<="&EOMONTH($B$2,0))) -> 358 | D14: =IF(A14="","",SUMIFS(COBROS_DIARIOS!$I$4:$I$505,COBROS_DIARIOS!$E$4:$E$505,A14,COBROS_DIARIOS!$A$4:$A$505,">="&$B$2,COBROS_DIARIOS!$A$4:$A$505,"<="&EOMONTH($B$2,0))) -> 315 | E14: =IF(A14="","",SUMIFS(COBROS_DIARIOS!$J$4:$J$505,COBROS_DIARIOS!$E$4:$E$505,A14,COBROS_DIARIOS!$A$4:$A$505,">="&$B$2,COBROS_DIARIOS!$A$4:$A$505,"<="&EOMONTH($B$2,0))) -> 135 | F14: =IF(A14="","",B14+C14+D14+E14) -> 942 | G14: =IF(A14="","",SUMIFS(COBROS_DIARIOS!$M$4:$M$505,COBROS_DIARIOS!$E$4:$E$505,A14,COBROS_DIARIOS!$A$4:$A$505,">="&$B$2,COBROS_DIARIOS!$A$4:$A$505,"<="&EOMONTH($B$2,0))) -> 1884
A15: =IFERROR(IF(PRODUCTOS!A8="","",PRODUCTOS!A8),"") -> wafle camisero | B15: =IF(A15="","",SUMIFS(COBROS_DIARIOS!$G$4:$G$505,COBROS_DIARIOS!$E$4:$E$505,A15,COBROS_DIARIOS!$A$4:$A$505,">="&$B$2,COBROS_DIARIOS!$A$4:$A$505,"<="&EOMONTH($B$2,0))) -> 82 | C15: =IF(A15="","",SUMIFS(COBROS_DIARIOS!$H$4:$H$505,COBROS_DIARIOS!$E$4:$E$505,A15,COBROS_DIARIOS!$A$4:$A$505,">="&$B$2,COBROS_DIARIOS!$A$4:$A$505,"<="&EOMONTH($B$2,0))) -> 294 | D15: =IF(A15="","",SUMIFS(COBROS_DIARIOS!$I$4:$I$505,COBROS_DIARIOS!$E$4:$E$505,A15,COBROS_DIARIOS!$A$4:$A$505,">="&$B$2,COBROS_DIARIOS!$A$4:$A$505,"<="&EOMONTH($B$2,0))) -> 11 | E15: =IF(A15="","",SUMIFS(COBROS_DIARIOS!$J$4:$J$505,COBROS_DIARIOS!$E$4:$E$505,A15,COBROS_DIARIOS!$A$4:$A$505,">="&$B$2,COBROS_DIARIOS!$A$4:$A$505,"<="&EOMONTH($B$2,0))) -> 80 | F15: =IF(A15="","",B15+C15+D15+E15) -> 467 | G15: =IF(A15="","",SUMIFS(COBROS_DIARIOS!$M$4:$M$505,COBROS_DIARIOS!$E$4:$E$505,A15,COBROS_DIARIOS!$A$4:$A$505,">="&$B$2,COBROS_DIARIOS!$A$4:$A$505,"<="&EOMONTH($B$2,0))) -> 1868
A16: =IFERROR(IF(PRODUCTOS!A9="","",PRODUCTOS!A9),"") -> pique camisero | B16: =IF(A16="","",SUMIFS(COBROS_DIARIOS!$G$4:$G$505,COBROS_DIARIOS!$E$4:$E$505,A16,COBROS_DIARIOS!$A$4:$A$505,">="&$B$2,COBROS_DIARIOS!$A$4:$A$505,"<="&EOMONTH($B$2,0))) -> 772 | C16: =IF(A16="","",SUMIFS(COBROS_DIARIOS!$H$4:$H$505,COBROS_DIARIOS!$E$4:$E$505,A16,COBROS_DIARIOS!$A$4:$A$505,">="&$B$2,COBROS_DIARIOS!$A$4:$A$505,"<="&EOMONTH($B$2,0))) -> 1331 | D16: =IF(A16="","",SUMIFS(COBROS_DIARIOS!$I$4:$I$505,COBROS_DIARIOS!$E$4:$E$505,A16,COBROS_DIARIOS!$A$4:$A$505,">="&$B$2,COBROS_DIARIOS!$A$4:$A$505,"<="&EOMONTH($B$2,0))) -> 1313 | E16: =IF(A16="","",SUMIFS(COBROS_DIARIOS!$J$4:$J$505,COBROS_DIARIOS!$E$4:$E$505,A16,COBROS_DIARIOS!$A$4:$A$505,">="&$B$2,COBROS_DIARIOS!$A$4:$A$505,"<="&EOMONTH($B$2,0))) -> 893 | F16: =IF(A16="","",B16+C16+D16+E16) -> 4309 | G16: =IF(A16="","",SUMIFS(COBROS_DIARIOS!$M$4:$M$505,COBROS_DIARIOS!$E$4:$E$505,A16,COBROS_DIARIOS!$A$4:$A$505,">="&$B$2,COBROS_DIARIOS!$A$4:$A$505,"<="&EOMONTH($B$2,0))) -> 17236
A17: =IFERROR(IF(PRODUCTOS!A10="","",PRODUCTOS!A10),"") -> top cero rib | B17: =IF(A17="","",SUMIFS(COBROS_DIARIOS!$G$4:$G$505,COBROS_DIARIOS!$E$4:$E$505,A17,COBROS_DIARIOS!$A$4:$A$505,">="&$B$2,COBROS_DIARIOS!$A$4:$A$505,"<="&EOMONTH($B$2,0))) -> 0 | C17: =IF(A17="","",SUMIFS(COBROS_DIARIOS!$H$4:$H$505,COBROS_DIARIOS!$E$4:$E$505,A17,COBROS_DIARIOS!$A$4:$A$505,">="&$B$2,COBROS_DIARIOS!$A$4:$A$505,"<="&EOMONTH($B$2,0))) -> 0 | D17: =IF(A17="","",SUMIFS(COBROS_DIARIOS!$I$4:$I$505,COBROS_DIARIOS!$E$4:$E$505,A17,COBROS_DIARIOS!$A$4:$A$505,">="&$B$2,COBROS_DIARIOS!$A$4:$A$505,"<="&EOMONTH($B$2,0))) -> 0 | E17: =IF(A17="","",SUMIFS(COBROS_DIARIOS!$J$4:$J$505,COBROS_DIARIOS!$E$4:$E$505,A17,COBROS_DIARIOS!$A$4:$A$505,">="&$B$2,COBROS_DIARIOS!$A$4:$A$505,"<="&EOMONTH($B$2,0))) -> 0 | F17: =IF(A17="","",B17+C17+D17+E17) -> 0 | G17: =IF(A17="","",SUMIFS(COBROS_DIARIOS!$M$4:$M$505,COBROS_DIARIOS!$E$4:$E$505,A17,COBROS_DIARIOS!$A$4:$A$505,">="&$B$2,COBROS_DIARIOS!$A$4:$A$505,"<="&EOMONTH($B$2,0))) -> 411.4
A18: =IFERROR(IF(PRODUCTOS!A11="","",PRODUCTOS!A11),"") -> top mc rib | B18: =IF(A18="","",SUMIFS(COBROS_DIARIOS!$G$4:$G$505,COBROS_DIARIOS!$E$4:$E$505,A18,COBROS_DIARIOS!$A$4:$A$505,">="&$B$2,COBROS_DIARIOS!$A$4:$A$505,"<="&EOMONTH($B$2,0))) -> 0 | C18: =IF(A18="","",SUMIFS(COBROS_DIARIOS!$H$4:$H$505,COBROS_DIARIOS!$E$4:$E$505,A18,COBROS_DIARIOS!$A$4:$A$505,">="&$B$2,COBROS_DIARIOS!$A$4:$A$505,"<="&EOMONTH($B$2,0))) -> 0 | D18: =IF(A18="","",SUMIFS(COBROS_DIARIOS!$I$4:$I$505,COBROS_DIARIOS!$E$4:$E$505,A18,COBROS_DIARIOS!$A$4:$A$505,">="&$B$2,COBROS_DIARIOS!$A$4:$A$505,"<="&EOMONTH($B$2,0))) -> 0 | E18: =IF(A18="","",SUMIFS(COBROS_DIARIOS!$J$4:$J$505,COBROS_DIARIOS!$E$4:$E$505,A18,COBROS_DIARIOS!$A$4:$A$505,">="&$B$2,COBROS_DIARIOS!$A$4:$A$505,"<="&EOMONTH($B$2,0))) -> 0 | F18: =IF(A18="","",B18+C18+D18+E18) -> 0 | G18: =IF(A18="","",SUMIFS(COBROS_DIARIOS!$M$4:$M$505,COBROS_DIARIOS!$E$4:$E$505,A18,COBROS_DIARIOS!$A$4:$A$505,">="&$B$2,COBROS_DIARIOS!$A$4:$A$505,"<="&EOMONTH($B$2,0))) -> 1232.5
A19: =IFERROR(IF(PRODUCTOS!A12="","",PRODUCTOS!A12),"") -> top ml rib | B19: =IF(A19="","",SUMIFS(COBROS_DIARIOS!$G$4:$G$505,COBROS_DIARIOS!$E$4:$E$505,A19,COBROS_DIARIOS!$A$4:$A$505,">="&$B$2,COBROS_DIARIOS!$A$4:$A$505,"<="&EOMONTH($B$2,0))) -> 0 | C19: =IF(A19="","",SUMIFS(COBROS_DIARIOS!$H$4:$H$505,COBROS_DIARIOS!$E$4:$E$505,A19,COBROS_DIARIOS!$A$4:$A$505,">="&$B$2,COBROS_DIARIOS!$A$4:$A$505,"<="&EOMONTH($B$2,0))) -> 0 | D19: =IF(A19="","",SUMIFS(COBROS_DIARIOS!$I$4:$I$505,COBROS_DIARIOS!$E$4:$E$505,A19,COBROS_DIARIOS!$A$4:$A$505,">="&$B$2,COBROS_DIARIOS!$A$4:$A$505,"<="&EOMONTH($B$2,0))) -> 0 | E19: =IF(A19="","",SUMIFS(COBROS_DIARIOS!$J$4:$J$505,COBROS_DIARIOS!$E$4:$E$505,A19,COBROS_DIARIOS!$A$4:$A$505,">="&$B$2,COBROS_DIARIOS!$A$4:$A$505,"<="&EOMONTH($B$2,0))) -> 0 | F19: =IF(A19="","",B19+C19+D19+E19) -> 0 | G19: =IF(A19="","",SUMIFS(COBROS_DIARIOS!$M$4:$M$505,COBROS_DIARIOS!$E$4:$E$505,A19,COBROS_DIARIOS!$A$4:$A$505,">="&$B$2,COBROS_DIARIOS!$A$4:$A$505,"<="&EOMONTH($B$2,0))) -> 1084.6
A20: =IFERROR(IF(PRODUCTOS!A13="","",PRODUCTOS!A13),"") -> baby ty mc | B20: =IF(A20="","",SUMIFS(COBROS_DIARIOS!$G$4:$G$505,COBROS_DIARIOS!$E$4:$E$505,A20,COBROS_DIARIOS!$A$4:$A$505,">="&$B$2,COBROS_DIARIOS!$A$4:$A$505,"<="&EOMONTH($B$2,0))) -> 634 | C20: =IF(A20="","",SUMIFS(COBROS_DIARIOS!$H$4:$H$505,COBROS_DIARIOS!$E$4:$E$505,A20,COBROS_DIARIOS!$A$4:$A$505,">="&$B$2,COBROS_DIARIOS!$A$4:$A$505,"<="&EOMONTH($B$2,0))) -> 671 | D20: =IF(A20="","",SUMIFS(COBROS_DIARIOS!$I$4:$I$505,COBROS_DIARIOS!$E$4:$E$505,A20,COBROS_DIARIOS!$A$4:$A$505,">="&$B$2,COBROS_DIARIOS!$A$4:$A$505,"<="&EOMONTH($B$2,0))) -> 667 | E20: =IF(A20="","",SUMIFS(COBROS_DIARIOS!$J$4:$J$505,COBROS_DIARIOS!$E$4:$E$505,A20,COBROS_DIARIOS!$A$4:$A$505,">="&$B$2,COBROS_DIARIOS!$A$4:$A$505,"<="&EOMONTH($B$2,0))) -> 0 | F20: =IF(A20="","",B20+C20+D20+E20) -> 1972 | G20: =IF(A20="","",SUMIFS(COBROS_DIARIOS!$M$4:$M$505,COBROS_DIARIOS!$E$4:$E$505,A20,COBROS_DIARIOS!$A$4:$A$505,">="&$B$2,COBROS_DIARIOS!$A$4:$A$505,"<="&EOMONTH($B$2,0))) -> 3352.4
A21: =IFERROR(IF(PRODUCTOS!A14="","",PRODUCTOS!A14),"") -> baby ty ml | B21: =IF(A21="","",SUMIFS(COBROS_DIARIOS!$G$4:$G$505,COBROS_DIARIOS!$E$4:$E$505,A21,COBROS_DIARIOS!$A$4:$A$505,">="&$B$2,COBROS_DIARIOS!$A$4:$A$505,"<="&EOMONTH($B$2,0))) -> 358 | C21: =IF(A21="","",SUMIFS(COBROS_DIARIOS!$H$4:$H$505,COBROS_DIARIOS!$E$4:$E$505,A21,COBROS_DIARIOS!$A$4:$A$505,">="&$B$2,COBROS_DIARIOS!$A$4:$A$505,"<="&EOMONTH($B$2,0))) -> 400 | D21: =IF(A21="","",SUMIFS(COBROS_DIARIOS!$I$4:$I$505,COBROS_DIARIOS!$E$4:$E$505,A21,COBROS_DIARIOS!$A$4:$A$505,">="&$B$2,COBROS_DIARIOS!$A$4:$A$505,"<="&EOMONTH($B$2,0))) -> 389 | E21: =IF(A21="","",SUMIFS(COBROS_DIARIOS!$J$4:$J$505,COBROS_DIARIOS!$E$4:$E$505,A21,COBROS_DIARIOS!$A$4:$A$505,">="&$B$2,COBROS_DIARIOS!$A$4:$A$505,"<="&EOMONTH($B$2,0))) -> 0 | F21: =IF(A21="","",B21+C21+D21+E21) -> 1147 | G21: =IF(A21="","",SUMIFS(COBROS_DIARIOS!$M$4:$M$505,COBROS_DIARIOS!$E$4:$E$505,A21,COBROS_DIARIOS!$A$4:$A$505,">="&$B$2,COBROS_DIARIOS!$A$4:$A$505,"<="&EOMONTH($B$2,0))) -> 1949.9
A22: =IFERROR(IF(PRODUCTOS!A15="","",PRODUCTOS!A15),"") -> Baby Tee con S | B22: =IF(A22="","",SUMIFS(COBROS_DIARIOS!$G$4:$G$505,COBROS_DIARIOS!$E$4:$E$505,A22,COBROS_DIARIOS!$A$4:$A$505,">="&$B$2,COBROS_DIARIOS!$A$4:$A$505,"<="&EOMONTH($B$2,0))) -> 313 | C22: =IF(A22="","",SUMIFS(COBROS_DIARIOS!$H$4:$H$505,COBROS_DIARIOS!$E$4:$E$505,A22,COBROS_DIARIOS!$A$4:$A$505,">="&$B$2,COBROS_DIARIOS!$A$4:$A$505,"<="&EOMONTH($B$2,0))) -> 310 | D22: =IF(A22="","",SUMIFS(COBROS_DIARIOS!$I$4:$I$505,COBROS_DIARIOS!$E$4:$E$505,A22,COBROS_DIARIOS!$A$4:$A$505,">="&$B$2,COBROS_DIARIOS!$A$4:$A$505,"<="&EOMONTH($B$2,0))) -> 312 | E22: =IF(A22="","",SUMIFS(COBROS_DIARIOS!$J$4:$J$505,COBROS_DIARIOS!$E$4:$E$505,A22,COBROS_DIARIOS!$A$4:$A$505,">="&$B$2,COBROS_DIARIOS!$A$4:$A$505,"<="&EOMONTH($B$2,0))) -> 0 | F22: =IF(A22="","",B22+C22+D22+E22) -> 935 | G22: =IF(A22="","",SUMIFS(COBROS_DIARIOS!$M$4:$M$505,COBROS_DIARIOS!$E$4:$E$505,A22,COBROS_DIARIOS!$A$4:$A$505,">="&$B$2,COBROS_DIARIOS!$A$4:$A$505,"<="&EOMONTH($B$2,0))) -> 1589.5
... A35: =IFERROR(IF(PRODUCTOS!A28="","",PRODUCTOS!A28),"") | B35: =IF(A35="","",SUMIFS(COBROS_DIARIOS!$G$4:$G$505,COBROS_DIARIOS!$E$4:$E$505,A35,COBROS_DIARIOS!$A$4:$A$505,">="&$B$2,COBROS_DIARIOS!$A$4:$A$505,"<="&EOMONTH($B$2,0))) | C35: =IF(A35="","",SUMIFS(COBROS_DIARIOS!$H$4:$H$505,COBROS_DIARIOS!$E$4:$E$505,A35,COBROS_DIARIOS!$A$4:$A$505,">="&$B$2,COBROS_DIARIOS!$A$4:$A$505,"<="&EOMONTH($B$2,0))) | D35: =IF(A35="","",SUMIFS(COBROS_DIARIOS!$I$4:$I$505,COBROS_DIARIOS!$E$4:$E$505,A35,COBROS_DIARIOS!$A$4:$A$505,">="&$B$2,COBROS_DIARIOS!$A$4:$A$505,"<="&EOMONTH($B$2,0))) | E35: =IF(A35="","",SUMIFS(COBROS_DIARIOS!$J$4:$J$505,COBROS_DIARIOS!$E$4:$E$505,A35,COBROS_DIARIOS!$A$4:$A$505,">="&$B$2,COBROS_DIARIOS!$A$4:$A$505,"<="&EOMONTH($B$2,0))) | F35: =IF(A35="","",B35+C35+D35+E35) | G35: =IF(A35="","",SUMIFS(COBROS_DIARIOS!$M$4:$M$505,COBROS_DIARIOS!$E$4:$E$505,A35,COBROS_DIARIOS!$A$4:$A$505,">="&$B$2,COBROS_DIARIOS!$A$4:$A$505,"<="&EOMONTH($B$2,0)))
A36: TOTAL ⇒ | B36: =SUM(B11:B35) -> 7197 | C36: =SUM(C11:C35) -> 10314 | D36: =SUM(D11:D35) -> 9806 | E36: =SUM(E11:E35) -> 4240 | F36: =SUM(F11:F35) -> 31557 | G36: =SUM(G11:G35) -> 82583.2
A38: CANTIDAD POR COLOR — Total entregado (todos los productos)
A39: COLOR | B39: TOTAL PRENDAS | C39: BRUTO S/. | D39: % TOTAL
A40: {=IFERROR(IF(LARGE($D$200:$D$249,1)<=0,"",INDEX($A$200:$A$249,MATCH(LARGE($D$200:$D$249,1),$D$200:$D$249,0))),"")} -> Negro | B40: {=IFERROR(IF(LARGE($D$200:$D$249,1)<=0,"",INDEX($B$200:$B$249,MATCH(LARGE($D$200:$D$249,1),$D$200:$D$249,0))),"")} -> 6201 | C40: {=IFERROR(IF(LARGE($D$200:$D$249,1)<=0,"",INDEX($C$200:$C$249,MATCH(LARGE($D$200:$D$249,1),$D$200:$D$249,0))),"")} -> 16120.7 | D40: =IFERROR(IF(B40="","",B40/SUMIFS(COBROS_DIARIOS!$K$4:$K$505,COBROS_DIARIOS!$A$4:$A$505,">="&$B$2,COBROS_DIARIOS!$A$4:$A$505,"<="&EOMONTH($B$2,0))),"") -> 0.18194355
A41: {=IFERROR(IF(LARGE($D$200:$D$249,2)<=0,"",INDEX($A$200:$A$249,MATCH(LARGE($D$200:$D$249,2),$D$200:$D$249,0))),"")} -> Vino | B41: {=IFERROR(IF(LARGE($D$200:$D$249,2)<=0,"",INDEX($B$200:$B$249,MATCH(LARGE($D$200:$D$249,2),$D$200:$D$249,0))),"")} -> 4566 | C41: {=IFERROR(IF(LARGE($D$200:$D$249,2)<=0,"",INDEX($C$200:$C$249,MATCH(LARGE($D$200:$D$249,2),$D$200:$D$249,0))),"")} -> 9329.4 | D41: =IFERROR(IF(B41="","",B41/SUMIFS(COBROS_DIARIOS!$K$4:$K$505,COBROS_DIARIOS!$A$4:$A$505,">="&$B$2,COBROS_DIARIOS!$A$4:$A$505,"<="&EOMONTH($B$2,0))),"") -> 0.13397101
A42: {=IFERROR(IF(LARGE($D$200:$D$249,3)<=0,"",INDEX($A$200:$A$249,MATCH(LARGE($D$200:$D$249,3),$D$200:$D$249,0))),"")} -> Azul Marino | B42: {=IFERROR(IF(LARGE($D$200:$D$249,3)<=0,"",INDEX($B$200:$B$249,MATCH(LARGE($D$200:$D$249,3),$D$200:$D$249,0))),"")} -> 4340 | C42: {=IFERROR(IF(LARGE($D$200:$D$249,3)<=0,"",INDEX($C$200:$C$249,MATCH(LARGE($D$200:$D$249,3),$D$200:$D$249,0))),"")} -> 11485.3 | D42: =IFERROR(IF(B42="","",B42/SUMIFS(COBROS_DIARIOS!$K$4:$K$505,COBROS_DIARIOS!$A$4:$A$505,">="&$B$2,COBROS_DIARIOS!$A$4:$A$505,"<="&EOMONTH($B$2,0))),"") -> 0.12733994
A43: {=IFERROR(IF(LARGE($D$200:$D$249,4)<=0,"",INDEX($A$200:$A$249,MATCH(LARGE($D$200:$D$249,4),$D$200:$D$249,0))),"")} -> Perla | B43: {=IFERROR(IF(LARGE($D$200:$D$249,4)<=0,"",INDEX($B$200:$B$249,MATCH(LARGE($D$200:$D$249,4),$D$200:$D$249,0))),"")} -> 3124 | C43: {=IFERROR(IF(LARGE($D$200:$D$249,4)<=0,"",INDEX($C$200:$C$249,MATCH(LARGE($D$200:$D$249,4),$D$200:$D$249,0))),"")} -> 6951.7 | D43: =IFERROR(IF(B43="","",B43/SUMIFS(COBROS_DIARIOS!$K$4:$K$505,COBROS_DIARIOS!$A$4:$A$505,">="&$B$2,COBROS_DIARIOS!$A$4:$A$505,"<="&EOMONTH($B$2,0))),"") -> 0.091661287
A44: {=IFERROR(IF(LARGE($D$200:$D$249,5)<=0,"",INDEX($A$200:$A$249,MATCH(LARGE($D$200:$D$249,5),$D$200:$D$249,0))),"")} -> Colegial | B44: {=IFERROR(IF(LARGE($D$200:$D$249,5)<=0,"",INDEX($B$200:$B$249,MATCH(LARGE($D$200:$D$249,5),$D$200:$D$249,0))),"")} -> 2998 | C44: {=IFERROR(IF(LARGE($D$200:$D$249,5)<=0,"",INDEX($C$200:$C$249,MATCH(LARGE($D$200:$D$249,5),$D$200:$D$249,0))),"")} -> 7367 | D44: =IFERROR(IF(B44="","",B44/SUMIFS(COBROS_DIARIOS!$K$4:$K$505,COBROS_DIARIOS!$A$4:$A$505,">="&$B$2,COBROS_DIARIOS!$A$4:$A$505,"<="&EOMONTH($B$2,0))),"") -> 0.087964321
A45: {=IFERROR(IF(LARGE($D$200:$D$249,6)<=0,"",INDEX($A$200:$A$249,MATCH(LARGE($D$200:$D$249,6),$D$200:$D$249,0))),"")} -> Denim | B45: {=IFERROR(IF(LARGE($D$200:$D$249,6)<=0,"",INDEX($B$200:$B$249,MATCH(LARGE($D$200:$D$249,6),$D$200:$D$249,0))),"")} -> 2363 | C45: {=IFERROR(IF(LARGE($D$200:$D$249,6)<=0,"",INDEX($C$200:$C$249,MATCH(LARGE($D$200:$D$249,6),$D$200:$D$249,0))),"")} -> 4836.2 | D45: =IFERROR(IF(B45="","",B45/SUMIFS(COBROS_DIARIOS!$K$4:$K$505,COBROS_DIARIOS!$A$4:$A$505,">="&$B$2,COBROS_DIARIOS!$A$4:$A$505,"<="&EOMONTH($B$2,0))),"") -> 0.069332786
A46: {=IFERROR(IF(LARGE($D$200:$D$249,7)<=0,"",INDEX($A$200:$A$249,MATCH(LARGE($D$200:$D$249,7),$D$200:$D$249,0))),"")} -> Botella | B46: {=IFERROR(IF(LARGE($D$200:$D$249,7)<=0,"",INDEX($B$200:$B$249,MATCH(LARGE($D$200:$D$249,7),$D$200:$D$249,0))),"")} -> 2100 | C46: {=IFERROR(IF(LARGE($D$200:$D$249,7)<=0,"",INDEX($C$200:$C$249,MATCH(LARGE($D$200:$D$249,7),$D$200:$D$249,0))),"")} -> 6356.1 | D46: =IFERROR(IF(B46="","",B46/SUMIFS(COBROS_DIARIOS!$K$4:$K$505,COBROS_DIARIOS!$A$4:$A$505,">="&$B$2,COBROS_DIARIOS!$A$4:$A$505,"<="&EOMONTH($B$2,0))),"") -> 0.061616102
A47: {=IFERROR(IF(LARGE($D$200:$D$249,8)<=0,"",INDEX($A$200:$A$249,MATCH(LARGE($D$200:$D$249,8),$D$200:$D$249,0))),"")} -> Beige | B47: {=IFERROR(IF(LARGE($D$200:$D$249,8)<=0,"",INDEX($B$200:$B$249,MATCH(LARGE($D$200:$D$249,8),$D$200:$D$249,0))),"")} -> 1871 | C47: {=IFERROR(IF(LARGE($D$200:$D$249,8)<=0,"",INDEX($C$200:$C$249,MATCH(LARGE($D$200:$D$249,8),$D$200:$D$249,0))),"")} -> 4322.9 | D47: =IFERROR(IF(B47="","",B47/SUMIFS(COBROS_DIARIOS!$K$4:$K$505,COBROS_DIARIOS!$A$4:$A$505,">="&$B$2,COBROS_DIARIOS!$A$4:$A$505,"<="&EOMONTH($B$2,0))),"") -> 0.054897013
A48: {=IFERROR(IF(LARGE($D$200:$D$249,9)<=0,"",INDEX($A$200:$A$249,MATCH(LARGE($D$200:$D$249,9),$D$200:$D$249,0))),"")} -> Topo | B48: {=IFERROR(IF(LARGE($D$200:$D$249,9)<=0,"",INDEX($B$200:$B$249,MATCH(LARGE($D$200:$D$249,9),$D$200:$D$249,0))),"")} -> 1543 | C48: {=IFERROR(IF(LARGE($D$200:$D$249,9)<=0,"",INDEX($C$200:$C$249,MATCH(LARGE($D$200:$D$249,9),$D$200:$D$249,0))),"")} -> 3547.7 | D48: =IFERROR(IF(B48="","",B48/SUMIFS(COBROS_DIARIOS!$K$4:$K$505,COBROS_DIARIOS!$A$4:$A$505,">="&$B$2,COBROS_DIARIOS!$A$4:$A$505,"<="&EOMONTH($B$2,0))),"") -> 0.045273165
A49: {=IFERROR(IF(LARGE($D$200:$D$249,10)<=0,"",INDEX($A$200:$A$249,MATCH(LARGE($D$200:$D$249,10),$D$200:$D$249,0))),"")} -> P. Rosa | B49: {=IFERROR(IF(LARGE($D$200:$D$249,10)<=0,"",INDEX($B$200:$B$249,MATCH(LARGE($D$200:$D$249,10),$D$200:$D$249,0))),"")} -> 1492 | C49: {=IFERROR(IF(LARGE($D$200:$D$249,10)<=0,"",INDEX($C$200:$C$249,MATCH(LARGE($D$200:$D$249,10),$D$200:$D$249,0))),"")} -> 3677.1 | D49: =IFERROR(IF(B49="","",B49/SUMIFS(COBROS_DIARIOS!$K$4:$K$505,COBROS_DIARIOS!$A$4:$A$505,">="&$B$2,COBROS_DIARIOS!$A$4:$A$505,"<="&EOMONTH($B$2,0))),"") -> 0.043776774
A50: {=IFERROR(IF(LARGE($D$200:$D$249,11)<=0,"",INDEX($A$200:$A$249,MATCH(LARGE($D$200:$D$249,11),$D$200:$D$249,0))),"")} -> V. Pacay | B50: {=IFERROR(IF(LARGE($D$200:$D$249,11)<=0,"",INDEX($B$200:$B$249,MATCH(LARGE($D$200:$D$249,11),$D$200:$D$249,0))),"")} -> 1337 | C50: {=IFERROR(IF(LARGE($D$200:$D$249,11)<=0,"",INDEX($C$200:$C$249,MATCH(LARGE($D$200:$D$249,11),$D$200:$D$249,0))),"")} -> 3456.3 | D50: =IFERROR(IF(B50="","",B50/SUMIFS(COBROS_DIARIOS!$K$4:$K$505,COBROS_DIARIOS!$A$4:$A$505,">="&$B$2,COBROS_DIARIOS!$A$4:$A$505,"<="&EOMONTH($B$2,0))),"") -> 0.039228918
A51: {=IFERROR(IF(LARGE($D$200:$D$249,12)<=0,"",INDEX($A$200:$A$249,MATCH(LARGE($D$200:$D$249,12),$D$200:$D$249,0))),"")} -> Cemento | B51: {=IFERROR(IF(LARGE($D$200:$D$249,12)<=0,"",INDEX($B$200:$B$249,MATCH(LARGE($D$200:$D$249,12),$D$200:$D$249,0))),"")} -> 1257 | C51: {=IFERROR(IF(LARGE($D$200:$D$249,12)<=0,"",INDEX($C$200:$C$249,MATCH(LARGE($D$200:$D$249,12),$D$200:$D$249,0))),"")} -> 2260.2 | D51: =IFERROR(IF(B51="","",B51/SUMIFS(COBROS_DIARIOS!$K$4:$K$505,COBROS_DIARIOS!$A$4:$A$505,">="&$B$2,COBROS_DIARIOS!$A$4:$A$505,"<="&EOMONTH($B$2,0))),"") -> 0.036881638
A52: {=IFERROR(IF(LARGE($D$200:$D$249,13)<=0,"",INDEX($A$200:$A$249,MATCH(LARGE($D$200:$D$249,13),$D$200:$D$249,0))),"")} -> Melange | B52: {=IFERROR(IF(LARGE($D$200:$D$249,13)<=0,"",INDEX($B$200:$B$249,MATCH(LARGE($D$200:$D$249,13),$D$200:$D$249,0))),"")} -> 692 | C52: {=IFERROR(IF(LARGE($D$200:$D$249,13)<=0,"",INDEX($C$200:$C$249,MATCH(LARGE($D$200:$D$249,13),$D$200:$D$249,0))),"")} -> 2536 | D52: =IFERROR(IF(B52="","",B52/SUMIFS(COBROS_DIARIOS!$K$4:$K$505,COBROS_DIARIOS!$A$4:$A$505,">="&$B$2,COBROS_DIARIOS!$A$4:$A$505,"<="&EOMONTH($B$2,0))),"") -> 0.020303973
A53: {=IFERROR(IF(LARGE($D$200:$D$249,14)<=0,"",INDEX($A$200:$A$249,MATCH(LARGE($D$200:$D$249,14),$D$200:$D$249,0))),"")} -> Palo Rosa | B53: {=IFERROR(IF(LARGE($D$200:$D$249,14)<=0,"",INDEX($B$200:$B$249,MATCH(LARGE($D$200:$D$249,14),$D$200:$D$249,0))),"")} -> 198 | C53: {=IFERROR(IF(LARGE($D$200:$D$249,14)<=0,"",INDEX($C$200:$C$249,MATCH(LARGE($D$200:$D$249,14),$D$200:$D$249,0))),"")} -> 336.6 | D53: =IFERROR(IF(B53="","",B53/SUMIFS(COBROS_DIARIOS!$K$4:$K$505,COBROS_DIARIOS!$A$4:$A$505,">="&$B$2,COBROS_DIARIOS!$A$4:$A$505,"<="&EOMONTH($B$2,0))),"") -> 0.0058095182
A54: {=IFERROR(IF(LARGE($D$200:$D$249,15)<=0,"",INDEX($A$200:$A$249,MATCH(LARGE($D$200:$D$249,15),$D$200:$D$249,0))),"")} | B54: {=IFERROR(IF(LARGE($D$200:$D$249,15)<=0,"",INDEX($B$200:$B$249,MATCH(LARGE($D$200:$D$249,15),$D$200:$D$249,0))),"")} | C54: {=IFERROR(IF(LARGE($D$200:$D$249,15)<=0,"",INDEX($C$200:$C$249,MATCH(LARGE($D$200:$D$249,15),$D$200:$D$249,0))),"")} | D54: =IFERROR(IF(B54="","",B54/SUMIFS(COBROS_DIARIOS!$K$4:$K$505,COBROS_DIARIOS!$A$4:$A$505,">="&$B$2,COBROS_DIARIOS!$A$4:$A$505,"<="&EOMONTH($B$2,0))),"")
A55: {=IFERROR(IF(LARGE($D$200:$D$249,16)<=0,"",INDEX($A$200:$A$249,MATCH(LARGE($D$200:$D$249,16),$D$200:$D$249,0))),"")} | B55: {=IFERROR(IF(LARGE($D$200:$D$249,16)<=0,"",INDEX($B$200:$B$249,MATCH(LARGE($D$200:$D$249,16),$D$200:$D$249,0))),"")} | C55: {=IFERROR(IF(LARGE($D$200:$D$249,16)<=0,"",INDEX($C$200:$C$249,MATCH(LARGE($D$200:$D$249,16),$D$200:$D$249,0))),"")} | D55: =IFERROR(IF(B55="","",B55/SUMIFS(COBROS_DIARIOS!$K$4:$K$505,COBROS_DIARIOS!$A$4:$A$505,">="&$B$2,COBROS_DIARIOS!$A$4:$A$505,"<="&EOMONTH($B$2,0))),"")
...
