Workbook
Name LISTA_PROVEEDORES: PROVEEDORES!$A$4:$A$52
Name LISTA_PRODUCTOS: PRODUCTOS!$A$4:$A$52
Name LISTA_CLIENTES: CLIENTES!$A$4:$A$9
Name LISTA_DESTINOS: PRODUCTOS!$N$4:$N$52
Name LISTA_CLIENTES_FILTRO: CLIENTES!$G$4:$G$10
Name LISTA_COLORES: COLORES!$A$4:$A$102
Name LISTA_TELAS: TELAS!$A$4:$A$32

Sheet MOVIMIENTOS
A1: MOVIMIENTOS DIARIOS — Llenar SOLO esta hoja (cardista)
A2: Fecha · Tipo · Cliente · Tela · Color · Rollos. Para INGRESO también: Proveedor · N° Factura · Costo Real. El sistema calcula Kg, Precio y Total automáticamente.
A3: FECHA | B3: TIPO | C3: CLIENTE | D3: TELA | E3: COLOR | F3: ROLLOS | G3: KG TOTAL | H3: CATEG. COLOR | I3: PRECIO/KG | J3: TOTAL S/. | K3: STOCK ANTES (rollos) | L3: STOCK DESPUÉS (rollos) | M3: RESPONSABLE | N3: NOTAS | O3: PROVEEDOR | P3: N° FACTURA | Q3: COSTO REAL FACT. S/. | R3: DIFERENCIA % (real vs teórico)
A4: 46146 | B4: INGRESO | C4: OverShark | D4: jersey 30/1 | E4: Negro | F4: 29 | G4: =IFERROR(F4*VLOOKUP(D4,TELAS!$A$4:$C$32,3,FALSE()),0) -> 580 | H4: =IFERROR(VLOOKUP(E4,COLORES!$A$4:$B$102,2,FALSE()),"") -> OSCURO | I4: =IFERROR(IF(H4="OSCURO",VLOOKUP(D4,PRECIOS!$A$4:$F$32,2,FALSE()),IF(H4="CLARO",VLOOKUP(D4,PRECIOS!$A$4:$F$32,3,FALSE()),IF(H4="MELANGE",VLOOKUP(D4,PRECIOS!$A$4:$F$32,4,FALSE()),IF(H4="PPT",VLOOKUP(D4,PRECIOS!$A$4:$F$32,5,FALSE()),0)))),0) -> 24 | J4: =IFERROR(G4*I4,0) -> 13920 | K4: =0 -> 0 | L4: =IF(C4="",0,K4+IF(OR(B4="INGRESO",B4="DE REPROCESO",B4="AJUSTE+"),F4,IF(OR(B4="A CORTE",B4="A REPROCESO",B4="MUESTRA",B4="AJUSTE-"),-F4,0))) -> 29 | M4: tomas | O4: progreso | R4: =IF(OR(Q4="",Q4=0,J4=0),"",(Q4-J4)/J4)
A5: 46146 | B5: INGRESO | C5: OverShark | D5: jersey 30/1 | E5: Perla | F5: 48 | G5: =IFERROR(F5*VLOOKUP(D5,TELAS!$A$4:$C$32,3,FALSE()),0) -> 960 | H5: =IFERROR(VLOOKUP(E5,COLORES!$A$4:$B$102,2,FALSE()),"") -> PPT | I5: =IFERROR(IF(H5="OSCURO",VLOOKUP(D5,PRECIOS!$A$4:$F$32,2,FALSE()),IF(H5="CLARO",VLOOKUP(D5,PRECIOS!$A$4:$F$32,3,FALSE()),IF(H5="MELANGE",VLOOKUP(D5,PRECIOS!$A$4:$F$32,4,FALSE()),IF(H5="PPT",VLOOKUP(D5,PRECIOS!$A$4:$F$32,5,FALSE()),0)))),0) -> 18 | J5: =IFERROR(G5*I5,0) -> 17280 | K5: =IFERROR(IF(C5="",0,SUMIFS($F$4,$C$4,C5,$D$4,D5,$E$4,E5,$B$4,"INGRESO")+SUMIFS($F$4,$C$4,C5,$D$4,D5,$E$4,E5,$B$4,"DE REPROCESO")+SUMIFS($F$4,$C$4,C5,$D$4,D5,$E$4,E5,$B$4,"AJUSTE+")-SUMIFS($F$4,$C$4,C5,$D$4,D5,$E$4,E5,$B$4,"A CORTE")-SUMIFS($F$4,$C$4,C5,$D$4,D5,$E$4,E5,$B$4,"A REPROCESO")-SUMIFS($F$4,$C$4,C5,$D$4,D5,$E$4,E5,$B$4,"MUESTRA")-SUMIFS($F$4,$C$4,C5,$D$4,D5,$E$4,E5,$B$4,"AJUSTE-")),0) -> 0 | L5: =IF(C5="",0,K5+IF(OR(B5="INGRESO",B5="DE REPROCESO",B5="AJUSTE+"),F5,IF(OR(B5="A CORTE",B5="A REPROCESO",B5="MUESTRA",B5="AJUSTE-"),-F5,0))) -> 48 | M5: tomas | O5: progreso | R5: =IF(OR(Q5="",Q5=0,J5=0),"",(Q5-J5)/J5)
A6: 46146 | B6: INGRESO | C6: OverShark | D6: jersey 30/1 | E6: Azul | F6: 10 | G6: =IFERROR(F6*VLOOKUP(D6,TELAS!$A$4:$C$32,3,FALSE()),0) -> 200 | H6: =IFERROR(VLOOKUP(E6,COLORES!$A$4:$B$102,2,FALSE()),"") -> OSCURO | I6: =IFERROR(IF(H6="OSCURO",VLOOKUP(D6,PRECIOS!$A$4:$F$32,2,FALSE()),IF(H6="CLARO",VLOOKUP(D6,PRECIOS!$A$4:$F$32,3,FALSE()),IF(H6="MELANGE",VLOOKUP(D6,PRECIOS!$A$4:$F$32,4,FALSE()),IF(H6="PPT",VLOOKUP(D6,PRECIOS!$A$4:$F$32,5,FALSE()),0)))),0) -> 24 | J6: =IFERROR(G6*I6,0) -> 4800 | K6: =IFERROR(IF(C6="",0,SUMIFS($F$4:$F$5,$C$4:$C$5,C6,$D$4:$D$5,D6,$E$4:$E$5,E6,$B$4:$B$5,"INGRESO")+SUMIFS($F$4:$F$5,$C$4:$C$5,C6,$D$4:$D$5,D6,$E$4:$E$5,E6,$B$4:$B$5,"DE REPROCESO")+SUMIFS($F$4:$F$5,$C$4:$C$5,C6,$D$4:$D$5,D6,$E$4:$E$5,E6,$B$4:$B$5,"AJUSTE+")-SUMIFS($F$4:$F$5,$C$4:$C$5,C6,$D$4:$D$5,D6,$E$4:$E$5,E6,$B$4:$B$5,"A CORTE")-SUMIFS($F$4:$F$5,$C$4:$C$5,C6,$D$4:$D$5,D6,$E$4:$E$5,E6,$B$4:$B$5,"A REPROCESO")-SUMIFS($F$4:$F$5,$C$4:$C$5,C6,$D$4:$D$5,D6,$E$4:$E$5,E6,$B$4:$B$5,"MUESTRA")-SUMIFS($F$4:$F$5,$C$4:$C$5,C6,$D$4:$D$5,D6,$E$4:$E$5,E6,$B$4:$B$5,"AJUSTE-")),0) -> 0 | L6: =IF(C6="",0,K6+IF(OR(B6="INGRESO",B6="DE REPROCESO",B6="AJUSTE+"),F6,IF(OR(B6="A CORTE",B6="A REPROCESO",B6="MUESTRA",B6="AJUSTE-"),-F6,0))) -> 10 | M6: tomas | O6: progreso | R6: =IF(OR(Q6="",Q6=0,J6=0),"",(Q6-J6)/J6)
A7: 46146 | B7: INGRESO | C7: OverShark | D7: jersey 30/1 | E7: Botella | F7: 15 | G7: =IFERROR(F7*VLOOKUP(D7,TELAS!$A$4:$C$32,3,FALSE()),0) -> 300 | H7: =IFERROR(VLOOKUP(E7,COLORES!$A$4:$B$102,2,FALSE()),"") -> OSCURO | I7: =IFERROR(IF(H7="OSCURO",VLOOKUP(D7,PRECIOS!$A$4:$F$32,2,FALSE()),IF(H7="CLARO",VLOOKUP(D7,PRECIOS!$A$4:$F$32,3,FALSE()),IF(H7="MELANGE",VLOOKUP(D7,PRECIOS!$A$4:$F$32,4,FALSE()),IF(H7="PPT",VLOOKUP(D7,PRECIOS!$A$4:$F$32,5,FALSE()),0)))),0) -> 24 | J7: =IFERROR(G7*I7,0) -> 7200 | K7: =IFERROR(IF(C7="",0,SUMIFS($F$4:$F$6,$C$4:$C$6,C7,$D$4:$D$6,D7,$E$4:$E$6,E7,$B$4:$B$6,"INGRESO")+SUMIFS($F$4:$F$6,$C$4:$C$6,C7,$D$4:$D$6,D7,$E$4:$E$6,E7,$B$4:$B$6,"DE REPROCESO")+SUMIFS($F$4:$F$6,$C$4:$C$6,C7,$D$4:$D$6,D7,$E$4:$E$6,E7,$B$4:$B$6,"AJUSTE+")-SUMIFS($F$4:$F$6,$C$4:$C$6,C7,$D$4:$D$6,D7,$E$4:$E$6,E7,$B$4:$B$6,"A CORTE")-SUMIFS($F$4:$F$6,$C$4:$C$6,C7,$D$4:$D$6,D7,$E$4:$E$6,E7,$B$4:$B$6,"A REPROCESO")-SUMIFS($F$4:$F$6,$C$4:$C$6,C7,$D$4:$D$6,D7,$E$4:$E$6,E7,$B$4:$B$6,"MUESTRA")-SUMIFS($F$4:$F$6,$C$4:$C$6,C7,$D$4:$D$6,D7,$E$4:$E$6,E7,$B$4:$B$6,"AJUSTE-")),0) -> 0 | L7: =IF(C7="",0,K7+IF(OR(B7="INGRESO",B7="DE REPROCESO",B7="AJUSTE+"),F7,IF(OR(B7="A CORTE",B7="A REPROCESO",B7="MUESTRA",B7="AJUSTE-"),-F7,0))) -> 15 | M7: tomas | O7: progreso | R7: =IF(OR(Q7="",Q7=0,J7=0),"",(Q7-J7)/J7)
A8: 46146 | B8: INGRESO | C8: OverShark | D8: jersey 30/1 | E8: Pacay | F8: 10 | G8: =IFERROR(F8*VLOOKUP(D8,TELAS!$A$4:$C$32,3,FALSE()),0) -> 200 | H8: =IFERROR(VLOOKUP(E8,COLORES!$A$4:$B$102,2,FALSE()),"") -> CLARO | I8: =IFERROR(IF(H8="OSCURO",VLOOKUP(D8,PRECIOS!$A$4:$F$32,2,FALSE()),IF(H8="CLARO",VLOOKUP(D8,PRECIOS!$A$4:$F$32,3,FALSE()),IF(H8="MELANGE",VLOOKUP(D8,PRECIOS!$A$4:$F$32,4,FALSE()),IF(H8="PPT",VLOOKUP(D8,PRECIOS!$A$4:$F$32,5,FALSE()),0)))),0) -> 21 | J8: =IFERROR(G8*I8,0) -> 4200 | K8: =IFERROR(IF(C8="",0,SUMIFS($F$4:$F$7,$C$4:$C$7,C8,$D$4:$D$7,D8,$E$4:$E$7,E8,$B$4:$B$7,"INGRESO")+SUMIFS($F$4:$F$7,$C$4:$C$7,C8,$D$4:$D$7,D8,$E$4:$E$7,E8,$B$4:$B$7,"DE REPROCESO")+SUMIFS($F$4:$F$7,$C$4:$C$7,C8,$D$4:$D$7,D8,$E$4:$E$7,E8,$B$4:$B$7,"AJUSTE+")-SUMIFS($F$4:$F$7,$C$4:$C$7,C8,$D$4:$D$7,D8,$E$4:$E$7,E8,$B$4:$B$7,"A CORTE")-SUMIFS($F$4:$F$7,$C$4:$C$7,C8,$D$4:$D$7,D8,$E$4:$E$7,E8,$B$4:$B$7,"A REPROCESO")-SUMIFS($F$4:$F$7,$C$4:$C$7,C8,$D$4:$D$7,D8,$E$4:$E$7,E8,$B$4:$B$7,"MUESTRA")-SUMIFS($F$4:$F$7,$C$4:$C$7,C8,$D$4:$D$7,D8,$E$4:$E$7,E8,$B$4:$B$7,"AJUSTE-")),0) -> 0 | L8: =IF(C8="",0,K8+IF(OR(B8="INGRESO",B8="DE REPROCESO",B8="AJUSTE+"),F8,IF(OR(B8="A CORTE",B8="A REPROCESO",B8="MUESTRA",B8="AJUSTE-"),-F8,0))) -> 10 | M8: tomas | O8: progreso | R8: =IF(OR(Q8="",Q8=0,J8=0),"",(Q8-J8)/J8)
A9: 46146 | B9: INGRESO | C9: OverShark | D9: jersey 30/1 | E9: Cemento | F9: 23 | G9: =IFERROR(F9*VLOOKUP(D9,TELAS!$A$4:$C$32,3,FALSE()),0) -> 460 | H9: =IFERROR(VLOOKUP(E9,COLORES!$A$4:$B$102,2,FALSE()),"") -> CLARO | I9: =IFERROR(IF(H9="OSCURO",VLOOKUP(D9,PRECIOS!$A$4:$F$32,2,FALSE()),IF(H9="CLARO",VLOOKUP(D9,PRECIOS!$A$4:$F$32,3,FALSE()),IF(H9="MELANGE",VLOOKUP(D9,PRECIOS!$A$4:$F$32,4,FALSE()),IF(H9="PPT",VLOOKUP(D9,PRECIOS!$A$4:$F$32,5,FALSE()),0)))),0) -> 21 | J9: =IFERROR(G9*I9,0) -> 9660 | K9: =IFERROR(IF(C9="",0,SUMIFS($F$4:$F$8,$C$4:$C$8,C9,$D$4:$D$8,D9,$E$4:$E$8,E9,$B$4:$B$8,"INGRESO")+SUMIFS($F$4:$F$8,$C$4:$C$8,C9,$D$4:$D$8,D9,$E$4:$E$8,E9,$B$4:$B$8,"DE REPROCESO")+SUMIFS($F$4:$F$8,$C$4:$C$8,C9,$D$4:$D$8,D9,$E$4:$E$8,E9,$B$4:$B$8,"AJUSTE+")-SUMIFS($F$4:$F$8,$C$4:$C$8,C9,$D$4:$D$8,D9,$E$4:$E$8,E9,$B$4:$B$8,"A CORTE")-SUMIFS($F$4:$F$8,$C$4:$C$8,C9,$D$4:$D$8,D9,$E$4:$E$8,E9,$B$4:$B$8,"A REPROCESO")-SUMIFS($F$4:$F$8,$C$4:$C$8,C9,$D$4:$D$8,D9,$E$4:$E$8,E9,$B$4:$B$8,"MUESTRA")-SUMIFS($F$4:$F$8,$C$4:$C$8,C9,$D$4:$D$8,D9,$E$4:$E$8,E9,$B$4:$B$8,"AJUSTE-")),0) -> 0 | L9: =IF(C9="",0,K9+IF(OR(B9="INGRESO",B9="DE REPROCESO",B9="AJUSTE+"),F9,IF(OR(B9="A CORTE",B9="A REPROCESO",B9="MUESTRA",B9="AJUSTE-"),-F9,0))) -> 23 | M9: tomas | O9: progreso | R9: =IF(OR(Q9="",Q9=0,J9=0),"",(Q9-J9)/J9)
A10: 46146 | B10: INGRESO | C10: OverShark | D10: jersey 30/1 | E10: P. Rosa | F10: 24 | G10: =IFERROR(F10*VLOOKUP(D10,TELAS!$A$4:$C$32,3,FALSE()),0) -> 480 | H10: =IFERROR(VLOOKUP(E10,COLORES!$A$4:$B$102,2,FALSE()),"") -> CLARO | I10: =IFERROR(IF(H10="OSCURO",VLOOKUP(D10,PRECIOS!$A$4:$F$32,2,FALSE()),IF(H10="CLARO",VLOOKUP(D10,PRECIOS!$A$4:$F$32,3,FALSE()),IF(H10="MELANGE",VLOOKUP(D10,PRECIOS!$A$4:$F$32,4,FALSE()),IF(H10="PPT",VLOOKUP(D10,PRECIOS!$A$4:$F$32,5,FALSE()),0)))),0) -> 21 | J10: =IFERROR(G10*I10,0) -> 10080 | K10: =IFERROR(IF(C10="",0,SUMIFS($F$4:$F$9,$C$4:$C$9,C10,$D$4:$D$9,D10,$E$4:$E$9,E10,$B$4:$B$9,"INGRESO")+SUMIFS($F$4:$F$9,$C$4:$C$9,C10,$D$4:$D$9,D10,$E$4:$E$9,E10,$B$4:$B$9,"DE REPROCESO")+SUMIFS($F$4:$F$9,$C$4:$C$9,C10,$D$4:$D$9,D10,$E$4:$E$9,E10,$B$4:$B$9,"AJUSTE+")-SUMIFS($F$4:$F$9,$C$4:$C$9,C10,$D$4:$D$9,D10,$E$4:$E$9,E10,$B$4:$B$9,"A CORTE")-SUMIFS($F$4:$F$9,$C$4:$C$9,C10,$D$4:$D$9,D10,$E$4:$E$9,E10,$B$4:$B$9,"A REPROCESO")-SUMIFS($F$4:$F$9,$C$4:$C$9,C10,$D$4:$D$9,D10,$E$4:$E$9,E10,$B$4:$B$9,"MUESTRA")-SUMIFS($F$4:$F$9,$C$4:$C$9,C10,$D$4:$D$9,D10,$E$4:$E$9,E10,$B$4:$B$9,"AJUSTE-")),0) -> 0 | L10: =IF(C10="",0,K10+IF(OR(B10="INGRESO",B10="DE REPROCESO",B10="AJUSTE+"),F10,IF(OR(B10="A CORTE",B10="A REPROCESO",B10="MUESTRA",B10="AJUSTE-"),-F10,0))) -> 24 | M10: tomas | O10: progreso | R10: =IF(OR(Q10="",Q10=0,J10=0),"",(Q10-J10)/J10)
A11: 46146 | B11: INGRESO | C11: OverShark | D11: jersey 30/1 | E11: Beige | F11: 14 | G11: =IFERROR(F11*VLOOKUP(D11,TELAS!$A$4:$C$32,3,FALSE()),0) -> 280 | H11: =IFERROR(VLOOKUP(E11,COLORES!$A$4:$B$102,2,FALSE()),"") -> CLARO | I11: =IFERROR(IF(H11="OSCURO",VLOOKUP(D11,PRECIOS!$A$4:$F$32,2,FALSE()),IF(H11="CLARO",VLOOKUP(D11,PRECIOS!$A$4:$F$32,3,FALSE()),IF(H11="MELANGE",VLOOKUP(D11,PRECIOS!$A$4:$F$32,4,FALSE()),IF(H11="PPT",VLOOKUP(D11,PRECIOS!$A$4:$F$32,5,FALSE()),0)))),0) -> 21 | J11: =IFERROR(G11*I11,0) -> 5880 | K11: =IFERROR(IF(C11="",0,SUMIFS($F$4:$F$10,$C$4:$C$10,C11,$D$4:$D$10,D11,$E$4:$E$10,E11,$B$4:$B$10,"INGRESO")+SUMIFS($F$4:$F$10,$C$4:$C$10,C11,$D$4:$D$10,D11,$E$4:$E$10,E11,$B$4:$B$10,"DE REPROCESO")+SUMIFS($F$4:$F$10,$C$4:$C$10,C11,$D$4:$D$10,D11,$E$4:$E$10,E11,$B$4:$B$10,"AJUSTE+")-SUMIFS($F$4:$F$10,$C$4:$C$10,C11,$D$4:$D$10,D11,$E$4:$E$10,E11,$B$4:$B$10,"A CORTE")-SUMIFS($F$4:$F$10,$C$4:$C$10,C11,$D$4:$D$10,D11,$E$4:$E$10,E11,$B$4:$B$10,"A REPROCESO")-SUMIFS($F$4:$F$10,$C$4:$C$10,C11,$D$4:$D$10,D11,$E$4:$E$10,E11,$B$4:$B$10,"MUESTRA")-SUMIFS($F$4:$F$10,$C$4:$C$10,C11,$D$4:$D$10,D11,$E$4:$E$10,E11,$B$4:$B$10,"AJUSTE-")),0) -> 0 | L11: =IF(C11="",0,K11+IF(OR(B11="INGRESO",B11="DE REPROCESO",B11="AJUSTE+"),F11,IF(OR(B11="A CORTE",B11="A REPROCESO",B11="MUESTRA",B11="AJUSTE-"),-F11,0))) -> 14 | M11: tomas | O11: progreso | R11: =IF(OR(Q11="",Q11=0,J11=0),"",(Q11-J11)/J11)
A12: 46146 | B12: INGRESO | C12: OverShark | D12: jersey 30/1 | E12: Vino | F12: 18 | G12: =IFERROR(F12*VLOOKUP(D12,TELAS!$A$4:$C$32,3,FALSE()),0) -> 360 | H12: =IFERROR(VLOOKUP(E12,COLORES!$A$4:$B$102,2,FALSE()),"") -> OSCURO | I12: =IFERROR(IF(H12="OSCURO",VLOOKUP(D12,PRECIOS!$A$4:$F$32,2,FALSE()),IF(H12="CLARO",VLOOKUP(D12,PRECIOS!$A$4:$F$32,3,FALSE()),IF(H12="MELANGE",VLOOKUP(D12,PRECIOS!$A$4:$F$32,4,FALSE()),IF(H12="PPT",VLOOKUP(D12,PRECIOS!$A$4:$F$32,5,FALSE()),0)))),0) -> 24 | J12: =IFERROR(G12*I12,0) -> 8640 | K12: =IFERROR(IF(C12="",0,SUMIFS($F$4:$F$11,$C$4:$C$11,C12,$D$4:$D$11,D12,$E$4:$E$11,E12,$B$4:$B$11,"INGRESO")+SUMIFS($F$4:$F$11,$C$4:$C$11,C12,$D$4:$D$11,D12,$E$4:$E$11,E12,$B$4:$B$11,"DE REPROCESO")+SUMIFS($F$4:$F$11,$C$4:$C$11,C12,$D$4:$D$11,D12,$E$4:$E$11,E12,$B$4:$B$11,"AJUSTE+")-SUMIFS($F$4:$F$11,$C$4:$C$11,C12,$D$4:$D$11,D12,$E$4:$E$11,E12,$B$4:$B$11,"A CORTE")-SUMIFS($F$4:$F$11,$C$4:$C$11,C12,$D$4:$D$11,D12,$E$4:$E$11,E12,$B$4:$B$11,"A REPROCESO")-SUMIFS($F$4:$F$11,$C$4:$C$11,C12,$D$4:$D$11,D12,$E$4:$E$11,E12,$B$4:$B$11,"MUESTRA")-SUMIFS($F$4:$F$11,$C$4:$C$11,C12,$D$4:$D$11,D12,$E$4:$E$11,E12,$B$4:$B$11,"AJUSTE-")),0) -> 0 | L12: =IF(C12="",0,K12+IF(OR(B12="INGRESO",B12="DE REPROCESO",B12="AJUSTE+"),F12,IF(OR(B12="A CORTE",B12="A REPROCESO",B12="MUESTRA",B12="AJUSTE-"),-F12,0))) -> 18 | M12: tomas | O12: progreso | R12: =IF(OR(Q12="",Q12=0,J12=0),"",(Q12-J12)/J12)
A13: 46146 | B13: INGRESO | C13: OverShark | D13: jersey 30/1 | E13: Denim | F13: 18 | G13: =IFERROR(F13*VLOOKUP(D13,TELAS!$A$4:$C$32,3,FALSE()),0) -> 360 | H13: =IFERROR(VLOOKUP(E13,COLORES!$A$4:$B$102,2,FALSE()),"") -> CLARO | I13: =IFERROR(IF(H13="OSCURO",VLOOKUP(D13,PRECIOS!$A$4:$F$32,2,FALSE()),IF(H13="CLARO",VLOOKUP(D13,PRECIOS!$A$4:$F$32,3,FALSE()),IF(H13="MELANGE",VLOOKUP(D13,PRECIOS!$A$4:$F$32,4,FALSE()),IF(H13="PPT",VLOOKUP(D13,PRECIOS!$A$4:$F$32,5,FALSE()),0)))),0) -> 21 | J13: =IFERROR(G13*I13,0) -> 7560 | K13: =IFERROR(IF(C13="",0,SUMIFS($F$4:$F$12,$C$4:$C$12,C13,$D$4:$D$12,D13,$E$4:$E$12,E13,$B$4:$B$12,"INGRESO")+SUMIFS($F$4:$F$12,$C$4:$C$12,C13,$D$4:$D$12,D13,$E$4:$E$12,E13,$B$4:$B$12,"DE REPROCESO")+SUMIFS($F$4:$F$12,$C$4:$C$12,C13,$D$4:$D$12,D13,$E$4:$E$12,E13,$B$4:$B$12,"AJUSTE+")-SUMIFS($F$4:$F$12,$C$4:$C$12,C13,$D$4:$D$12,D13,$E$4:$E$12,E13,$B$4:$B$12,"A CORTE")-SUMIFS($F$4:$F$12,$C$4:$C$12,C13,$D$4:$D$12,D13,$E$4:$E$12,E13,$B$4:$B$12,"A REPROCESO")-SUMIFS($F$4:$F$12,$C$4:$C$12,C13,$D$4:$D$12,D13,$E$4:$E$12,E13,$B$4:$B$12,"MUESTRA")-SUMIFS($F$4:$F$12,$C$4:$C$12,C13,$D$4:$D$12,D13,$E$4:$E$12,E13,$B$4:$B$12,"AJUSTE-")),0) -> 0 | L13: =IF(C13="",0,K13+IF(OR(B13="INGRESO",B13="DE REPROCESO",B13="AJUSTE+"),F13,IF(OR(B13="A CORTE",B13="A REPROCESO",B13="MUESTRA",B13="AJUSTE-"),-F13,0))) -> 18 | M13: tomas | O13: progreso | R13: =IF(OR(Q13="",Q13=0,J13=0),"",(Q13-J13)/J13)
A14: 46146 | B14: INGRESO | C14: OverShark | D14: jersey 30/1 | E14: Plomo | F14: 15 | G14: =IFERROR(F14*VLOOKUP(D14,TELAS!$A$4:$C$32,3,FALSE()),0) -> 300 | H14: =IFERROR(VLOOKUP(E14,COLORES!$A$4:$B$102,2,FALSE()),"") -> OSCURO | I14: =IFERROR(IF(H14="OSCURO",VLOOKUP(D14,PRECIOS!$A$4:$F$32,2,FALSE()),IF(H14="CLARO",VLOOKUP(D14,PRECIOS!$A$4:$F$32,3,FALSE()),IF(H14="MELANGE",VLOOKUP(D14,PRECIOS!$A$4:$F$32,4,FALSE()),IF(H14="PPT",VLOOKUP(D14,PRECIOS!$A$4:$F$32,5,FALSE()),0)))),0) -> 24 | J14: =IFERROR(G14*I14,0) -> 7200 | K14: =IFERROR(IF(C14="",0,SUMIFS($F$4:$F$13,$C$4:$C$13,C14,$D$4:$D$13,D14,$E$4:$E$13,E14,$B$4:$B$13,"INGRESO")+SUMIFS($F$4:$F$13,$C$4:$C$13,C14,$D$4:$D$13,D14,$E$4:$E$13,E14,$B$4:$B$13,"DE REPROCESO")+SUMIFS($F$4:$F$13,$C$4:$C$13,C14,$D$4:$D$13,D14,$E$4:$E$13,E14,$B$4:$B$13,"AJUSTE+")-SUMIFS($F$4:$F$13,$C$4:$C$13,C14,$D$4:$D$13,D14,$E$4:$E$13,E14,$B$4:$B$13,"A CORTE")-SUMIFS($F$4:$F$13,$C$4:$C$13,C14,$D$4:$D$13,D14,$E$4:$E$13,E14,$B$4:$B$13,"A REPROCESO")-SUMIFS($F$4:$F$13,$C$4:$C$13,C14,$D$4:$D$13,D14,$E$4:$E$13,E14,$B$4:$B$13,"MUESTRA")-SUMIFS($F$4:$F$13,$C$4:$C$13,C14,$D$4:$D$13,D14,$E$4:$E$13,E14,$B$4:$B$13,"AJUSTE-")),0) -> 0 | L14: =IF(C14="",0,K14+IF(OR(B14="INGRESO",B14="DE REPROCESO",B14="AJUSTE+"),F14,IF(OR(B14="A CORTE",B14="A REPROCESO",B14="MUESTRA",B14="AJUSTE-"),-F14,0))) -> 15 | M14: tomas | O14: progreso | R14: =IF(OR(Q14="",Q14=0,J14=0),"",(Q14-J14)/J14)
A15: 46141 | B15: INGRESO | C15: Bravos | D15: french terry 24/1 | E15: Negro | F15: 37 | G15: =IFERROR(F15*VLOOKUP(D15,TELAS!$A$4:$C$32,3,FALSE()),0) -> 740 | H15: =IFERROR(VLOOKUP(E15,COLORES!$A$4:$B$102,2,FALSE()),"") -> OSCURO | I15: =IFERROR(IF(H15="OSCURO",VLOOKUP(D15,PRECIOS!$A$4:$F$32,2,FALSE()),IF(H15="CLARO",VLOOKUP(D15,PRECIOS!$A$4:$F$32,3,FALSE()),IF(H15="MELANGE",VLOOKUP(D15,PRECIOS!$A$4:$F$32,4,FALSE()),IF(H15="PPT",VLOOKUP(D15,PRECIOS!$A$4:$F$32,5,FALSE()),0)))),0) -> 24 | J15: =IFERROR(G15*I15,0) -> 17760 | K15: =IFERROR(IF(C15="",0,SUMIFS($F$4:$F$14,$C$4:$C$14,C15,$D$4:$D$14,D15,$E$4:$E$14,E15,$B$4:$B$14,"INGRESO")+SUMIFS($F$4:$F$14,$C$4:$C$14,C15,$D$4:$D$14,D15,$E$4:$E$14,E15,$B$4:$B$14,"DE REPROCESO")+SUMIFS($F$4:$F$14,$C$4:$C$14,C15,$D$4:$D$14,D15,$E$4:$E$14,E15,$B$4:$B$14,"AJUSTE+")-SUMIFS($F$4:$F$14,$C$4:$C$14,C15,$D$4:$D$14,D15,$E$4:$E$14,E15,$B$4:$B$14,"A CORTE")-SUMIFS($F$4:$F$14,$C$4:$C$14,C15,$D$4:$D$14,D15,$E$4:$E$14,E15,$B$4:$B$14,"A REPROCESO")-SUMIFS($F$4:$F$14,$C$4:$C$14,C15,$D$4:$D$14,D15,$E$4:$E$14,E15,$B$4:$B$14,"MUESTRA")-SUMIFS($F$4:$F$14,$C$4:$C$14,C15,$D$4:$D$14,D15,$E$4:$E$14,E15,$B$4:$B$14,"AJUSTE-")),0) -> 0 | L15: =IF(C15="",0,K15+IF(OR(B15="INGRESO",B15="DE REPROCESO",B15="AJUSTE+"),F15,IF(OR(B15="A CORTE",B15="A REPROCESO",B15="MUESTRA",B15="AJUSTE-"),-F15,0))) -> 37 | M15: tomas | O15: progreso | R15: =IF(OR(Q15="",Q15=0,J15=0),"",(Q15-J15)/J15)
A16: 46141 | B16: INGRESO | C16: Bravos | D16: french terry 24/1 | E16: Perla | F16: 28 | G16: =IFERROR(F16*VLOOKUP(D16,TELAS!$A$4:$C$32,3,FALSE()),0) -> 560 | H16: =IFERROR(VLOOKUP(E16,COLORES!$A$4:$B$102,2,FALSE()),"") -> PPT | I16: =IFERROR(IF(H16="OSCURO",VLOOKUP(D16,PRECIOS!$A$4:$F$32,2,FALSE()),IF(H16="CLARO",VLOOKUP(D16,PRECIOS!$A$4:$F$32,3,FALSE()),IF(H16="MELANGE",VLOOKUP(D16,PRECIOS!$A$4:$F$32,4,FALSE()),IF(H16="PPT",VLOOKUP(D16,PRECIOS!$A$4:$F$32,5,FALSE()),0)))),0) -> 18 | J16: =IFERROR(G16*I16,0) -> 10080 | K16: =IFERROR(IF(C16="",0,SUMIFS($F$4:$F$15,$C$4:$C$15,C16,$D$4:$D$15,D16,$E$4:$E$15,E16,$B$4:$B$15,"INGRESO")+SUMIFS($F$4:$F$15,$C$4:$C$15,C16,$D$4:$D$15,D16,$E$4:$E$15,E16,$B$4:$B$15,"DE REPROCESO")+SUMIFS($F$4:$F$15,$C$4:$C$15,C16,$D$4:$D$15,D16,$E$4:$E$15,E16,$B$4:$B$15,"AJUSTE+")-SUMIFS($F$4:$F$15,$C$4:$C$15,C16,$D$4:$D$15,D16,$E$4:$E$15,E16,$B$4:$B$15,"A CORTE")-SUMIFS($F$4:$F$15,$C$4:$C$15,C16,$D$4:$D$15,D16,$E$4:$E$15,E16,$B$4:$B$15,"A REPROCESO")-SUMIFS($F$4:$F$15,$C$4:$C$15,C16,$D$4:$D$15,D16,$E$4:$E$15,E16,$B$4:$B$15,"MUESTRA")-SUMIFS($F$4:$F$15,$C$4:$C$15,C16,$D$4:$D$15,D16,$E$4:$E$15,E16,$B$4:$B$15,"AJUSTE-")),0) -> 0 | L16: =IF(C16="",0,K16+IF(OR(B16="INGRESO",B16="DE REPROCESO",B16="AJUSTE+"),F16,IF(OR(B16="A CORTE",B16="A REPROCESO",B16="MUESTRA",B16="AJUSTE-"),-F16,0))) -> 28 | M16: tomas | O16: progreso | R16: =IF(OR(Q16="",Q16=0,J16=0),"",(Q16-J16)/J16)
A17: 46141 | B17: INGRESO | C17: Bravos | D17: french terry 24/1 | E17: Azul | F17: 7 | G17: =IFERROR(F17*VLOOKUP(D17,TELAS!$A$4:$C$32,3,FALSE()),0) -> 140 | H17: =IFERROR(VLOOKUP(E17,COLORES!$A$4:$B$102,2,FALSE()),"") -> OSCURO | I17: =IFERROR(IF(H17="OSCURO",VLOOKUP(D17,PRECIOS!$A$4:$F$32,2,FALSE()),IF(H17="CLARO",VLOOKUP(D17,PRECIOS!$A$4:$F$32,3,FALSE()),IF(H17="MELANGE",VLOOKUP(D17,PRECIOS!$A$4:$F$32,4,FALSE()),IF(H17="PPT",VLOOKUP(D17,PRECIOS!$A$4:$F$32,5,FALSE()),0)))),0) -> 24 | J17: =IFERROR(G17*I17,0) -> 3360 | K17: =IFERROR(IF(C17="",0,SUMIFS($F$4:$F$16,$C$4:$C$16,C17,$D$4:$D$16,D17,$E$4:$E$16,E17,$B$4:$B$16,"INGRESO")+SUMIFS($F$4:$F$16,$C$4:$C$16,C17,$D$4:$D$16,D17,$E$4:$E$16,E17,$B$4:$B$16,"DE REPROCESO")+SUMIFS($F$4:$F$16,$C$4:$C$16,C17,$D$4:$D$16,D17,$E$4:$E$16,E17,$B$4:$B$16,"AJUSTE+")-SUMIFS($F$4:$F$16,$C$4:$C$16,C17,$D$4:$D$16,D17,$E$4:$E$16,E17,$B$4:$B$16,"A CORTE")-SUMIFS($F$4:$F$16,$C$4:$C$16,C17,$D$4:$D$16,D17,$E$4:$E$16,E17,$B$4:$B$16,"A REPROCESO")-SUMIFS($F$4:$F$16,$C$4:$C$16,C17,$D$4:$D$16,D17,$E$4:$E$16,E17,$B$4:$B$16,"MUESTRA")-SUMIFS($F$4:$F$16,$C$4:$C$16,C17,$D$4:$D$16,D17,$E$4:$E$16,E17,$B$4:$B$16,"AJUSTE-")),0) -> 0 | L17: =IF(C17="",0,K17+IF(OR(B17="INGRESO",B17="DE REPROCESO",B17="AJUSTE+"),F17,IF(OR(B17="A CORTE",B17="A REPROCESO",B17="MUESTRA",B17="AJUSTE-"),-F17,0))) -> 7 | M17: tomas | O17: progreso | R17: =IF(OR(Q17="",Q17=0,J17=0),"",(Q17-J17)/J17)
A18: 46141 | B18: INGRESO | C18: Bravos | D18: french terry 24/1 | E18: Botella | F18: 5 | G18: =IFERROR(F18*VLOOKUP(D18,TELAS!$A$4:$C$32,3,FALSE()),0) -> 100 | H18: =IFERROR(VLOOKUP(E18,COLORES!$A$4:$B$102,2,FALSE()),"") -> OSCURO | I18: =IFERROR(IF(H18="OSCURO",VLOOKUP(D18,PRECIOS!$A$4:$F$32,2,FALSE()),IF(H18="CLARO",VLOOKUP(D18,PRECIOS!$A$4:$F$32,3,FALSE()),IF(H18="MELANGE",VLOOKUP(D18,PRECIOS!$A$4:$F$32,4,FALSE()),IF(H18="PPT",VLOOKUP(D18,PRECIOS!$A$4:$F$32,5,FALSE()),0)))),0) -> 24 | J18: =IFERROR(G18*I18,0) -> 2400 | K18: =IFERROR(IF(C18="",0,SUMIFS($F$4:$F$17,$C$4:$C$17,C18,$D$4:$D$17,D18,$E$4:$E$17,E18,$B$4:$B$17,"INGRESO")+SUMIFS($F$4:$F$17,$C$4:$C$17,C18,$D$4:$D$17,D18,$E$4:$E$17,E18,$B$4:$B$17,"DE REPROCESO")+SUMIFS($F$4:$F$17,$C$4:$C$17,C18,$D$4:$D$17,D18,$E$4:$E$17,E18,$B$4:$B$17,"AJUSTE+")-SUMIFS($F$4:$F$17,$C$4:$C$17,C18,$D$4:$D$17,D18,$E$4:$E$17,E18,$B$4:$B$17,"A CORTE")-SUMIFS($F$4:$F$17,$C$4:$C$17,C18,$D$4:$D$17,D18,$E$4:$E$17,E18,$B$4:$B$17,"A REPROCESO")-SUMIFS($F$4:$F$17,$C$4:$C$17,C18,$D$4:$D$17,D18,$E$4:$E$17,E18,$B$4:$B$17,"MUESTRA")-SUMIFS($F$4:$F$17,$C$4:$C$17,C18,$D$4:$D$17,D18,$E$4:$E$17,E18,$B$4:$B$17,"AJUSTE-")),0) -> 0 | L18: =IF(C18="",0,K18+IF(OR(B18="INGRESO",B18="DE REPROCESO",B18="AJUSTE+"),F18,IF(OR(B18="A CORTE",B18="A REPROCESO",B18="MUESTRA",B18="AJUSTE-"),-F18,0))) -> 5 | M18: tomas | O18: progreso | R18: =IF(OR(Q18="",Q18=0,J18=0),"",(Q18-J18)/J18)
A19: 46141 | B19: INGRESO | C19: Bravos | D19: french terry 24/1 | E19: Pacay | F19: 1 | G19: =IFERROR(F19*VLOOKUP(D19,TELAS!$A$4:$C$32,3,FALSE()),0) -> 20 | H19: =IFERROR(VLOOKUP(E19,COLORES!$A$4:$B$102,2,FALSE()),"") -> CLARO | I19: =IFERROR(IF(H19="OSCURO",VLOOKUP(D19,PRECIOS!$A$4:$F$32,2,FALSE()),IF(H19="CLARO",VLOOKUP(D19,PRECIOS!$A$4:$F$32,3,FALSE()),IF(H19="MELANGE",VLOOKUP(D19,PRECIOS!$A$4:$F$32,4,FALSE()),IF(H19="PPT",VLOOKUP(D19,PRECIOS!$A$4:$F$32,5,FALSE()),0)))),0) -> 21 | J19: =IFERROR(G19*I19,0) -> 420 | K19: =IFERROR(IF(C19="",0,SUMIFS($F$4:$F$18,$C$4:$C$18,C19,$D$4:$D$18,D19,$E$4:$E$18,E19,$B$4:$B$18,"INGRESO")+SUMIFS($F$4:$F$18,$C$4:$C$18,C19,$D$4:$D$18,D19,$E$4:$E$18,E19,$B$4:$B$18,"DE REPROCESO")+SUMIFS($F$4:$F$18,$C$4:$C$18,C19,$D$4:$D$18,D19,$E$4:$E$18,E19,$B$4:$B$18,"AJUSTE+")-SUMIFS($F$4:$F$18,$C$4:$C$18,C19,$D$4:$D$18,D19,$E$4:$E$18,E19,$B$4:$B$18,"A CORTE")-SUMIFS($F$4:$F$18,$C$4:$C$18,C19,$D$4:$D$18,D19,$E$4:$E$18,E19,$B$4:$B$18,"A REPROCESO")-SUMIFS($F$4:$F$18,$C$4:$C$18,C19,$D$4:$D$18,D19,$E$4:$E$18,E19,$B$4:$B$18,"MUESTRA")-SUMIFS($F$4:$F$18,$C$4:$C$18,C19,$D$4:$D$18,D19,$E$4:$E$18,E19,$B$4:$B$18,"AJUSTE-")),0) -> 0 | L19: =IF(C19="",0,K19+IF(OR(B19="INGRESO",B19="DE REPROCESO",B19="AJUSTE+"),F19,IF(OR(B19="A CORTE",B19="A REPROCESO",B19="MUESTRA",B19="AJUSTE-"),-F19,0))) -> 1 | M19: tomas | O19: progreso | R19: =IF(OR(Q19="",Q19=0,J19=0),"",(Q19-J19)/J19)
A20: 46141 | B20: INGRESO | C20: Bravos | D20: french terry 24/1 | E20: P. Rosa | F20: 2 | G20: =IFERROR(F20*VLOOKUP(D20,TELAS!$A$4:$C$32,3,FALSE()),0) -> 40 | H20: =IFERROR(VLOOKUP(E20,COLORES!$A$4:$B$102,2,FALSE()),"") -> CLARO | I20: =IFERROR(IF(H20="OSCURO",VLOOKUP(D20,PRECIOS!$A$4:$F$32,2,FALSE()),IF(H20="CLARO",VLOOKUP(D20,PRECIOS!$A$4:$F$32,3,FALSE()),IF(H20="MELANGE",VLOOKUP(D20,PRECIOS!$A$4:$F$32,4,FALSE()),IF(H20="PPT",VLOOKUP(D20,PRECIOS!$A$4:$F$32,5,FALSE()),0)))),0) -> 21 | J20: =IFERROR(G20*I20,0) -> 840 | K20: =IFERROR(IF(C20="",0,SUMIFS($F$4:$F$19,$C$4:$C$19,C20,$D$4:$D$19,D20,$E$4:$E$19,E20,$B$4:$B$19,"INGRESO")+SUMIFS($F$4:$F$19,$C$4:$C$19,C20,$D$4:$D$19,D20,$E$4:$E$19,E20,$B$4:$B$19,"DE REPROCESO")+SUMIFS($F$4:$F$19,$C$4:$C$19,C20,$D$4:$D$19,D20,$E$4:$E$19,E20,$B$4:$B$19,"AJUSTE+")-SUMIFS($F$4:$F$19,$C$4:$C$19,C20,$D$4:$D$19,D20,$E$4:$E$19,E20,$B$4:$B$19,"A CORTE")-SUMIFS($F$4:$F$19,$C$4:$C$19,C20,$D$4:$D$19,D20,$E$4:$E$19,E20,$B$4:$B$19,"A REPROCESO")-SUMIFS($F$4:$F$19,$C$4:$C$19,C20,$D$4:$D$19,D20,$E$4:$E$19,E20,$B$4:$B$19,"MUESTRA")-SUMIFS($F$4:$F$19,$C$4:$C$19,C20,$D$4:$D$19,D20,$E$4:$E$19,E20,$B$4:$B$19,"AJUSTE-")),0) -> 0 | L20: =IF(C20="",0,K20+IF(OR(B20="INGRESO",B20="DE REPROCESO",B20="AJUSTE+"),F20,IF(OR(B20="A CORTE",B20="A REPROCESO",B20="MUESTRA",B20="AJUSTE-"),-F20,0))) -> 2 | M20: tomas | O20: progreso | R20: =IF(OR(Q20="",Q20=0,J20=0),"",(Q20-J20)/J20)
A21: 46141 | B21: INGRESO | C21: Bravos | D21: french terry 24/1 | E21: Beige | F21: 2 | G21: =IFERROR(F21*VLOOKUP(D21,TELAS!$A$4:$C$32,3,FALSE()),0) -> 40 | H21: =IFERROR(VLOOKUP(E21,COLORES!$A$4:$B$102,2,FALSE()),"") -> CLARO | I21: =IFERROR(IF(H21="OSCURO",VLOOKUP(D21,PRECIOS!$A$4:$F$32,2,FALSE()),IF(H21="CLARO",VLOOKUP(D21,PRECIOS!$A$4:$F$32,3,FALSE()),IF(H21="MELANGE",VLOOKUP(D21,PRECIOS!$A$4:$F$32,4,FALSE()),IF(H21="PPT",VLOOKUP(D21,PRECIOS!$A$4:$F$32,5,FALSE()),0)))),0) -> 21 | J21: =IFERROR(G21*I21,0) -> 840 | K21: =IFERROR(IF(C21="",0,SUMIFS($F$4:$F$20,$C$4:$C$20,C21,$D$4:$D$20,D21,$E$4:$E$20,E21,$B$4:$B$20,"INGRESO")+SUMIFS($F$4:$F$20,$C$4:$C$20,C21,$D$4:$D$20,D21,$E$4:$E$20,E21,$B$4:$B$20,"DE REPROCESO")+SUMIFS($F$4:$F$20,$C$4:$C$20,C21,$D$4:$D$20,D21,$E$4:$E$20,E21,$B$4:$B$20,"AJUSTE+")-SUMIFS($F$4:$F$20,$C$4:$C$20,C21,$D$4:$D$20,D21,$E$4:$E$20,E21,$B$4:$B$20,"A CORTE")-SUMIFS($F$4:$F$20,$C$4:$C$20,C21,$D$4:$D$20,D21,$E$4:$E$20,E21,$B$4:$B$20,"A REPROCESO")-SUMIFS($F$4:$F$20,$C$4:$C$20,C21,$D$4:$D$20,D21,$E$4:$E$20,E21,$B$4:$B$20,"MUESTRA")-SUMIFS($F$4:$F$20,$C$4:$C$20,C21,$D$4:$D$20,D21,$E$4:$E$20,E21,$B$4:$B$20,"AJUSTE-")),0) -> 0 | L21: =IF(C21="",0,K21+IF(OR(B21="INGRESO",B21="DE REPROCESO",B21="AJUSTE+"),F21,IF(OR(B21="A CORTE",B21="A REPROCESO",B21="MUESTRA",B21="AJUSTE-"),-F21,0))) -> 2 | M21: tomas | O21: progreso | R21: =IF(OR(Q21="",Q21=0,J21=0),"",(Q21-J21)/J21)
A22: 46141 | B22: INGRESO | C22: Bravos | D22: french terry 24/1 | E22: Denim | F22: 1 | G22: =IFERROR(F22*VLOOKUP(D22,TELAS!$A$4:$C$32,3,FALSE()),0) -> 20 | H22: =IFERROR(VLOOKUP(E22,COLORES!$A$4:$B$102,2,FALSE()),"") -> CLARO | I22: =IFERROR(IF(H22="OSCURO",VLOOKUP(D22,PRECIOS!$A$4:$F$32,2,FALSE()),IF(H22="CLARO",VLOOKUP(D22,PRECIOS!$A$4:$F$32,3,FALSE()),IF(H22="MELANGE",VLOOKUP(D22,PRECIOS!$A$4:$F$32,4,FALSE()),IF(H22="PPT",VLOOKUP(D22,PRECIOS!$A$4:$F$32,5,FALSE()),0)))),0) -> 21 | J22: =IFERROR(G22*I22,0) -> 420 | K22: =IFERROR(IF(C22="",0,SUMIFS($F$4:$F$21,$C$4:$C$21,C22,$D$4:$D$21,D22,$E$4:$E$21,E22,$B$4:$B$21,"INGRESO")+SUMIFS($F$4:$F$21,$C$4:$C$21,C22,$D$4:$D$21,D22,$E$4:$E$21,E22,$B$4:$B$21,"DE REPROCESO")+SUMIFS($F$4:$F$21,$C$4:$C$21,C22,$D$4:$D$21,D22,$E$4:$E$21,E22,$B$4:$B$21,"AJUSTE+")-SUMIFS($F$4:$F$21,$C$4:$C$21,C22,$D$4:$D$21,D22,$E$4:$E$21,E22,$B$4:$B$21,"A CORTE")-SUMIFS($F$4:$F$21,$C$4:$C$21,C22,$D$4:$D$21,D22,$E$4:$E$21,E22,$B$4:$B$21,"A REPROCESO")-SUMIFS($F$4:$F$21,$C$4:$C$21,C22,$D$4:$D$21,D22,$E$4:$E$21,E22,$B$4:$B$21,"MUESTRA")-SUMIFS($F$4:$F$21,$C$4:$C$21,C22,$D$4:$D$21,D22,$E$4:$E$21,E22,$B$4:$B$21,"AJUSTE-")),0) -> 0 | L22: =IF(C22="",0,K22+IF(OR(B22="INGRESO",B22="DE REPROCESO",B22="AJUSTE+"),F22,IF(OR(B22="A CORTE",B22="A REPROCESO",B22="MUESTRA",B22="AJUSTE-"),-F22,0))) -> 1 | M22: tomas | O22: progreso | R22: =IF(OR(Q22="",Q22=0,J22=0),"",(Q22-J22)/J22)
A23: 46141 | B23: INGRESO | C23: Bravos | D23: french terry 24/1 | E23: Plomo | F23: 4 | G23: =IFERROR(F23*VLOOKUP(D23,TELAS!$A$4:$C$32,3,FALSE()),0) -> 80 | H23: =IFERROR(VLOOKUP(E23,COLORES!$A$4:$B$102,2,FALSE()),"") -> OSCURO | I23: =IFERROR(IF(H23="OSCURO",VLOOKUP(D23,PRECIOS!$A$4:$F$32,2,FALSE()),IF(H23="CLARO",VLOOKUP(D23,PRECIOS!$A$4:$F$32,3,FALSE()),IF(H23="MELANGE",VLOOKUP(D23,PRECIOS!$A$4:$F$32,4,FALSE()),IF(H23="PPT",VLOOKUP(D23,PRECIOS!$A$4:$F$32,5,FALSE()),0)))),0) -> 24 | J23: =IFERROR(G23*I23,0) -> 1920 | K23: =IFERROR(IF(C23="",0,SUMIFS($F$4:$F$22,$C$4:$C$22,C23,$D$4:$D$22,D23,$E$4:$E$22,E23,$B$4:$B$22,"INGRESO")+SUMIFS($F$4:$F$22,$C$4:$C$22,C23,$D$4:$D$22,D23,$E$4:$E$22,E23,$B$4:$B$22,"DE REPROCESO")+SUMIFS($F$4:$F$22,$C$4:$C$22,C23,$D$4:$D$22,D23,$E$4:$E$22,E23,$B$4:$B$22,"AJUSTE+")-SUMIFS($F$4:$F$22,$C$4:$C$22,C23,$D$4:$D$22,D23,$E$4:$E$22,E23,$B$4:$B$22,"A CORTE")-SUMIFS($F$4:$F$22,$C$4:$C$22,C23,$D$4:$D$22,D23,$E$4:$E$22,E23,$B$4:$B$22,"A REPROCESO")-SUMIFS($F$4:$F$22,$C$4:$C$22,C23,$D$4:$D$22,D23,$E$4:$E$22,E23,$B$4:$B$22,"MUESTRA")-SUMIFS($F$4:$F$22,$C$4:$C$22,C23,$D$4:$D$22,D23,$E$4:$E$22,E23,$B$4:$B$22,"AJUSTE-")),0) -> 0 | L23: =IF(C23="",0,K23+IF(OR(B23="INGRESO",B23="DE REPROCESO",B23="AJUSTE+"),F23,IF(OR(B23="A CORTE",B23="A REPROCESO",B23="MUESTRA",B23="AJUSTE-"),-F23,0))) -> 4 | M23: tomas | O23: progreso | R23: =IF(OR(Q23="",Q23=0,J23=0),"",(Q23-J23)/J23)
A24: 46142 | B24: INGRESO | C24: OverShark | D24: pique 30/1 | E24: Perla | F24: 10 | G24: =IFERROR(F24*VLOOKUP(D24,TELAS!$A$4:$C$32,3,FALSE()),0) -> 200 | H24: =IFERROR(VLOOKUP(E24,COLORES!$A$4:$B$102,2,FALSE()),"") -> PPT | I24: =IFERROR(IF(H24="OSCURO",VLOOKUP(D24,PRECIOS!$A$4:$F$32,2,FALSE()),IF(H24="CLARO",VLOOKUP(D24,PRECIOS!$A$4:$F$32,3,FALSE()),IF(H24="MELANGE",VLOOKUP(D24,PRECIOS!$A$4:$F$32,4,FALSE()),IF(H24="PPT",VLOOKUP(D24,PRECIOS!$A$4:$F$32,5,FALSE()),0)))),0) -> 18 | J24: =IFERROR(G24*I24,0) -> 3600 | K24: =IFERROR(IF(C24="",0,SUMIFS($F$4:$F$23,$C$4:$C$23,C24,$D$4:$D$23,D24,$E$4:$E$23,E24,$B$4:$B$23,"INGRESO")+SUMIFS($F$4:$F$23,$C$4:$C$23,C24,$D$4:$D$23,D24,$E$4:$E$23,E24,$B$4:$B$23,"DE REPROCESO")+SUMIFS($F$4:$F$23,$C$4:$C$23,C24,$D$4:$D$23,D24,$E$4:$E$23,E24,$B$4:$B$23,"AJUSTE+")-SUMIFS($F$4:$F$23,$C$4:$C$23,C24,$D$4:$D$23,D24,$E$4:$E$23,E24,$B$4:$B$23,"A CORTE")-SUMIFS($F$4:$F$23,$C$4:$C$23,C24,$D$4:$D$23,D24,$E$4:$E$23,E24,$B$4:$B$23,"A REPROCESO")-SUMIFS($F$4:$F$23,$C$4:$C$23,C24,$D$4:$D$23,D24,$E$4:$E$23,E24,$B$4:$B$23,"MUESTRA")-SUMIFS($F$4:$F$23,$C$4:$C$23,C24,$D$4:$D$23,D24,$E$4:$E$23,E24,$B$4:$B$23,"AJUSTE-")),0) -> 0 | L24: =IF(C24="",0,K24+IF(OR(B24="INGRESO",B24="DE REPROCESO",B24="AJUSTE+"),F24,IF(OR(B24="A CORTE",B24="A REPROCESO",B24="MUESTRA",B24="AJUSTE-"),-F24,0))) -> 10 | M24: tomas | O24: progreso | R24: =IF(OR(Q24="",Q24=0,J24=0),"",(Q24-J24)/J24)
A25: 46142 | B25: INGRESO | C25: OverShark | D25: pique 30/1 | E25: Azul | F25: 6 | G25: =IFERROR(F25*VLOOKUP(D25,TELAS!$A$4:$C$32,3,FALSE()),0) -> 120 | H25: =IFERROR(VLOOKUP(E25,COLORES!$A$4:$B$102,2,FALSE()),"") -> OSCURO | I25: =IFERROR(IF(H25="OSCURO",VLOOKUP(D25,PRECIOS!$A$4:$F$32,2,FALSE()),IF(H25="CLARO",VLOOKUP(D25,PRECIOS!$A$4:$F$32,3,FALSE()),IF(H25="MELANGE",VLOOKUP(D25,PRECIOS!$A$4:$F$32,4,FALSE()),IF(H25="PPT",VLOOKUP(D25,PRECIOS!$A$4:$F$32,5,FALSE()),0)))),0) -> 24 | J25: =IFERROR(G25*I25,0) -> 2880 | K25: =IFERROR(IF(C25="",0,SUMIFS($F$4:$F$24,$C$4:$C$24,C25,$D$4:$D$24,D25,$E$4:$E$24,E25,$B$4:$B$24,"INGRESO")+SUMIFS($F$4:$F$24,$C$4:$C$24,C25,$D$4:$D$24,D25,$E$4:$E$24,E25,$B$4:$B$24,"DE REPROCESO")+SUMIFS($F$4:$F$24,$C$4:$C$24,C25,$D$4:$D$24,D25,$E$4:$E$24,E25,$B$4:$B$24,"AJUSTE+")-SUMIFS($F$4:$F$24,$C$4:$C$24,C25,$D$4:$D$24,D25,$E$4:$E$24,E25,$B$4:$B$24,"A CORTE")-SUMIFS($F$4:$F$24,$C$4:$C$24,C25,$D$4:$D$24,D25,$E$4:$E$24,E25,$B$4:$B$24,"A REPROCESO")-SUMIFS($F$4:$F$24,$C$4:$C$24,C25,$D$4:$D$24,D25,$E$4:$E$24,E25,$B$4:$B$24,"MUESTRA")-SUMIFS($F$4:$F$24,$C$4:$C$24,C25,$D$4:$D$24,D25,$E$4:$E$24,E25,$B$4:$B$24,"AJUSTE-")),0) -> 0 | L25: =IF(C25="",0,K25+IF(OR(B25="INGRESO",B25="DE REPROCESO",B25="AJUSTE+"),F25,IF(OR(B25="A CORTE",B25="A REPROCESO",B25="MUESTRA",B25="AJUSTE-"),-F25,0))) -> 6 | M25: tomas | O25: progreso | R25: =IF(OR(Q25="",Q25=0,J25=0),"",(Q25-J25)/J25)
A26: 46142 | B26: INGRESO | C26: OverShark | D26: pique 30/1 | E26: Botella | F26: 6 | G26: =IFERROR(F26*VLOOKUP(D26,TELAS!$A$4:$C$32,3,FALSE()),0) -> 120 | H26: =IFERROR(VLOOKUP(E26,COLORES!$A$4:$B$102,2,FALSE()),"") -> OSCURO | I26: =IFERROR(IF(H26="OSCURO",VLOOKUP(D26,PRECIOS!$A$4:$F$32,2,FALSE()),IF(H26="CLARO",VLOOKUP(D26,PRECIOS!$A$4:$F$32,3,FALSE()),IF(H26="MELANGE",VLOOKUP(D26,PRECIOS!$A$4:$F$32,4,FALSE()),IF(H26="PPT",VLOOKUP(D26,PRECIOS!$A$4:$F$32,5,FALSE()),0)))),0) -> 24 | J26: =IFERROR(G26*I26,0) -> 2880 | K26: =IFERROR(IF(C26="",0,SUMIFS($F$4:$F$25,$C$4:$C$25,C26,$D$4:$D$25,D26,$E$4:$E$25,E26,$B$4:$B$25,"INGRESO")+SUMIFS($F$4:$F$25,$C$4:$C$25,C26,$D$4:$D$25,D26,$E$4:$E$25,E26,$B$4:$B$25,"DE REPROCESO")+SUMIFS($F$4:$F$25,$C$4:$C$25,C26,$D$4:$D$25,D26,$E$4:$E$25,E26,$B$4:$B$25,"AJUSTE+")-SUMIFS($F$4:$F$25,$C$4:$C$25,C26,$D$4:$D$25,D26,$E$4:$E$25,E26,$B$4:$B$25,"A CORTE")-SUMIFS($F$4:$F$25,$C$4:$C$25,C26,$D$4:$D$25,D26,$E$4:$E$25,E26,$B$4:$B$25,"A REPROCESO")-SUMIFS($F$4:$F$25,$C$4:$C$25,C26,$D$4:$D$25,D26,$E$4:$E$25,E26,$B$4:$B$25,"MUESTRA")-SUMIFS($F$4:$F$25,$C$4:$C$25,C26,$D$4:$D$25,D26,$E$4:$E$25,E26,$B$4:$B$25,"AJUSTE-")),0) -> 0 | L26: =IF(C26="",0,K26+IF(OR(B26="INGRESO",B26="DE REPROCESO",B26="AJUSTE+"),F26,IF(OR(B26="A CORTE",B26="A REPROCESO",B26="MUESTRA",B26="AJUSTE-"),-F26,0))) -> 6 | M26: tomas | O26: progreso | R26: =IF(OR(Q26="",Q26=0,J26=0),"",(Q26-J26)/J26)
A27: 46142 | B27: INGRESO | C27: OverShark | D27: pique 30/1 | E27: Pacay | F27: 13 | G27: =IFERROR(F27*VLOOKUP(D27,TELAS!$A$4:$C$32,3,FALSE()),0) -> 260 | H27: =IFERROR(VLOOKUP(E27,COLORES!$A$4:$B$102,2,FALSE()),"") -> CLARO | I27: =IFERROR(IF(H27="OSCURO",VLOOKUP(D27,PRECIOS!$A$4:$F$32,2,FALSE()),IF(H27="CLARO",VLOOKUP(D27,PRECIOS!$A$4:$F$32,3,FALSE()),IF(H27="MELANGE",VLOOKUP(D27,PRECIOS!$A$4:$F$32,4,FALSE()),IF(H27="PPT",VLOOKUP(D27,PRECIOS!$A$4:$F$32,5,FALSE()),0)))),0) -> 21 | J27: =IFERROR(G27*I27,0) -> 5460 | K27: =IFERROR(IF(C27="",0,SUMIFS($F$4:$F$26,$C$4:$C$26,C27,$D$4:$D$26,D27,$E$4:$E$26,E27,$B$4:$B$26,"INGRESO")+SUMIFS($F$4:$F$26,$C$4:$C$26,C27,$D$4:$D$26,D27,$E$4:$E$26,E27,$B$4:$B$26,"DE REPROCESO")+SUMIFS($F$4:$F$26,$C$4:$C$26,C27,$D$4:$D$26,D27,$E$4:$E$26,E27,$B$4:$B$26,"AJUSTE+")-SUMIFS($F$4:$F$26,$C$4:$C$26,C27,$D$4:$D$26,D27,$E$4:$E$26,E27,$B$4:$B$26,"A CORTE")-SUMIFS($F$4:$F$26,$C$4:$C$26,C27,$D$4:$D$26,D27,$E$4:$E$26,E27,$B$4:$B$26,"A REPROCESO")-SUMIFS($F$4:$F$26,$C$4:$C$26,C27,$D$4:$D$26,D27,$E$4:$E$26,E27,$B$4:$B$26,"MUESTRA")-SUMIFS($F$4:$F$26,$C$4:$C$26,C27,$D$4:$D$26,D27,$E$4:$E$26,E27,$B$4:$B$26,"AJUSTE-")),0) -> 0 | L27: =IF(C27="",0,K27+IF(OR(B27="INGRESO",B27="DE REPROCESO",B27="AJUSTE+"),F27,IF(OR(B27="A CORTE",B27="A REPROCESO",B27="MUESTRA",B27="AJUSTE-"),-F27,0))) -> 13 | M27: tomas | O27: progreso | R27: =IF(OR(Q27="",Q27=0,J27=0),"",(Q27-J27)/J27)
A28: 46142 | B28: INGRESO | C28: OverShark | D28: pique 30/1 | E28: Cemento | F28: 9 | G28: =IFERROR(F28*VLOOKUP(D28,TELAS!$A$4:$C$32,3,FALSE()),0) -> 180 | H28: =IFERROR(VLOOKUP(E28,COLORES!$A$4:$B$102,2,FALSE()),"") -> CLARO | I28: =IFERROR(IF(H28="OSCURO",VLOOKUP(D28,PRECIOS!$A$4:$F$32,2,FALSE()),IF(H28="CLARO",VLOOKUP(D28,PRECIOS!$A$4:$F$32,3,FALSE()),IF(H28="MELANGE",VLOOKUP(D28,PRECIOS!$A$4:$F$32,4,FALSE()),IF(H28="PPT",VLOOKUP(D28,PRECIOS!$A$4:$F$32,5,FALSE()),0)))),0) -> 21 | J28: =IFERROR(G28*I28,0) -> 3780 | K28: =IFERROR(IF(C28="",0,SUMIFS($F$4:$F$27,$C$4:$C$27,C28,$D$4:$D$27,D28,$E$4:$E$27,E28,$B$4:$B$27,"INGRESO")+SUMIFS($F$4:$F$27,$C$4:$C$27,C28,$D$4:$D$27,D28,$E$4:$E$27,E28,$B$4:$B$27,"DE REPROCESO")+SUMIFS($F$4:$F$27,$C$4:$C$27,C28,$D$4:$D$27,D28,$E$4:$E$27,E28,$B$4:$B$27,"AJUSTE+")-SUMIFS($F$4:$F$27,$C$4:$C$27,C28,$D$4:$D$27,D28,$E$4:$E$27,E28,$B$4:$B$27,"A CORTE")-SUMIFS($F$4:$F$27,$C$4:$C$27,C28,$D$4:$D$27,D28,$E$4:$E$27,E28,$B$4:$B$27,"A REPROCESO")-SUMIFS($F$4:$F$27,$C$4:$C$27,C28,$D$4:$D$27,D28,$E$4:$E$27,E28,$B$4:$B$27,"MUESTRA")-SUMIFS($F$4:$F$27,$C$4:$C$27,C28,$D$4:$D$27,D28,$E$4:$E$27,E28,$B$4:$B$27,"AJUSTE-")),0) -> 0 | L28: =IF(C28="",0,K28+IF(OR(B28="INGRESO",B28="DE REPROCESO",B28="AJUSTE+"),F28,IF(OR(B28="A CORTE",B28="A REPROCESO",B28="MUESTRA",B28="AJUSTE-"),-F28,0))) -> 9 | M28: tomas | O28: progreso | R28: =IF(OR(Q28="",Q28=0,J28=0),"",(Q28-J28)/J28)
A29: 46142 | B29: INGRESO | C29: OverShark | D29: pique 30/1 | E29: P. Rosa | F29: 9 | G29: =IFERROR(F29*VLOOKUP(D29,TELAS!$A$4:$C$32,3,FALSE()),0) -> 180 | H29: =IFERROR(VLOOKUP(E29,COLORES!$A$4:$B$102,2,FALSE()),"") -> CLARO | I29: =IFERROR(IF(H29="OSCURO",VLOOKUP(D29,PRECIOS!$A$4:$F$32,2,FALSE()),IF(H29="CLARO",VLOOKUP(D29,PRECIOS!$A$4:$F$32,3,FALSE()),IF(H29="MELANGE",VLOOKUP(D29,PRECIOS!$A$4:$F$32,4,FALSE()),IF(H29="PPT",VLOOKUP(D29,PRECIOS!$A$4:$F$32,5,FALSE()),0)))),0) -> 21 | J29: =IFERROR(G29*I29,0) -> 3780 | K29: =IFERROR(IF(C29="",0,SUMIFS($F$4:$F$28,$C$4:$C$28,C29,$D$4:$D$28,D29,$E$4:$E$28,E29,$B$4:$B$28,"INGRESO")+SUMIFS($F$4:$F$28,$C$4:$C$28,C29,$D$4:$D$28,D29,$E$4:$E$28,E29,$B$4:$B$28,"DE REPROCESO")+SUMIFS($F$4:$F$28,$C$4:$C$28,C29,$D$4:$D$28,D29,$E$4:$E$28,E29,$B$4:$B$28,"AJUSTE+")-SUMIFS($F$4:$F$28,$C$4:$C$28,C29,$D$4:$D$28,D29,$E$4:$E$28,E29,$B$4:$B$28,"A CORTE")-SUMIFS($F$4:$F$28,$C$4:$C$28,C29,$D$4:$D$28,D29,$E$4:$E$28,E29,$B$4:$B$28,"A REPROCESO")-SUMIFS($F$4:$F$28,$C$4:$C$28,C29,$D$4:$D$28,D29,$E$4:$E$28,E29,$B$4:$B$28,"MUESTRA")-SUMIFS($F$4:$F$28,$C$4:$C$28,C29,$D$4:$D$28,D29,$E$4:$E$28,E29,$B$4:$B$28,"AJUSTE-")),0) -> 0 | L29: =IF(C29="",0,K29+IF(OR(B29="INGRESO",B29="DE REPROCESO",B29="AJUSTE+"),F29,IF(OR(B29="A CORTE",B29="A REPROCESO",B29="MUESTRA",B29="AJUSTE-"),-F29,0))) -> 9 | M29: tomas | O29: progreso | R29: =IF(OR(Q29="",Q29=0,J29=0),"",(Q29-J29)/J29)
A30: 46142 | B30: INGRESO | C30: OverShark | D30: pique 30/1 | E30: Topo | F30: 3 | G30: =IFERROR(F30*VLOOKUP(D30,TELAS!$A$4:$C$32,3,FALSE()),0) -> 60 | H30: =IFERROR(VLOOKUP(E30,COLORES!$A$4:$B$102,2,FALSE()),"") -> CLARO | I30: =IFERROR(IF(H30="OSCURO",VLOOKUP(D30,PRECIOS!$A$4:$F$32,2,FALSE()),IF(H30="CLARO",VLOOKUP(D30,PRECIOS!$A$4:$F$32,3,FALSE()),IF(H30="MELANGE",VLOOKUP(D30,PRECIOS!$A$4:$F$32,4,FALSE()),IF(H30="PPT",VLOOKUP(D30,PRECIOS!$A$4:$F$32,5,FALSE()),0)))),0) -> 21 | J30: =IFERROR(G30*I30,0) -> 1260 | K30: =IFERROR(IF(C30="",0,SUMIFS($F$4:$F$29,$C$4:$C$29,C30,$D$4:$D$29,D30,$E$4:$E$29,E30,$B$4:$B$29,"INGRESO")+SUMIFS($F$4:$F$29,$C$4:$C$29,C30,$D$4:$D$29,D30,$E$4:$E$29,E30,$B$4:$B$29,"DE REPROCESO")+SUMIFS($F$4:$F$29,$C$4:$C$29,C30,$D$4:$D$29,D30,$E$4:$E$29,E30,$B$4:$B$29,"AJUSTE+")-SUMIFS($F$4:$F$29,$C$4:$C$29,C30,$D$4:$D$29,D30,$E$4:$E$29,E30,$B$4:$B$29,"A CORTE")-SUMIFS($F$4:$F$29,$C$4:$C$29,C30,$D$4:$D$29,D30,$E$4:$E$29,E30,$B$4:$B$29,"A REPROCESO")-SUMIFS($F$4:$F$29,$C$4:$C$29,C30,$D$4:$D$29,D30,$E$4:$E$29,E30,$B$4:$B$29,"MUESTRA")-SUMIFS($F$4:$F$29,$C$4:$C$29,C30,$D$4:$D$29,D30,$E$4:$E$29,E30,$B$4:$B$29,"AJUSTE-")),0) -> 0 | L30: =IF(C30="",0,K30+IF(OR(B30="INGRESO",B30="DE REPROCESO",B30="AJUSTE+"),F30,IF(OR(B30="A CORTE",B30="A REPROCESO",B30="MUESTRA",B30="AJUSTE-"),-F30,0))) -> 3 | M30: tomas | O30: progreso | R30: =IF(OR(Q30="",Q30=0,J30=0),"",(Q30-J30)/J30)
A31: 46142 | B31: INGRESO | C31: OverShark | D31: pique 30/1 | E31: Vino | F31: 2 | G31: =IFERROR(F31*VLOOKUP(D31,TELAS!$A$4:$C$32,3,FALSE()),0) -> 40 | H31: =IFERROR(VLOOKUP(E31,COLORES!$A$4:$B$102,2,FALSE()),"") -> OSCURO | I31: =IFERROR(IF(H31="OSCURO",VLOOKUP(D31,PRECIOS!$A$4:$F$32,2,FALSE()),IF(H31="CLARO",VLOOKUP(D31,PRECIOS!$A$4:$F$32,3,FALSE()),IF(H31="MELANGE",VLOOKUP(D31,PRECIOS!$A$4:$F$32,4,FALSE()),IF(H31="PPT",VLOOKUP(D31,PRECIOS!$A$4:$F$32,5,FALSE()),0)))),0) -> 24 | J31: =IFERROR(G31*I31,0) -> 960 | K31: =IFERROR(IF(C31="",0,SUMIFS($F$4:$F$30,$C$4:$C$30,C31,$D$4:$D$30,D31,$E$4:$E$30,E31,$B$4:$B$30,"INGRESO")+SUMIFS($F$4:$F$30,$C$4:$C$30,C31,$D$4:$D$30,D31,$E$4:$E$30,E31,$B$4:$B$30,"DE REPROCESO")+SUMIFS($F$4:$F$30,$C$4:$C$30,C31,$D$4:$D$30,D31,$E$4:$E$30,E31,$B$4:$B$30,"AJUSTE+")-SUMIFS($F$4:$F$30,$C$4:$C$30,C31,$D$4:$D$30,D31,$E$4:$E$30,E31,$B$4:$B$30,"A CORTE")-SUMIFS($F$4:$F$30,$C$4:$C$30,C31,$D$4:$D$30,D31,$E$4:$E$30,E31,$B$4:$B$30,"A REPROCESO")-SUMIFS($F$4:$F$30,$C$4:$C$30,C31,$D$4:$D$30,D31,$E$4:$E$30,E31,$B$4:$B$30,"MUESTRA")-SUMIFS($F$4:$F$30,$C$4:$C$30,C31,$D$4:$D$30,D31,$E$4:$E$30,E31,$B$4:$B$30,"AJUSTE-")),0) -> 0 | L31: =IF(C31="",0,K31+IF(OR(B31="INGRESO",B31="DE REPROCESO",B31="AJUSTE+"),F31,IF(OR(B31="A CORTE",B31="A REPROCESO",B31="MUESTRA",B31="AJUSTE-"),-F31,0))) -> 2 | M31: tomas | O31: progreso | R31: =IF(OR(Q31="",Q31=0,J31=0),"",(Q31-J31)/J31)
A32: 46142 | B32: INGRESO | C32: OverShark | D32: pique 30/1 | E32: Denim | F32: 13 | G32: =IFERROR(F32*VLOOKUP(D32,TELAS!$A$4:$C$32,3,FALSE()),0) -> 260 | H32: =IFERROR(VLOOKUP(E32,COLORES!$A$4:$B$102,2,FALSE()),"") -> CLARO | I32: =IFERROR(IF(H32="OSCURO",VLOOKUP(D32,PRECIOS!$A$4:$F$32,2,FALSE()),IF(H32="CLARO",VLOOKUP(D32,PRECIOS!$A$4:$F$32,3,FALSE()),IF(H32="MELANGE",VLOOKUP(D32,PRECIOS!$A$4:$F$32,4,FALSE()),IF(H32="PPT",VLOOKUP(D32,PRECIOS!$A$4:$F$32,5,FALSE()),0)))),0) -> 21 | J32: =IFERROR(G32*I32,0) -> 5460 | K32: =IFERROR(IF(C32="",0,SUMIFS($F$4:$F$31,$C$4:$C$31,C32,$D$4:$D$31,D32,$E$4:$E$31,E32,$B$4:$B$31,"INGRESO")+SUMIFS($F$4:$F$31,$C$4:$C$31,C32,$D$4:$D$31,D32,$E$4:$E$31,E32,$B$4:$B$31,"DE REPROCESO")+SUMIFS($F$4:$F$31,$C$4:$C$31,C32,$D$4:$D$31,D32,$E$4:$E$31,E32,$B$4:$B$31,"AJUSTE+")-SUMIFS($F$4:$F$31,$C$4:$C$31,C32,$D$4:$D$31,D32,$E$4:$E$31,E32,$B$4:$B$31,"A CORTE")-SUMIFS($F$4:$F$31,$C$4:$C$31,C32,$D$4:$D$31,D32,$E$4:$E$31,E32,$B$4:$B$31,"A REPROCESO")-SUMIFS($F$4:$F$31,$C$4:$C$31,C32,$D$4:$D$31,D32,$E$4:$E$31,E32,$B$4:$B$31,"MUESTRA")-SUMIFS($F$4:$F$31,$C$4:$C$31,C32,$D$4:$D$31,D32,$E$4:$E$31,E32,$B$4:$B$31,"AJUSTE-")),0) -> 0 | L32: =IF(C32="",0,K32+IF(OR(B32="INGRESO",B32="DE REPROCESO",B32="AJUSTE+"),F32,IF(OR(B32="A CORTE",B32="A REPROCESO",B32="MUESTRA",B32="AJUSTE-"),-F32,0))) -> 13 | M32: tomas | O32: progreso | R32: =IF(OR(Q32="",Q32=0,J32=0),"",(Q32-J32)/J32)
A33: 46142 | B33: INGRESO | C33: OverShark | D33: pique 30/1 | E33: Plomo | F33: 6 | G33: =IFERROR(F33*VLOOKUP(D33,TELAS!$A$4:$C$32,3,FALSE()),0) -> 120 | H33: =IFERROR(VLOOKUP(E33,COLORES!$A$4:$B$102,2,FALSE()),"") -> OSCURO | I33: =IFERROR(IF(H33="OSCURO",VLOOKUP(D33,PRECIOS!$A$4:$F$32,2,FALSE()),IF(H33="CLARO",VLOOKUP(D33,PRECIOS!$A$4:$F$32,3,FALSE()),IF(H33="MELANGE",VLOOKUP(D33,PRECIOS!$A$4:$F$32,4,FALSE()),IF(H33="PPT",VLOOKUP(D33,PRECIOS!$A$4:$F$32,5,FALSE()),0)))),0) -> 24 | J33: =IFERROR(G33*I33,0) -> 2880 | K33: =IFERROR(IF(C33="",0,SUMIFS($F$4:$F$32,$C$4:$C$32,C33,$D$4:$D$32,D33,$E$4:$E$32,E33,$B$4:$B$32,"INGRESO")+SUMIFS($F$4:$F$32,$C$4:$C$32,C33,$D$4:$D$32,D33,$E$4:$E$32,E33,$B$4:$B$32,"DE REPROCESO")+SUMIFS($F$4:$F$32,$C$4:$C$32,C33,$D$4:$D$32,D33,$E$4:$E$32,E33,$B$4:$B$32,"AJUSTE+")-SUMIFS($F$4:$F$32,$C$4:$C$32,C33,$D$4:$D$32,D33,$E$4:$E$32,E33,$B$4:$B$32,"A CORTE")-SUMIFS($F$4:$F$32,$C$4:$C$32,C33,$D$4:$D$32,D33,$E$4:$E$32,E33,$B$4:$B$32,"A REPROCESO")-SUMIFS($F$4:$F$32,$C$4:$C$32,C33,$D$4:$D$32,D33,$E$4:$E$32,E33,$B$4:$B$32,"MUESTRA")-SUMIFS($F$4:$F$32,$C$4:$C$32,C33,$D$4:$D$32,D33,$E$4:$E$32,E33,$B$4:$B$32,"AJUSTE-")),0) -> 0 | L33: =IF(C33="",0,K33+IF(OR(B33="INGRESO",B33="DE REPROCESO",B33="AJUSTE+"),F33,IF(OR(B33="A CORTE",B33="A REPROCESO",B33="MUESTRA",B33="AJUSTE-"),-F33,0))) -> 6 | M33: tomas | O33: progreso | R33: =IF(OR(Q33="",Q33=0,J33=0),"",(Q33-J33)/J33)
A34: 46142 | B34: INGRESO | C34: OverShark | D34: pique 30/1 | E34: Melange | F34: 9 | G34: =IFERROR(F34*VLOOKUP(D34,TELAS!$A$4:$C$32,3,FALSE()),0) -> 180 | H34: =IFERROR(VLOOKUP(E34,COLORES!$A$4:$B$102,2,FALSE()),"") -> MELANGE | I34: =IFERROR(IF(H34="OSCURO",VLOOKUP(D34,PRECIOS!$A$4:$F$32,2,FALSE()),IF(H34="CLARO",VLOOKUP(D34,PRECIOS!$A$4:$F$32,3,FALSE()),IF(H34="MELANGE",VLOOKUP(D34,PRECIOS!$A$4:$F$32,4,FALSE()),IF(H34="PPT",VLOOKUP(D34,PRECIOS!$A$4:$F$32,5,FALSE()),0)))),0) -> 18 | J34: =IFERROR(G34*I34,0) -> 3240 | K34: =IFERROR(IF(C34="",0,SUMIFS($F$4:$F$33,$C$4:$C$33,C34,$D$4:$D$33,D34,$E$4:$E$33,E34,$B$4:$B$33,"INGRESO")+SUMIFS($F$4:$F$33,$C$4:$C$33,C34,$D$4:$D$33,D34,$E$4:$E$33,E34,$B$4:$B$33,"DE REPROCESO")+SUMIFS($F$4:$F$33,$C$4:$C$33,C34,$D$4:$D$33,D34,$E$4:$E$33,E34,$B$4:$B$33,"AJUSTE+")-SUMIFS($F$4:$F$33,$C$4:$C$33,C34,$D$4:$D$33,D34,$E$4:$E$33,E34,$B$4:$B$33,"A CORTE")-SUMIFS($F$4:$F$33,$C$4:$C$33,C34,$D$4:$D$33,D34,$E$4:$E$33,E34,$B$4:$B$33,"A REPROCESO")-SUMIFS($F$4:$F$33,$C$4:$C$33,C34,$D$4:$D$33,D34,$E$4:$E$33,E34,$B$4:$B$33,"MUESTRA")-SUMIFS($F$4:$F$33,$C$4:$C$33,C34,$D$4:$D$33,D34,$E$4:$E$33,E34,$B$4:$B$33,"AJUSTE-")),0) -> 0 | L34: =IF(C34="",0,K34+IF(OR(B34="INGRESO",B34="DE REPROCESO",B34="AJUSTE+"),F34,IF(OR(B34="A CORTE",B34="A REPROCESO",B34="MUESTRA",B34="AJUSTE-"),-F34,0))) -> 9 | M34: tomas | O34: progreso | R34: =IF(OR(Q34="",Q34=0,J34=0),"",(Q34-J34)/J34)
A35: 46147 | B35: INGRESO | C35: OverShark | D35: wafle 30/1 | E35: Negro | F35: 33 | G35: =IFERROR(F35*VLOOKUP(D35,TELAS!$A$4:$C$32,3,FALSE()),0) -> 660 | H35: =IFERROR(VLOOKUP(E35,COLORES!$A$4:$B$102,2,FALSE()),"") -> OSCURO | I35: =IFERROR(IF(H35="OSCURO",VLOOKUP(D35,PRECIOS!$A$4:$F$32,2,FALSE()),IF(H35="CLARO",VLOOKUP(D35,PRECIOS!$A$4:$F$32,3,FALSE()),IF(H35="MELANGE",VLOOKUP(D35,PRECIOS!$A$4:$F$32,4,FALSE()),IF(H35="PPT",VLOOKUP(D35,PRECIOS!$A$4:$F$32,5,FALSE()),0)))),0) -> 26 | J35: =IFERROR(G35*I35,0) -> 17160 | K35: =IFERROR(IF(C35="",0,SUMIFS($F$4:$F$34,$C$4:$C$34,C35,$D$4:$D$34,D35,$E$4:$E$34,E35,$B$4:$B$34,"INGRESO")+SUMIFS($F$4:$F$34,$C$4:$C$34,C35,$D$4:$D$34,D35,$E$4:$E$34,E35,$B$4:$B$34,"DE REPROCESO")+SUMIFS($F$4:$F$34,$C$4:$C$34,C35,$D$4:$D$34,D35,$E$4:$E$34,E35,$B$4:$B$34,"AJUSTE+")-SUMIFS($F$4:$F$34,$C$4:$C$34,C35,$D$4:$D$34,D35,$E$4:$E$34,E35,$B$4:$B$34,"A CORTE")-SUMIFS($F$4:$F$34,$C$4:$C$34,C35,$D$4:$D$34,D35,$E$4:$E$34,E35,$B$4:$B$34,"A REPROCESO")-SUMIFS($F$4:$F$34,$C$4:$C$34,C35,$D$4:$D$34,D35,$E$4:$E$34,E35,$B$4:$B$34,"MUESTRA")-SUMIFS($F$4:$F$34,$C$4:$C$34,C35,$D$4:$D$34,D35,$E$4:$E$34,E35,$B$4:$B$34,"AJUSTE-")),0) -> 0 | L35: =IF(C35="",0,K35+IF(OR(B35="INGRESO",B35="DE REPROCESO",B35="AJUSTE+"),F35,IF(OR(B35="A CORTE",B35="A REPROCESO",B35="MUESTRA",B35="AJUSTE-"),-F35,0))) -> 33 | M35: tomas | O35: progreso | R35: =IF(OR(Q35="",Q35=0,J35=0),"",(Q35-J35)/J35)
A36: 46147 | B36: INGRESO | C36: OverShark | D36: wafle 30/1 | E36: Perla | F36: 36 | G36: =IFERROR(F36*VLOOKUP(D36,TELAS!$A$4:$C$32,3,FALSE()),0) -> 720 | H36: =IFERROR(VLOOKUP(E36,COLORES!$A$4:$B$102,2,FALSE()),"") -> PPT | I36: =IFERROR(IF(H36="OSCURO",VLOOKUP(D36,PRECIOS!$A$4:$F$32,2,FALSE()),IF(H36="CLARO",VLOOKUP(D36,PRECIOS!$A$4:$F$32,3,FALSE()),IF(H36="MELANGE",VLOOKUP(D36,PRECIOS!$A$4:$F$32,4,FALSE()),IF(H36="PPT",VLOOKUP(D36,PRECIOS!$A$4:$F$32,5,FALSE()),0)))),0) -> 19 | J36: =IFERROR(G36*I36,0) -> 13680 | K36: =IFERROR(IF(C36="",0,SUMIFS($F$4:$F$35,$C$4:$C$35,C36,$D$4:$D$35,D36,$E$4:$E$35,E36,$B$4:$B$35,"INGRESO")+SUMIFS($F$4:$F$35,$C$4:$C$35,C36,$D$4:$D$35,D36,$E$4:$E$35,E36,$B$4:$B$35,"DE REPROCESO")+SUMIFS($F$4:$F$35,$C$4:$C$35,C36,$D$4:$D$35,D36,$E$4:$E$35,E36,$B$4:$B$35,"AJUSTE+")-SUMIFS($F$4:$F$35,$C$4:$C$35,C36,$D$4:$D$35,D36,$E$4:$E$35,E36,$B$4:$B$35,"A CORTE")-SUMIFS($F$4:$F$35,$C$4:$C$35,C36,$D$4:$D$35,D36,$E$4:$E$35,E36,$B$4:$B$35,"A REPROCESO")-SUMIFS($F$4:$F$35,$C$4:$C$35,C36,$D$4:$D$35,D36,$E$4:$E$35,E36,$B$4:$B$35,"MUESTRA")-SUMIFS($F$4:$F$35,$C$4:$C$35,C36,$D$4:$D$35,D36,$E$4:$E$35,E36,$B$4:$B$35,"AJUSTE-")),0) -> 0 | L36: =IF(C36="",0,K36+IF(OR(B36="INGRESO",B36="DE REPROCESO",B36="AJUSTE+"),F36,IF(OR(B36="A CORTE",B36="A REPROCESO",B36="MUESTRA",B36="AJUSTE-"),-F36,0))) -> 36 | M36: tomas | O36: progreso | R36: =IF(OR(Q36="",Q36=0,J36=0),"",(Q36-J36)/J36)
A37: 46147 | B37: INGRESO | C37: OverShark | D37: wafle 30/1 | E37: Azul | F37: 35 | G37: =IFERROR(F37*VLOOKUP(D37,TELAS!$A$4:$C$32,3,FALSE()),0) -> 700 | H37: =IFERROR(VLOOKUP(E37,COLORES!$A$4:$B$102,2,FALSE()),"") -> OSCURO | I37: =IFERROR(IF(H37="OSCURO",VLOOKUP(D37,PRECIOS!$A$4:$F$32,2,FALSE()),IF(H37="CLARO",VLOOKUP(D37,PRECIOS!$A$4:$F$32,3,FALSE()),IF(H37="MELANGE",VLOOKUP(D37,PRECIOS!$A$4:$F$32,4,FALSE()),IF(H37="PPT",VLOOKUP(D37,PRECIOS!$A$4:$F$32,5,FALSE()),0)))),0) -> 26 | J37: =IFERROR(G37*I37,0) -> 18200 | K37: =IFERROR(IF(C37="",0,SUMIFS($F$4:$F$36,$C$4:$C$36,C37,$D$4:$D$36,D37,$E$4:$E$36,E37,$B$4:$B$36,"INGRESO")+SUMIFS($F$4:$F$36,$C$4:$C$36,C37,$D$4:$D$36,D37,$E$4:$E$36,E37,$B$4:$B$36,"DE REPROCESO")+SUMIFS($F$4:$F$36,$C$4:$C$36,C37,$D$4:$D$36,D37,$E$4:$E$36,E37,$B$4:$B$36,"AJUSTE+")-SUMIFS($F$4:$F$36,$C$4:$C$36,C37,$D$4:$D$36,D37,$E$4:$E$36,E37,$B$4:$B$36,"A CORTE")-SUMIFS($F$4:$F$36,$C$4:$C$36,C37,$D$4:$D$36,D37,$E$4:$E$36,E37,$B$4:$B$36,"A REPROCESO")-SUMIFS($F$4:$F$36,$C$4:$C$36,C37,$D$4:$D$36,D37,$E$4:$E$36,E37,$B$4:$B$36,"MUESTRA")-SUMIFS($F$4:$F$36,$C$4:$C$36,C37,$D$4:$D$36,D37,$E$4:$E$36,E37,$B$4:$B$36,"AJUSTE-")),0) -> 0 | L37: =IF(C37="",0,K37+IF(OR(B37="INGRESO",B37="DE REPROCESO",B37="AJUSTE+"),F37,IF(OR(B37="A CORTE",B37="A REPROCESO",B37="MUESTRA",B37="AJUSTE-"),-F37,0))) -> 35 | M37: tomas | O37: progreso | R37: =IF(OR(Q37="",Q37=0,J37=0),"",(Q37-J37)/J37)
A38: 46147 | B38: INGRESO | C38: OverShark | D38: wafle 30/1 | E38: Botella | F38: 20 | G38: =IFERROR(F38*VLOOKUP(D38,TELAS!$A$4:$C$32,3,FALSE()),0) -> 400 | H38: =IFERROR(VLOOKUP(E38,COLORES!$A$4:$B$102,2,FALSE()),"") -> OSCURO | I38: =IFERROR(IF(H38="OSCURO",VLOOKUP(D38,PRECIOS!$A$4:$F$32,2,FALSE()),IF(H38="CLARO",VLOOKUP(D38,PRECIOS!$A$4:$F$32,3,FALSE()),IF(H38="MELANGE",VLOOKUP(D38,PRECIOS!$A$4:$F$32,4,FALSE()),IF(H38="PPT",VLOOKUP(D38,PRECIOS!$A$4:$F$32,5,FALSE()),0)))),0) -> 26 | J38: =IFERROR(G38*I38,0) -> 10400 | K38: =IFERROR(IF(C38="",0,SUMIFS($F$4:$F$37,$C$4:$C$37,C38,$D$4:$D$37,D38,$E$4:$E$37,E38,$B$4:$B$37,"INGRESO")+SUMIFS($F$4:$F$37,$C$4:$C$37,C38,$D$4:$D$37,D38,$E$4:$E$37,E38,$B$4:$B$37,"DE REPROCESO")+SUMIFS($F$4:$F$37,$C$4:$C$37,C38,$D$4:$D$37,D38,$E$4:$E$37,E38,$B$4:$B$37,"AJUSTE+")-SUMIFS($F$4:$F$37,$C$4:$C$37,C38,$D$4:$D$37,D38,$E$4:$E$37,E38,$B$4:$B$37,"A CORTE")-SUMIFS($F$4:$F$37,$C$4:$C$37,C38,$D$4:$D$37,D38,$E$4:$E$37,E38,$B$4:$B$37,"A REPROCESO")-SUMIFS($F$4:$F$37,$C$4:$C$37,C38,$D$4:$D$37,D38,$E$4:$E$37,E38,$B$4:$B$37,"MUESTRA")-SUMIFS($F$4:$F$37,$C$4:$C$37,C38,$D$4:$D$37,D38,$E$4:$E$37,E38,$B$4:$B$37,"AJUSTE-")),0) -> 0 | L38: =IF(C38="",0,K38+IF(OR(B38="INGRESO",B38="DE REPROCESO",B38="AJUSTE+"),F38,IF(OR(B38="A CORTE",B38="A REPROCESO",B38="MUESTRA",B38="AJUSTE-"),-F38,0))) -> 20 | M38: tomas | O38: progreso | R38: =IF(OR(Q38="",Q38=0,J38=0),"",(Q38-J38)/J38)
A39: 46147 | B39: INGRESO | C39: OverShark | D39: wafle 30/1 | E39: Pacay | F39: 15 | G39: =IFERROR(F39*VLOOKUP(D39,TELAS!$A$4:$C$32,3,FALSE()),0) -> 300 | H39: =IFERROR(VLOOKUP(E39,COLORES!$A$4:$B$102,2,FALSE()),"") -> CLARO | I39: =IFERROR(IF(H39="OSCURO",VLOOKUP(D39,PRECIOS!$A$4:$F$32,2,FALSE()),IF(H39="CLARO",VLOOKUP(D39,PRECIOS!$A$4:$F$32,3,FALSE()),IF(H39="MELANGE",VLOOKUP(D39,PRECIOS!$A$4:$F$32,4,FALSE()),IF(H39="PPT",VLOOKUP(D39,PRECIOS!$A$4:$F$32,5,FALSE()),0)))),0) -> 22.5 | J39: =IFERROR(G39*I39,0) -> 6750 | K39: =IFERROR(IF(C39="",0,SUMIFS($F$4:$F$38,$C$4:$C$38,C39,$D$4:$D$38,D39,$E$4:$E$38,E39,$B$4:$B$38,"INGRESO")+SUMIFS($F$4:$F$38,$C$4:$C$38,C39,$D$4:$D$38,D39,$E$4:$E$38,E39,$B$4:$B$38,"DE REPROCESO")+SUMIFS($F$4:$F$38,$C$4:$C$38,C39,$D$4:$D$38,D39,$E$4:$E$38,E39,$B$4:$B$38,"AJUSTE+")-SUMIFS($F$4:$F$38,$C$4:$C$38,C39,$D$4:$D$38,D39,$E$4:$E$38,E39,$B$4:$B$38,"A CORTE")-SUMIFS($F$4:$F$38,$C$4:$C$38,C39,$D$4:$D$38,D39,$E$4:$E$38,E39,$B$4:$B$38,"A REPROCESO")-SUMIFS($F$4:$F$38,$C$4:$C$38,C39,$D$4:$D$38,D39,$E$4:$E$38,E39,$B$4:$B$38,"MUESTRA")-SUMIFS($F$4:$F$38,$C$4:$C$38,C39,$D$4:$D$38,D39,$E$4:$E$38,E39,$B$4:$B$38,"AJUSTE-")),0) -> 0 | L39: =IF(C39="",0,K39+IF(OR(B39="INGRESO",B39="DE REPROCESO",B39="AJUSTE+"),F39,IF(OR(B39="A CORTE",B39="A REPROCESO",B39="MUESTRA",B39="AJUSTE-"),-F39,0))) -> 15 | M39: tomas | O39: progreso | R39: =IF(OR(Q39="",Q39=0,J39=0),"",(Q39-J39)/J39)
A40: 46147 | B40: INGRESO | C40: OverShark | D40: wafle 30/1 | E40: Cemento | F40: 14 | G40: =IFERROR(F40*VLOOKUP(D40,TELAS!$A$4:$C$32,3,FALSE()),0) -> 280 | H40: =IFERROR(VLOOKUP(E40,COLORES!$A$4:$B$102,2,FALSE()),"") -> CLARO | I40: =IFERROR(IF(H40="OSCURO",VLOOKUP(D40,PRECIOS!$A$4:$F$32,2,FALSE()),IF(H40="CLARO",VLOOKUP(D40,PRECIOS!$A$4:$F$32,3,FALSE()),IF(H40="MELANGE",VLOOKUP(D40,PRECIOS!$A$4:$F$32,4,FALSE()),IF(H40="PPT",VLOOKUP(D40,PRECIOS!$A$4:$F$32,5,FALSE()),0)))),0) -> 22.5 | J40: =IFERROR(G40*I40,0) -> 6300 | K40: =IFERROR(IF(C40="",0,SUMIFS($F$4:$F$39,$C$4:$C$39,C40,$D$4:$D$39,D40,$E$4:$E$39,E40,$B$4:$B$39,"INGRESO")+SUMIFS($F$4:$F$39,$C$4:$C$39,C40,$D$4:$D$39,D40,$E$4:$E$39,E40,$B$4:$B$39,"DE REPROCESO")+SUMIFS($F$4:$F$39,$C$4:$C$39,C40,$D$4:$D$39,D40,$E$4:$E$39,E40,$B$4:$B$39,"AJUSTE+")-SUMIFS($F$4:$F$39,$C$4:$C$39,C40,$D$4:$D$39,D40,$E$4:$E$39,E40,$B$4:$B$39,"A CORTE")-SUMIFS($F$4:$F$39,$C$4:$C$39,C40,$D$4:$D$39,D40,$E$4:$E$39,E40,$B$4:$B$39,"A REPROCESO")-SUMIFS($F$4:$F$39,$C$4:$C$39,C40,$D$4:$D$39,D40,$E$4:$E$39,E40,$B$4:$B$39,"MUESTRA")-SUMIFS($F$4:$F$39,$C$4:$C$39,C40,$D$4:$D$39,D40,$E$4:$E$39,E40,$B$4:$B$39,"AJUSTE-")),0) -> 0 | L40: =IF(C40="",0,K40+IF(OR(B40="INGRESO",B40="DE REPROCESO",B40="AJUSTE+"),F40,IF(OR(B40="A CORTE",B40="A REPROCESO",B40="MUESTRA",B40="AJUSTE-"),-F40,0))) -> 14 | M40: tomas | O40: progreso | R40: =IF(OR(Q40="",Q40=0,J40=0),"",(Q40-J40)/J40)
...

Sheet MOVIMIENTOS_COMPLEMENTOS
A1: MOVIMIENTOS COMPLEMENTOS — Cuellos / Puños / Pretinas
A2: Solo 3 tipos: INGRESO (compra externa, req. proveedor/factura), DE CORTE (cortado de rib internamente), SALIDA (al taller, muestra, etc).
A3: FECHA | B3: TIPO MOV | C3: CLIENTE | D3: TIPO PIEZA | E3: ORIGEN | F3: PRODUCTO DESTINO | G3: COLOR | H3: TALLA | I3: CANTIDAD | J3: PRECIO UNIT | K3: TOTAL S/. | L3: STOCK ANTES | M3: STOCK DESPUÉS | N3: PROVEEDOR | O3: N° FACTURA | P3: COSTO REAL FACT. | Q3: NOTAS
J4: {=IFERROR(INDEX(PRECIOS_COMPLEMENTOS!$C$4:$F$17,MATCH(D4&"_"&E4,PRECIOS_COMPLEMENTOS!$H$4:$H$17,0),IF(OR(H4="S",H4="20cm"),1,IF(OR(H4="M",H4="25cm"),2,IF(OR(H4="L",H4="30cm"),3,IF(OR(H4="XL",H4="35cm"),4,0))))),0)} -> #REF! | K4: =IFERROR(I4*J4,0) -> 0 | L4: =0 -> 0 | M4: =IF(C4="",0,L4+IF(OR(B4="INGRESO",B4="DE CORTE"),I4,IF(B4="SALIDA",-I4,0))) -> 0
J5: {=IFERROR(INDEX(PRECIOS_COMPLEMENTOS!$C$4:$F$17,MATCH(D5&"_"&E5,PRECIOS_COMPLEMENTOS!$H$4:$H$17,0),IF(OR(H5="S",H5="20cm"),1,IF(OR(H5="M",H5="25cm"),2,IF(OR(H5="L",H5="30cm"),3,IF(OR(H5="XL",H5="35cm"),4,0))))),0)} -> #REF! | K5: =IFERROR(I5*J5,0) -> 0 | L5: =IFERROR(IF(C5="",0,IF(D5="PRETINA",SUMIFS($I$4,$C$4,C5,$D$4,D5,$E$4,E5,$F$4,F5,$G$4,G5,$H$4,H5,$B$4,"INGRESO")+SUMIFS($I$4,$C$4,C5,$D$4,D5,$E$4,E5,$F$4,F5,$G$4,G5,$H$4,H5,$B$4,"DE CORTE")-SUMIFS($I$4,$C$4,C5,$D$4,D5,$E$4,E5,$F$4,F5,$G$4,G5,$H$4,H5,$B$4,"SALIDA"),SUMIFS($I$4,$C$4,C5,$D$4,D5,$E$4,E5,$G$4,G5,$H$4,H5,$B$4,"INGRESO")+SUMIFS($I$4,$C$4,C5,$D$4,D5,$E$4,E5,$G$4,G5,$H$4,H5,$B$4,"DE CORTE")-SUMIFS($I$4,$C$4,C5,$D$4,D5,$E$4,E5,$G$4,G5,$H$4,H5,$B$4,"SALIDA"))),0) -> 0 | M5: =IF(C5="",0,L5+IF(OR(B5="INGRESO",B5="DE CORTE"),I5,IF(B5="SALIDA",-I5,0))) -> 0
J6: {=IFERROR(INDEX(PRECIOS_COMPLEMENTOS!$C$4:$F$17,MATCH(D6&"_"&E6,PRECIOS_COMPLEMENTOS!$H$4:$H$17,0),IF(OR(H6="S",H6="20cm"),1,IF(OR(H6="M",H6="25cm"),2,IF(OR(H6="L",H6="30cm"),3,IF(OR(H6="XL",H6="35cm"),4,0))))),0)} -> #REF! | K6: =IFERROR(I6*J6,0) -> 0 | L6: =IFERROR(IF(C6="",0,IF(D6="PRETINA",SUMIFS($I$4:$I$5,$C$4:$C$5,C6,$D$4:$D$5,D6,$E$4:$E$5,E6,$F$4:$F$5,F6,$G$4:$G$5,G6,$H$4:$H$5,H6,$B$4:$B$5,"INGRESO")+SUMIFS($I$4:$I$5,$C$4:$C$5,C6,$D$4:$D$5,D6,$E$4:$E$5,E6,$F$4:$F$5,F6,$G$4:$G$5,G6,$H$4:$H$5,H6,$B$4:$B$5,"DE CORTE")-SUMIFS($I$4:$I$5,$C$4:$C$5,C6,$D$4:$D$5,D6,$E$4:$E$5,E6,$F$4:$F$5,F6,$G$4:$G$5,G6,$H$4:$H$5,H6,$B$4:$B$5,"SALIDA"),SUMIFS($I$4:$I$5,$C$4:$C$5,C6,$D$4:$D$5,D6,$E$4:$E$5,E6,$G$4:$G$5,G6,$H$4:$H$5,H6,$B$4:$B$5,"INGRESO")+SUMIFS($I$4:$I$5,$C$4:$C$5,C6,$D$4:$D$5,D6,$E$4:$E$5,E6,$G$4:$G$5,G6,$H$4:$H$5,H6,$B$4:$B$5,"DE CORTE")-SUMIFS($I$4:$I$5,$C$4:$C$5,C6,$D$4:$D$5,D6,$E$4:$E$5,E6,$G$4:$G$5,G6,$H$4:$H$5,H6,$B$4:$B$5,"SALIDA"))),0) -> 0 | M6: =IF(C6="",0,L6+IF(OR(B6="INGRESO",B6="DE CORTE"),I6,IF(B6="SALIDA",-I6,0))) -> 0
J7: {=IFERROR(INDEX(PRECIOS_COMPLEMENTOS!$C$4:$F$17,MATCH(D7&"_"&E7,PRECIOS_COMPLEMENTOS!$H$4:$H$17,0),IF(OR(H7="S",H7="20cm"),1,IF(OR(H7="M",H7="25cm"),2,IF(OR(H7="L",H7="30cm"),3,IF(OR(H7="XL",H7="35cm"),4,0))))),0)} -> #REF! | K7: =IFERROR(I7*J7,0) -> 0 | L7: =IFERROR(IF(C7="",0,IF(D7="PRETINA",SUMIFS($I$4:$I$6,$C$4:$C$6,C7,$D$4:$D$6,D7,$E$4:$E$6,E7,$F$4:$F$6,F7,$G$4:$G$6,G7,$H$4:$H$6,H7,$B$4:$B$6,"INGRESO")+SUMIFS($I$4:$I$6,$C$4:$C$6,C7,$D$4:$D$6,D7,$E$4:$E$6,E7,$F$4:$F$6,F7,$G$4:$G$6,G7,$H$4:$H$6,H7,$B$4:$B$6,"DE CORTE")-SUMIFS($I$4:$I$6,$C$4:$C$6,C7,$D$4:$D$6,D7,$E$4:$E$6,E7,$F$4:$F$6,F7,$G$4:$G$6,G7,$H$4:$H$6,H7,$B$4:$B$6,"SALIDA"),SUMIFS($I$4:$I$6,$C$4:$C$6,C7,$D$4:$D$6,D7,$E$4:$E$6,E7,$G$4:$G$6,G7,$H$4:$H$6,H7,$B$4:$B$6,"INGRESO")+SUMIFS($I$4:$I$6,$C$4:$C$6,C7,$D$4:$D$6,D7,$E$4:$E$6,E7,$G$4:$G$6,G7,$H$4:$H$6,H7,$B$4:$B$6,"DE CORTE")-SUMIFS($I$4:$I$6,$C$4:$C$6,C7,$D$4:$D$6,D7,$E$4:$E$6,E7,$G$4:$G$6,G7,$H$4:$H$6,H7,$B$4:$B$6,"SALIDA"))),0) -> 0 | M7: =IF(C7="",0,L7+IF(OR(B7="INGRESO",B7="DE CORTE"),I7,IF(B7="SALIDA",-I7,0))) -> 0
J8: {=IFERROR(INDEX(PRECIOS_COMPLEMENTOS!$C$4:$F$17,MATCH(D8&"_"&E8,PRECIOS_COMPLEMENTOS!$H$4:$H$17,0),IF(OR(H8="S",H8="20cm"),1,IF(OR(H8="M",H8="25cm"),2,IF(OR(H8="L",H8="30cm"),3,IF(OR(H8="XL",H8="35cm"),4,0))))),0)} -> #REF! | K8: =IFERROR(I8*J8,0) -> 0 | L8: =IFERROR(IF(C8="",0,IF(D8="PRETINA",SUMIFS($I$4:$I$7,$C$4:$C$7,C8,$D$4:$D$7,D8,$E$4:$E$7,E8,$F$4:$F$7,F8,$G$4:$G$7,G8,$H$4:$H$7,H8,$B$4:$B$7,"INGRESO")+SUMIFS($I$4:$I$7,$C$4:$C$7,C8,$D$4:$D$7,D8,$E$4:$E$7,E8,$F$4:$F$7,F8,$G$4:$G$7,G8,$H$4:$H$7,H8,$B$4:$B$7,"DE CORTE")-SUMIFS($I$4:$I$7,$C$4:$C$7,C8,$D$4:$D$7,D8,$E$4:$E$7,E8,$F$4:$F$7,F8,$G$4:$G$7,G8,$H$4:$H$7,H8,$B$4:$B$7,"SALIDA"),SUMIFS($I$4:$I$7,$C$4:$C$7,C8,$D$4:$D$7,D8,$E$4:$E$7,E8,$G$4:$G$7,G8,$H$4:$H$7,H8,$B$4:$B$7,"INGRESO")+SUMIFS($I$4:$I$7,$C$4:$C$7,C8,$D$4:$D$7,D8,$E$4:$E$7,E8,$G$4:$G$7,G8,$H$4:$H$7,H8,$B$4:$B$7,"DE CORTE")-SUMIFS($I$4:$I$7,$C$4:$C$7,C8,$D$4:$D$7,D8,$E$4:$E$7,E8,$G$4:$G$7,G8,$H$4:$H$7,H8,$B$4:$B$7,"SALIDA"))),0) -> 0 | M8: =IF(C8="",0,L8+IF(OR(B8="INGRESO",B8="DE CORTE"),I8,IF(B8="SALIDA",-I8,0))) -> 0
J9: {=IFERROR(INDEX(PRECIOS_COMPLEMENTOS!$C$4:$F$17,MATCH(D9&"_"&E9,PRECIOS_COMPLEMENTOS!$H$4:$H$17,0),IF(OR(H9="S",H9="20cm"),1,IF(OR(H9="M",H9="25cm"),2,IF(OR(H9="L",H9="30cm"),3,IF(OR(H9="XL",H9="35cm"),4,0))))),0)} -> #REF! | K9: =IFERROR(I9*J9,0) -> 0 | L9: =IFERROR(IF(C9="",0,IF(D9="PRETINA",SUMIFS($I$4:$I$8,$C$4:$C$8,C9,$D$4:$D$8,D9,$E$4:$E$8,E9,$F$4:$F$8,F9,$G$4:$G$8,G9,$H$4:$H$8,H9,$B$4:$B$8,"INGRESO")+SUMIFS($I$4:$I$8,$C$4:$C$8,C9,$D$4:$D$8,D9,$E$4:$E$8,E9,$F$4:$F$8,F9,$G$4:$G$8,G9,$H$4:$H$8,H9,$B$4:$B$8,"DE CORTE")-SUMIFS($I$4:$I$8,$C$4:$C$8,C9,$D$4:$D$8,D9,$E$4:$E$8,E9,$F$4:$F$8,F9,$G$4:$G$8,G9,$H$4:$H$8,H9,$B$4:$B$8,"SALIDA"),SUMIFS($I$4:$I$8,$C$4:$C$8,C9,$D$4:$D$8,D9,$E$4:$E$8,E9,$G$4:$G$8,G9,$H$4:$H$8,H9,$B$4:$B$8,"INGRESO")+SUMIFS($I$4:$I$8,$C$4:$C$8,C9,$D$4:$D$8,D9,$E$4:$E$8,E9,$G$4:$G$8,G9,$H$4:$H$8,H9,$B$4:$B$8,"DE CORTE")-SUMIFS($I$4:$I$8,$C$4:$C$8,C9,$D$4:$D$8,D9,$E$4:$E$8,E9,$G$4:$G$8,G9,$H$4:$H$8,H9,$B$4:$B$8,"SALIDA"))),0) -> 0 | M9: =IF(C9="",0,L9+IF(OR(B9="INGRESO",B9="DE CORTE"),I9,IF(B9="SALIDA",-I9,0))) -> 0
J10: {=IFERROR(INDEX(PRECIOS_COMPLEMENTOS!$C$4:$F$17,MATCH(D10&"_"&E10,PRECIOS_COMPLEMENTOS!$H$4:$H$17,0),IF(OR(H10="S",H10="20cm"),1,IF(OR(H10="M",H10="25cm"),2,IF(OR(H10="L",H10="30cm"),3,IF(OR(H10="XL",H10="35cm"),4,0))))),0)} -> #REF! | K10: =IFERROR(I10*J10,0) -> 0 | L10: =IFERROR(IF(C10="",0,IF(D10="PRETINA",SUMIFS($I$4:$I$9,$C$4:$C$9,C10,$D$4:$D$9,D10,$E$4:$E$9,E10,$F$4:$F$9,F10,$G$4:$G$9,G10,$H$4:$H$9,H10,$B$4:$B$9,"INGRESO")+SUMIFS($I$4:$I$9,$C$4:$C$9,C10,$D$4:$D$9,D10,$E$4:$E$9,E10,$F$4:$F$9,F10,$G$4:$G$9,G10,$H$4:$H$9,H10,$B$4:$B$9,"DE CORTE")-SUMIFS($I$4:$I$9,$C$4:$C$9,C10,$D$4:$D$9,D10,$E$4:$E$9,E10,$F$4:$F$9,F10,$G$4:$G$9,G10,$H$4:$H$9,H10,$B$4:$B$9,"SALIDA"),SUMIFS($I$4:$I$9,$C$4:$C$9,C10,$D$4:$D$9,D10,$E$4:$E$9,E10,$G$4:$G$9,G10,$H$4:$H$9,H10,$B$4:$B$9,"INGRESO")+SUMIFS($I$4:$I$9,$C$4:$C$9,C10,$D$4:$D$9,D10,$E$4:$E$9,E10,$G$4:$G$9,G10,$H$4:$H$9,H10,$B$4:$B$9,"DE CORTE")-SUMIFS($I$4:$I$9,$C$4:$C$9,C10,$D$4:$D$9,D10,$E$4:$E$9,E10,$G$4:$G$9,G10,$H$4:$H$9,H10,$B$4:$B$9,"SALIDA"))),0) -> 0 | M10: =IF(C10="",0,L10+IF(OR(B10="INGRESO",B10="DE CORTE"),I10,IF(B10="SALIDA",-I10,0))) -> 0
J11: {=IFERROR(INDEX(PRECIOS_COMPLEMENTOS!$C$4:$F$17,MATCH(D11&"_"&E11,PRECIOS_COMPLEMENTOS!$H$4:$H$17,0),IF(OR(H11="S",H11="20cm"),1,IF(OR(H11="M",H11="25cm"),2,IF(OR(H11="L",H11="30cm"),3,IF(OR(H11="XL",H11="35cm"),4,0))))),0)} -> #REF! | K11: =IFERROR(I11*J11,0) -> 0 | L11: =IFERROR(IF(C11="",0,IF(D11="PRETINA",SUMIFS($I$4:$I$10,$C$4:$C$10,C11,$D$4:$D$10,D11,$E$4:$E$10,E11,$F$4:$F$10,F11,$G$4:$G$10,G11,$H$4:$H$10,H11,$B$4:$B$10,"INGRESO")+SUMIFS($I$4:$I$10,$C$4:$C$10,C11,$D$4:$D$10,D11,$E$4:$E$10,E11,$F$4:$F$10,F11,$G$4:$G$10,G11,$H$4:$H$10,H11,$B$4:$B$10,"DE CORTE")-SUMIFS($I$4:$I$10,$C$4:$C$10,C11,$D$4:$D$10,D11,$E$4:$E$10,E11,$F$4:$F$10,F11,$G$4:$G$10,G11,$H$4:$H$10,H11,$B$4:$B$10,"SALIDA"),SUMIFS($I$4:$I$10,$C$4:$C$10,C11,$D$4:$D$10,D11,$E$4:$E$10,E11,$G$4:$G$10,G11,$H$4:$H$10,H11,$B$4:$B$10,"INGRESO")+SUMIFS($I$4:$I$10,$C$4:$C$10,C11,$D$4:$D$10,D11,$E$4:$E$10,E11,$G$4:$G$10,G11,$H$4:$H$10,H11,$B$4:$B$10,"DE CORTE")-SUMIFS($I$4:$I$10,$C$4:$C$10,C11,$D$4:$D$10,D11,$E$4:$E$10,E11,$G$4:$G$10,G11,$H$4:$H$10,H11,$B$4:$B$10,"SALIDA"))),0) -> 0 | M11: =IF(C11="",0,L11+IF(OR(B11="INGRESO",B11="DE CORTE"),I11,IF(B11="SALIDA",-I11,0))) -> 0
