Workbook
Name LISTA_SERVICIOS_TINTOR: PRECIOS_TINTORERIA!$A$4:$A$15
Name LISTA_HILOS: HILOS!$A$4:$A$22
Name LISTA_PROVEEDORES: PROVEEDORES!$A$4:$A$32
Name LISTA_TIPOS_TEJIDO: PRECIOS_TEJEDURIA!$A$4:$A$22
Name LISTA_PROGRAMAS: PROGRAMAS!$A$4:$A$103
Name LISTA_COLORES: COLORES!$A$4:$A$52

Sheet PROGRAMAS
A1: PROGRAMAS — Master con resumen hilo/tej/tint, comisión y costos totales
A2: Solo resumen. La operación detallada (factura tejeduría, tintorería por color, etc.) se llena en PROGRAMA_DETALLE.
A3: ID PROGRAMA | B3: FECHA INICIO | C3: DESCRIPCIÓN | D3: TIPO HILO | E3: ROLLOS OBJETIVO | F3: KG OBJETIVO | G3: TIPO TEJIDO | H3: CLIENTE | I3: ESTADO | J3: NOTAS | K3: ROLLOS DETALLE (auto) | L3: KG DETALLE (auto) | M3: KG HILO COMPRADO | N3: COSTO HILO TOTAL | O3: N° FACTURA HILO | P3: GUÍA HILO | Q3: KG TEJ ENVIADO | R3: KG TEJ RETORNADO | S3: KG CONOS EXTORNO | T3: KG MERMA TEJ | U3: % MERMA TEJ | V3: KG TINT ENVIADO | W3: KG TINT RETORNADO | X3: KG MERMA TINT (etapa) | Y3: % MERMA TINT | Z3: KG MERMA TOTAL | AA3: % MERMA TOTAL | AB3: COMISIÓN JOSÉ | AC3: ESTADO PAGO COMISIÓN | AD3: FECHA ENTREGA | AE3: INVERSIÓN TOTAL | AF3: COSTO PROM S/./kg | AG3: DÍAS ENTREGA
A4: PIQUE-001 | B4: 46113 | C4: PIQUE | D4: Hilo 30/1 PC | E4: 50 | F4: 1000 | G4: Pique 30/1 | H4: OverShark | I4: CERRADO | K4: =IFERROR(SUMIFS(PROGRAMA_DETALLE!$E$4:$E$503,PROGRAMA_DETALLE!$A$4:$A$503,A4),0) -> 50 | L4: =IFERROR(SUMIFS(PROGRAMA_DETALLE!$F$4:$F$503,PROGRAMA_DETALLE!$A$4:$A$503,A4),0) -> 1000 | M4: =IF(A4="","",IFERROR(SUMIFS(COMPRAS_HILO!$D$4:$D$203,COMPRAS_HILO!$B$4:$B$203,A4),0)) -> 1000 | N4: =IF(A4="","",IFERROR(SUMIFS(COMPRAS_HILO!$H$4:$H$203,COMPRAS_HILO!$B$4:$B$203,A4),0)) -> 10500 | O4: =IFERROR(IF(SUMPRODUCT((COMPRAS_HILO!$B$4:$B$203=A4)*1)=0,"",LOOKUP(2,1/((COMPRAS_HILO!$B$4:$B$203=A4)*(COMPRAS_HILO!$J$4:$J$203<>"")),COMPRAS_HILO!$J$4:$J$203)),"") -> COTTOON-001 | Q4: =IF(A4="","",IFERROR(SUMIFS(PROGRAMA_DETALLE!$H$4:$H$503,PROGRAMA_DETALLE!$A$4:$A$503,A4),0)) -> 1000 | R4: =IF(A4="","",IFERROR(SUMIFS(PROGRAMA_DETALLE!$I$4:$I$503,PROGRAMA_DETALLE!$A$4:$A$503,A4),0)) -> 980 | S4: 5 | T4: =IFERROR(Q4-R4-S4,0) -> 15 | U4: =IFERROR(T4/Q4,0) -> 0.015 | V4: =IF(A4="","",IFERROR(SUMIFS(PROGRAMA_DETALLE!$R$4:$R$503,PROGRAMA_DETALLE!$A$4:$A$503,A4),0)) -> 980 | W4: =IF(A4="","",IFERROR(SUMIFS(PROGRAMA_DETALLE!$S$4:$S$503,PROGRAMA_DETALLE!$A$4:$A$503,A4),0)) -> 890 | X4: =IFERROR(V4-W4,0) -> 90 | Y4: =IFERROR(X4/V4,0) -> 0.091836735 | Z4: =IFERROR(Q4-W4-S4,0) -> 105 | AA4: =IFERROR(Z4/Q4,0) -> 0.105 | AB4: =IFERROR(W4*DASHBOARD!$C$2,0) -> 267 | AC4: PENDIENTE | AD4: 46142 | AE4: =IFERROR(N4+IFERROR(SUMIFS(PROGRAMA_DETALLE!$M$4:$M$503,PROGRAMA_DETALLE!$A$4:$A$503,A4),0)+IFERROR(SUMIFS(PROGRAMA_DETALLE!$Z$4:$Z$503,PROGRAMA_DETALLE!$A$4:$A$503,A4),0)+AB4,0) -> 19171.175 | AF4: =IFERROR(AE4/W4,0) -> 21.540646 | AG4: =IFERROR(AD4-B4,"") -> 29
A5: FULL LYCRA 50/1-001 | B5: 46152 | C5: 50/1 ALGODON 100% | D5: hilo 50/1 cotton +lycra 4% | E5: 25 | F5: 500 | G5: full lycra | H5: OverShark | I5: EN TEJEDURÍA | K5: =IFERROR(SUMIFS(PROGRAMA_DETALLE!$E$4:$E$503,PROGRAMA_DETALLE!$A$4:$A$503,A5),0) -> 25 | L5: =IFERROR(SUMIFS(PROGRAMA_DETALLE!$F$4:$F$503,PROGRAMA_DETALLE!$A$4:$A$503,A5),0) -> 500 | M5: =IF(A5="","",IFERROR(SUMIFS(COMPRAS_HILO!$D$4:$D$203,COMPRAS_HILO!$B$4:$B$203,A5),0)) -> 500 | N5: =IF(A5="","",IFERROR(SUMIFS(COMPRAS_HILO!$H$4:$H$203,COMPRAS_HILO!$B$4:$B$203,A5),0)) -> 9625 | O5: =IFERROR(IF(SUMPRODUCT((COMPRAS_HILO!$B$4:$B$203=A5)*1)=0,"",LOOKUP(2,1/((COMPRAS_HILO!$B$4:$B$203=A5)*(COMPRAS_HILO!$J$4:$J$203<>"")),COMPRAS_HILO!$J$4:$J$203)),"") -> COTTOON-001 | Q5: =IF(A5="","",IFERROR(SUMIFS(PROGRAMA_DETALLE!$H$4:$H$503,PROGRAMA_DETALLE!$A$4:$A$503,A5),0)) -> 500 | R5: =IF(A5="","",IFERROR(SUMIFS(PROGRAMA_DETALLE!$I$4:$I$503,PROGRAMA_DETALLE!$A$4:$A$503,A5),0)) -> 0 | T5: =IFERROR(Q5-R5-S5,0) -> 500 | U5: =IFERROR(T5/Q5,0) -> 1 | V5: =IF(A5="","",IFERROR(SUMIFS(PROGRAMA_DETALLE!$R$4:$R$503,PROGRAMA_DETALLE!$A$4:$A$503,A5),0)) -> 0 | W5: =IF(A5="","",IFERROR(SUMIFS(PROGRAMA_DETALLE!$S$4:$S$503,PROGRAMA_DETALLE!$A$4:$A$503,A5),0)) -> 0 | X5: =IFERROR(V5-W5,0) -> 0 | Y5: =IFERROR(X5/V5,0) -> 0 | Z5: =IFERROR(Q5-W5-S5,0) -> 500 | AA5: =IFERROR(Z5/Q5,0) -> 1 | AB5: =IFERROR(W5*DASHBOARD!$C$2,0) -> 0 | AE5: =IFERROR(N5+IFERROR(SUMIFS(PROGRAMA_DETALLE!$M$4:$M$503,PROGRAMA_DETALLE!$A$4:$A$503,A5),0)+IFERROR(SUMIFS(PROGRAMA_DETALLE!$Z$4:$Z$503,PROGRAMA_DETALLE!$A$4:$A$503,A5),0)+AB5,0) -> 9625 | AF5: =IFERROR(AE5/W5,0) -> 0 | AG5: =IFERROR(AD5-B5,"") -> -46152
A6: frecnh terry - 001 | B6: 46152 | C6: french terry 30/1 | D6: Hilo 30/1 PC | E6: 145 | F6: 2943 | G6: French terry 30/1 | H6: Bravos | I6: EN TEJEDURÍA | K6: =IFERROR(SUMIFS(PROGRAMA_DETALLE!$E$4:$E$503,PROGRAMA_DETALLE!$A$4:$A$503,A6),0) -> 145 | L6: =IFERROR(SUMIFS(PROGRAMA_DETALLE!$F$4:$F$503,PROGRAMA_DETALLE!$A$4:$A$503,A6),0) -> 2900 | M6: =IF(A6="","",IFERROR(SUMIFS(COMPRAS_HILO!$D$4:$D$203,COMPRAS_HILO!$B$4:$B$203,A6),0)) -> 3000 | N6: =IF(A6="","",IFERROR(SUMIFS(COMPRAS_HILO!$H$4:$H$203,COMPRAS_HILO!$B$4:$B$203,A6),0)) -> 31050 | O6: =IFERROR(IF(SUMPRODUCT((COMPRAS_HILO!$B$4:$B$203=A6)*1)=0,"",LOOKUP(2,1/((COMPRAS_HILO!$B$4:$B$203=A6)*(COMPRAS_HILO!$J$4:$J$203<>"")),COMPRAS_HILO!$J$4:$J$203)),"") | Q6: =IF(A6="","",IFERROR(SUMIFS(PROGRAMA_DETALLE!$H$4:$H$503,PROGRAMA_DETALLE!$A$4:$A$503,A6),0)) -> 0 | R6: =IF(A6="","",IFERROR(SUMIFS(PROGRAMA_DETALLE!$I$4:$I$503,PROGRAMA_DETALLE!$A$4:$A$503,A6),0)) -> 0 | T6: =IFERROR(Q6-R6-S6,0) -> 0 | U6: =IFERROR(T6/Q6,0) -> 0 | V6: =IF(A6="","",IFERROR(SUMIFS(PROGRAMA_DETALLE!$R$4:$R$503,PROGRAMA_DETALLE!$A$4:$A$503,A6),0)) -> 0 | W6: =IF(A6="","",IFERROR(SUMIFS(PROGRAMA_DETALLE!$S$4:$S$503,PROGRAMA_DETALLE!$A$4:$A$503,A6),0)) -> 0 | X6: =IFERROR(V6-W6,0) -> 0 | Y6: =IFERROR(X6/V6,0) -> 0 | Z6: =IFERROR(Q6-W6-S6,0) -> 0 | AA6: =IFERROR(Z6/Q6,0) -> 0 | AB6: =IFERROR(W6*DASHBOARD!$C$2,0) -> 0 | AE6: =IFERROR(N6+IFERROR(SUMIFS(PROGRAMA_DETALLE!$M$4:$M$503,PROGRAMA_DETALLE!$A$4:$A$503,A6),0)+IFERROR(SUMIFS(PROGRAMA_DETALLE!$Z$4:$Z$503,PROGRAMA_DETALLE!$A$4:$A$503,A6),0)+AB6,0) -> 31050 | AF6: =IFERROR(AE6/W6,0) -> 0 | AG6: =IFERROR(AD6-B6,"") -> -46152
A7: jersey algodon - 001 | B7: 46313 | C7: ALGODON 30/1 | D7: Hilo 30/1 ALGODON | E7: 33 | F7: 660 | G7: Jersey 30/1 | H7: OverShark | I7: EN TINTORERÍA | K7: =IFERROR(SUMIFS(PROGRAMA_DETALLE!$E$4:$E$503,PROGRAMA_DETALLE!$A$4:$A$503,A7),0) -> 0 | L7: =IFERROR(SUMIFS(PROGRAMA_DETALLE!$F$4:$F$503,PROGRAMA_DETALLE!$A$4:$A$503,A7),0) -> 0 | M7: =IF(A7="","",IFERROR(SUMIFS(COMPRAS_HILO!$D$4:$D$203,COMPRAS_HILO!$B$4:$B$203,A7),0)) -> 660 | N7: =IF(A7="","",IFERROR(SUMIFS(COMPRAS_HILO!$H$4:$H$203,COMPRAS_HILO!$B$4:$B$203,A7),0)) -> 9108 | O7: =IFERROR(IF(SUMPRODUCT((COMPRAS_HILO!$B$4:$B$203=A7)*1)=0,"",LOOKUP(2,1/((COMPRAS_HILO!$B$4:$B$203=A7)*(COMPRAS_HILO!$J$4:$J$203<>"")),COMPRAS_HILO!$J$4:$J$203)),"") | Q7: =IF(A7="","",IFERROR(SUMIFS(PROGRAMA_DETALLE!$H$4:$H$503,PROGRAMA_DETALLE!$A$4:$A$503,A7),0)) -> 0 | R7: =IF(A7="","",IFERROR(SUMIFS(PROGRAMA_DETALLE!$I$4:$I$503,PROGRAMA_DETALLE!$A$4:$A$503,A7),0)) -> 0 | T7: =IFERROR(Q7-R7-S7,0) -> 0 | U7: =IFERROR(T7/Q7,0) -> 0 | V7: =IF(A7="","",IFERROR(SUMIFS(PROGRAMA_DETALLE!$R$4:$R$503,PROGRAMA_DETALLE!$A$4:$A$503,A7),0)) -> 0 | W7: =IF(A7="","",IFERROR(SUMIFS(PROGRAMA_DETALLE!$S$4:$S$503,PROGRAMA_DETALLE!$A$4:$A$503,A7),0)) -> 0 | X7: =IFERROR(V7-W7,0) -> 0 | Y7: =IFERROR(X7/V7,0) -> 0 | Z7: =IFERROR(Q7-W7-S7,0) -> 0 | AA7: =IFERROR(Z7/Q7,0) -> 0 | AB7: =IFERROR(W7*DASHBOARD!$C$2,0) -> 0 | AE7: =IFERROR(N7+IFERROR(SUMIFS(PROGRAMA_DETALLE!$M$4:$M$503,PROGRAMA_DETALLE!$A$4:$A$503,A7),0)+IFERROR(SUMIFS(PROGRAMA_DETALLE!$Z$4:$Z$503,PROGRAMA_DETALLE!$A$4:$A$503,A7),0)+AB7,0) -> 9108 | AF7: =IFERROR(AE7/W7,0) -> 0 | AG7: =IFERROR(AD7-B7,"") -> -46313
A8: rib 1x1- jersey algodon -001 | B8: 46160 | C8: rib complemento ja-001 | D8: Hilo 30/1 ALGODON | E8: 2 | F8: 40 | G8: Rib 1x1 | H8: OverShark | I8: EN TINTORERÍA | K8: =IFERROR(SUMIFS(PROGRAMA_DETALLE!$E$4:$E$503,PROGRAMA_DETALLE!$A$4:$A$503,A8),0) -> 0 | L8: =IFERROR(SUMIFS(PROGRAMA_DETALLE!$F$4:$F$503,PROGRAMA_DETALLE!$A$4:$A$503,A8),0) -> 0 | M8: =IF(A8="","",IFERROR(SUMIFS(COMPRAS_HILO!$D$4:$D$203,COMPRAS_HILO!$B$4:$B$203,A8),0)) -> 0 | N8: =IF(A8="","",IFERROR(SUMIFS(COMPRAS_HILO!$H$4:$H$203,COMPRAS_HILO!$B$4:$B$203,A8),0)) -> 0 | O8: =IFERROR(IF(SUMPRODUCT((COMPRAS_HILO!$B$4:$B$203=A8)*1)=0,"",LOOKUP(2,1/((COMPRAS_HILO!$B$4:$B$203=A8)*(COMPRAS_HILO!$J$4:$J$203<>"")),COMPRAS_HILO!$J$4:$J$203)),"") | Q8: =IF(A8="","",IFERROR(SUMIFS(PROGRAMA_DETALLE!$H$4:$H$503,PROGRAMA_DETALLE!$A$4:$A$503,A8),0)) -> 0 | R8: =IF(A8="","",IFERROR(SUMIFS(PROGRAMA_DETALLE!$I$4:$I$503,PROGRAMA_DETALLE!$A$4:$A$503,A8),0)) -> 0 | T8: =IFERROR(Q8-R8-S8,0) -> 0 | U8: =IFERROR(T8/Q8,0) -> 0 | V8: =IF(A8="","",IFERROR(SUMIFS(PROGRAMA_DETALLE!$R$4:$R$503,PROGRAMA_DETALLE!$A$4:$A$503,A8),0)) -> 0 | W8: =IF(A8="","",IFERROR(SUMIFS(PROGRAMA_DETALLE!$S$4:$S$503,PROGRAMA_DETALLE!$A$4:$A$503,A8),0)) -> 0 | X8: =IFERROR(V8-W8,0) -> 0 | Y8: =IFERROR(X8/V8,0) -> 0 | Z8: =IFERROR(Q8-W8-S8,0) -> 0 | AA8: =IFERROR(Z8/Q8,0) -> 0 | AB8: =IFERROR(W8*DASHBOARD!$C$2,0) -> 0 | AE8: =IFERROR(N8+IFERROR(SUMIFS(PROGRAMA_DETALLE!$M$4:$M$503,PROGRAMA_DETALLE!$A$4:$A$503,A8),0)+IFERROR(SUMIFS(PROGRAMA_DETALLE!$Z$4:$Z$503,PROGRAMA_DETALLE!$A$4:$A$503,A8),0)+AB8,0) -> 0 | AF8: =IFERROR(AE8/W8,0) -> 0 | AG8: =IFERROR(AD8-B8,"") -> -46160
K9: =IFERROR(SUMIFS(PROGRAMA_DETALLE!$E$4:$E$503,PROGRAMA_DETALLE!$A$4:$A$503,A9),0) -> 0 | L9: =IFERROR(SUMIFS(PROGRAMA_DETALLE!$F$4:$F$503,PROGRAMA_DETALLE!$A$4:$A$503,A9),0) -> 0 | M9: =IF(A9="","",IFERROR(SUMIFS(COMPRAS_HILO!$D$4:$D$203,COMPRAS_HILO!$B$4:$B$203,A9),0)) | N9: =IF(A9="","",IFERROR(SUMIFS(COMPRAS_HILO!$H$4:$H$203,COMPRAS_HILO!$B$4:$B$203,A9),0)) | O9: =IFERROR(IF(SUMPRODUCT((COMPRAS_HILO!$B$4:$B$203=A9)*1)=0,"",LOOKUP(2,1/((COMPRAS_HILO!$B$4:$B$203=A9)*(COMPRAS_HILO!$J$4:$J$203<>"")),COMPRAS_HILO!$J$4:$J$203)),"") | Q9: =IF(A9="","",IFERROR(SUMIFS(PROGRAMA_DETALLE!$H$4:$H$503,PROGRAMA_DETALLE!$A$4:$A$503,A9),0)) | R9: =IF(A9="","",IFERROR(SUMIFS(PROGRAMA_DETALLE!$I$4:$I$503,PROGRAMA_DETALLE!$A$4:$A$503,A9),0)) | T9: =IFERROR(Q9-R9-S9,0) -> 0 | U9: =IFERROR(T9/Q9,0) -> 0 | V9: =IF(A9="","",IFERROR(SUMIFS(PROGRAMA_DETALLE!$R$4:$R$503,PROGRAMA_DETALLE!$A$4:$A$503,A9),0)) | W9: =IF(A9="","",IFERROR(SUMIFS(PROGRAMA_DETALLE!$S$4:$S$503,PROGRAMA_DETALLE!$A$4:$A$503,A9),0)) | X9: =IFERROR(V9-W9,0) -> 0 | Y9: =IFERROR(X9/V9,0) -> 0 | Z9: =IFERROR(Q9-W9-S9,0) -> 0 | AA9: =IFERROR(Z9/Q9,0) -> 0 | AB9: =IFERROR(W9*DASHBOARD!$C$2,0) -> 0 | AE9: =IFERROR(N9+IFERROR(SUMIFS(PROGRAMA_DETALLE!$M$4:$M$503,PROGRAMA_DETALLE!$A$4:$A$503,A9),0)+IFERROR(SUMIFS(PROGRAMA_DETALLE!$Z$4:$Z$503,PROGRAMA_DETALLE!$A$4:$A$503,A9),0)+AB9,0) -> 0 | AF9: =IFERROR(AE9/W9,0) -> 0 | AG9: =IFERROR(AD9-B9,"") -> 0
K10: =IFERROR(SUMIFS(PROGRAMA_DETALLE!$E$4:$E$503,PROGRAMA_DETALLE!$A$4:$A$503,A10),0) -> 0 | L10: =IFERROR(SUMIFS(PROGRAMA_DETALLE!$F$4:$F$503,PROGRAMA_DETALLE!$A$4:$A$503,A10),0) -> 0 | M10: =IF(A10="","",IFERROR(SUMIFS(COMPRAS_HILO!$D$4:$D$203,COMPRAS_HILO!$B$4:$B$203,A10),0)) | N10: =IF(A10="","",IFERROR(SUMIFS(COMPRAS_HILO!$H$4:$H$203,COMPRAS_HILO!$B$4:$B$203,A10),0)) | O10: =IFERROR(IF(SUMPRODUCT((COMPRAS_HILO!$B$4:$B$203=A10)*1)=0,"",LOOKUP(2,1/((COMPRAS_HILO!$B$4:$B$203=A10)*(COMPRAS_HILO!$J$4:$J$203<>"")),COMPRAS_HILO!$J$4:$J$203)),"") | Q10: =IF(A10="","",IFERROR(SUMIFS(PROGRAMA_DETALLE!$H$4:$H$503,PROGRAMA_DETALLE!$A$4:$A$503,A10),0)) | R10: =IF(A10="","",IFERROR(SUMIFS(PROGRAMA_DETALLE!$I$4:$I$503,PROGRAMA_DETALLE!$A$4:$A$503,A10),0)) | T10: =IFERROR(Q10-R10-S10,0) -> 0 | U10: =IFERROR(T10/Q10,0) -> 0 | V10: =IF(A10="","",IFERROR(SUMIFS(PROGRAMA_DETALLE!$R$4:$R$503,PROGRAMA_DETALLE!$A$4:$A$503,A10),0)) | W10: =IF(A10="","",IFERROR(SUMIFS(PROGRAMA_DETALLE!$S$4:$S$503,PROGRAMA_DETALLE!$A$4:$A$503,A10),0)) | X10: =IFERROR(V10-W10,0) -> 0 | Y10: =IFERROR(X10/V10,0) -> 0 | Z10: =IFERROR(Q10-W10-S10,0) -> 0 | AA10: =IFERROR(Z10/Q10,0) -> 0 | AB10: =IFERROR(W10*DASHBOARD!$C$2,0) -> 0 | AE10: =IFERROR(N10+IFERROR(SUMIFS(PROGRAMA_DETALLE!$M$4:$M$503,PROGRAMA_DETALLE!$A$4:$A$503,A10),0)+IFERROR(SUMIFS(PROGRAMA_DETALLE!$Z$4:$Z$503,PROGRAMA_DETALLE!$A$4:$A$503,A10),0)+AB10,0) -> 0 | AF10: =IFERROR(AE10/W10,0) -> 0 | AG10: =IFERROR(AD10-B10,"") -> 0
K11: =IFERROR(SUMIFS(PROGRAMA_DETALLE!$E$4:$E$503,PROGRAMA_DETALLE!$A$4:$A$503,A11),0) -> 0 | L11: =IFERROR(SUMIFS(PROGRAMA_DETALLE!$F$4:$F$503,PROGRAMA_DETALLE!$A$4:$A$503,A11),0) -> 0 | M11: =IF(A11="","",IFERROR(SUMIFS(COMPRAS_HILO!$D$4:$D$203,COMPRAS_HILO!$B$4:$B$203,A11),0)) | N11: =IF(A11="","",IFERROR(SUMIFS(COMPRAS_HILO!$H$4:$H$203,COMPRAS_HILO!$B$4:$B$203,A11),0)) | O11: =IFERROR(IF(SUMPRODUCT((COMPRAS_HILO!$B$4:$B$203=A11)*1)=0,"",LOOKUP(2,1/((COMPRAS_HILO!$B$4:$B$203=A11)*(COMPRAS_HILO!$J$4:$J$203<>"")),COMPRAS_HILO!$J$4:$J$203)),"") | Q11: =IF(A11="","",IFERROR(SUMIFS(PROGRAMA_DETALLE!$H$4:$H$503,PROGRAMA_DETALLE!$A$4:$A$503,A11),0)) | R11: =IF(A11="","",IFERROR(SUMIFS(PROGRAMA_DETALLE!$I$4:$I$503,PROGRAMA_DETALLE!$A$4:$A$503,A11),0)) | T11: =IFERROR(Q11-R11-S11,0) -> 0 | U11: =IFERROR(T11/Q11,0) -> 0 | V11: =IF(A11="","",IFERROR(SUMIFS(PROGRAMA_DETALLE!$R$4:$R$503,PROGRAMA_DETALLE!$A$4:$A$503,A11),0)) | W11: =IF(A11="","",IFERROR(SUMIFS(PROGRAMA_DETALLE!$S$4:$S$503,PROGRAMA_DETALLE!$A$4:$A$503,A11),0)) | X11: =IFERROR(V11-W11,0) -> 0 | Y11: =IFERROR(X11/V11,0) -> 0 | Z11: =IFERROR(Q11-W11-S11,0) -> 0 | AA11: =IFERROR(Z11/Q11,0) -> 0 | AB11: =IFERROR(W11*DASHBOARD!$C$2,0) -> 0 | AE11: =IFERROR(N11+IFERROR(SUMIFS(PROGRAMA_DETALLE!$M$4:$M$503,PROGRAMA_DETALLE!$A$4:$A$503,A11),0)+IFERROR(SUMIFS(PROGRAMA_DETALLE!$Z$4:$Z$503,PROGRAMA_DETALLE!$A$4:$A$503,A11),0)+AB11,0) -> 0 | AF11: =IFERROR(AE11/W11,0) -> 0 | AG11: =IFERROR(AD11-B11,"") -> 0
K12: =IFERROR(SUMIFS(PROGRAMA_DETALLE!$E$4:$E$503,PROGRAMA_DETALLE!$A$4:$A$503,A12),0) -> 0 | L12: =IFERROR(SUMIFS(PROGRAMA_DETALLE!$F$4:$F$503,PROGRAMA_DETALLE!$A$4:$A$503,A12),0) -> 0 | M12: =IF(A12="","",IFERROR(SUMIFS(COMPRAS_HILO!$D$4:$D$203,COMPRAS_HILO!$B$4:$B$203,A12),0)) | N12: =IF(A12="","",IFERROR(SUMIFS(COMPRAS_HILO!$H$4:$H$203,COMPRAS_HILO!$B$4:$B$203,A12),0)) | O12: =IFERROR(IF(SUMPRODUCT((COMPRAS_HILO!$B$4:$B$203=A12)*1)=0,"",LOOKUP(2,1/((COMPRAS_HILO!$B$4:$B$203=A12)*(COMPRAS_HILO!$J$4:$J$203<>"")),COMPRAS_HILO!$J$4:$J$203)),"") | Q12: =IF(A12="","",IFERROR(SUMIFS(PROGRAMA_DETALLE!$H$4:$H$503,PROGRAMA_DETALLE!$A$4:$A$503,A12),0)) | R12: =IF(A12="","",IFERROR(SUMIFS(PROGRAMA_DETALLE!$I$4:$I$503,PROGRAMA_DETALLE!$A$4:$A$503,A12),0)) | T12: =IFERROR(Q12-R12-S12,0) -> 0 | U12: =IFERROR(T12/Q12,0) -> 0 | V12: =IF(A12="","",IFERROR(SUMIFS(PROGRAMA_DETALLE!$R$4:$R$503,PROGRAMA_DETALLE!$A$4:$A$503,A12),0)) | W12: =IF(A12="","",IFERROR(SUMIFS(PROGRAMA_DETALLE!$S$4:$S$503,PROGRAMA_DETALLE!$A$4:$A$503,A12),0)) | X12: =IFERROR(V12-W12,0) -> 0 | Y12: =IFERROR(X12/V12,0) -> 0 | Z12: =IFERROR(Q12-W12-S12,0) -> 0 | AA12: =IFERROR(Z12/Q12,0) -> 0 | AB12: =IFERROR(W12*DASHBOARD!$C$2,0) -> 0 | AE12: =IFERROR(N12+IFERROR(SUMIFS(PROGRAMA_DETALLE!$M$4:$M$503,PROGRAMA_DETALLE!$A$4:$A$503,A12),0)+IFERROR(SUMIFS(PROGRAMA_DETALLE!$Z$4:$Z$503,PROGRAMA_DETALLE!$A$4:$A$503,A12),0)+AB12,0) -> 0 | AF12: =IFERROR(AE12/W12,0) -> 0 | AG12: =IFERROR(AD12-B12,"") -> 0
K13: =IFERROR(SUMIFS(PROGRAMA_DETALLE!$E$4:$E$503,PROGRAMA_DETALLE!$A$4:$A$503,A13),0) -> 0 | L13: =IFERROR(SUMIFS(PROGRAMA_DETALLE!$F$4:$F$503,PROGRAMA_DETALLE!$A$4:$A$503,A13),0) -> 0 | M13: =IF(A13="","",IFERROR(SUMIFS(COMPRAS_HILO!$D$4:$D$203,COMPRAS_HILO!$B$4:$B$203,A13),0)) | N13: =IF(A13="","",IFERROR(SUMIFS(COMPRAS_HILO!$H$4:$H$203,COMPRAS_HILO!$B$4:$B$203,A13),0)) | O13: =IFERROR(IF(SUMPRODUCT((COMPRAS_HILO!$B$4:$B$203=A13)*1)=0,"",LOOKUP(2,1/((COMPRAS_HILO!$B$4:$B$203=A13)*(COMPRAS_HILO!$J$4:$J$203<>"")),COMPRAS_HILO!$J$4:$J$203)),"") | Q13: =IF(A13="","",IFERROR(SUMIFS(PROGRAMA_DETALLE!$H$4:$H$503,PROGRAMA_DETALLE!$A$4:$A$503,A13),0)) | R13: =IF(A13="","",IFERROR(SUMIFS(PROGRAMA_DETALLE!$I$4:$I$503,PROGRAMA_DETALLE!$A$4:$A$503,A13),0)) | T13: =IFERROR(Q13-R13-S13,0) -> 0 | U13: =IFERROR(T13/Q13,0) -> 0 | V13: =IF(A13="","",IFERROR(SUMIFS(PROGRAMA_DETALLE!$R$4:$R$503,PROGRAMA_DETALLE!$A$4:$A$503,A13),0)) | W13: =IF(A13="","",IFERROR(SUMIFS(PROGRAMA_DETALLE!$S$4:$S$503,PROGRAMA_DETALLE!$A$4:$A$503,A13),0)) | X13: =IFERROR(V13-W13,0) -> 0 | Y13: =IFERROR(X13/V13,0) -> 0 | Z13: =IFERROR(Q13-W13-S13,0) -> 0 | AA13: =IFERROR(Z13/Q13,0) -> 0 | AB13: =IFERROR(W13*DASHBOARD!$C$2,0) -> 0 | AE13: =IFERROR(N13+IFERROR(SUMIFS(PROGRAMA_DETALLE!$M$4:$M$503,PROGRAMA_DETALLE!$A$4:$A$503,A13),0)+IFERROR(SUMIFS(PROGRAMA_DETALLE!$Z$4:$Z$503,PROGRAMA_DETALLE!$A$4:$A$503,A13),0)+AB13,0) -> 0 | AF13: =IFERROR(AE13/W13,0) -> 0 | AG13: =IFERROR(AD13-B13,"") -> 0
K14: =IFERROR(SUMIFS(PROGRAMA_DETALLE!$E$4:$E$503,PROGRAMA_DETALLE!$A$4:$A$503,A14),0) -> 0 | L14: =IFERROR(SUMIFS(PROGRAMA_DETALLE!$F$4:$F$503,PROGRAMA_DETALLE!$A$4:$A$503,A14),0) -> 0 | M14: =IF(A14="","",IFERROR(SUMIFS(COMPRAS_HILO!$D$4:$D$203,COMPRAS_HILO!$B$4:$B$203,A14),0)) | N14: =IF(A14="","",IFERROR(SUMIFS(COMPRAS_HILO!$H$4:$H$203,COMPRAS_HILO!$B$4:$B$203,A14),0)) | O14: =IFERROR(IF(SUMPRODUCT((COMPRAS_HILO!$B$4:$B$203=A14)*1)=0,"",LOOKUP(2,1/((COMPRAS_HILO!$B$4:$B$203=A14)*(COMPRAS_HILO!$J$4:$J$203<>"")),COMPRAS_HILO!$J$4:$J$203)),"") | Q14: =IF(A14="","",IFERROR(SUMIFS(PROGRAMA_DETALLE!$H$4:$H$503,PROGRAMA_DETALLE!$A$4:$A$503,A14),0)) | R14: =IF(A14="","",IFERROR(SUMIFS(PROGRAMA_DETALLE!$I$4:$I$503,PROGRAMA_DETALLE!$A$4:$A$503,A14),0)) | T14: =IFERROR(Q14-R14-S14,0) -> 0 | U14: =IFERROR(T14/Q14,0) -> 0 | V14: =IF(A14="","",IFERROR(SUMIFS(PROGRAMA_DETALLE!$R$4:$R$503,PROGRAMA_DETALLE!$A$4:$A$503,A14),0)) | W14: =IF(A14="","",IFERROR(SUMIFS(PROGRAMA_DETALLE!$S$4:$S$503,PROGRAMA_DETALLE!$A$4:$A$503,A14),0)) | X14: =IFERROR(V14-W14,0) -> 0 | Y14: =IFERROR(X14/V14,0) -> 0 | Z14: =IFERROR(Q14-W14-S14,0) -> 0 | AA14: =IFERROR(Z14/Q14,0) -> 0 | AB14: =IFERROR(W14*DASHBOARD!$C$2,0) -> 0 | AE14: =IFERROR(N14+IFERROR(SUMIFS(PROGRAMA_DETALLE!$M$4:$M$503,PROGRAMA_DETALLE!$A$4:$A$503,A14),0)+IFERROR(SUMIFS(PROGRAMA_DETALLE!$Z$4:$Z$503,PROGRAMA_DETALLE!$A$4:$A$503,A14),0)+AB14,0) -> 0 | AF14: =IFERROR(AE14/W14,0) -> 0 | AG14: =IFERROR(AD14-B14,"") -> 0
K15: =IFERROR(SUMIFS(PROGRAMA_DETALLE!$E$4:$E$503,PROGRAMA_DETALLE!$A$4:$A$503,A15),0) -> 0 | L15: =IFERROR(SUMIFS(PROGRAMA_DETALLE!$F$4:$F$503,PROGRAMA_DETALLE!$A$4:$A$503,A15),0) -> 0 | M15: =IF(A15="","",IFERROR(SUMIFS(COMPRAS_HILO!$D$4:$D$203,COMPRAS_HILO!$B$4:$B$203,A15),0)) | N15: =IF(A15="","",IFERROR(SUMIFS(COMPRAS_HILO!$H$4:$H$203,COMPRAS_HILO!$B$4:$B$203,A15),0)) | O15: =IFERROR(IF(SUMPRODUCT((COMPRAS_HILO!$B$4:$B$203=A15)*1)=0,"",LOOKUP(2,1/((COMPRAS_HILO!$B$4:$B$203=A15)*(COMPRAS_HILO!$J$4:$J$203<>"")),COMPRAS_HILO!$J$4:$J$203)),"") | Q15: =IF(A15="","",IFERROR(SUMIFS(PROGRAMA_DETALLE!$H$4:$H$503,PROGRAMA_DETALLE!$A$4:$A$503,A15),0)) | R15: =IF(A15="","",IFERROR(SUMIFS(PROGRAMA_DETALLE!$I$4:$I$503,PROGRAMA_DETALLE!$A$4:$A$503,A15),0)) | T15: =IFERROR(Q15-R15-S15,0) -> 0 | U15: =IFERROR(T15/Q15,0) -> 0 | V15: =IF(A15="","",IFERROR(SUMIFS(PROGRAMA_DETALLE!$R$4:$R$503,PROGRAMA_DETALLE!$A$4:$A$503,A15),0)) | W15: =IF(A15="","",IFERROR(SUMIFS(PROGRAMA_DETALLE!$S$4:$S$503,PROGRAMA_DETALLE!$A$4:$A$503,A15),0)) | X15: =IFERROR(V15-W15,0) -> 0 | Y15: =IFERROR(X15/V15,0) -> 0 | Z15: =IFERROR(Q15-W15-S15,0) -> 0 | AA15: =IFERROR(Z15/Q15,0) -> 0 | AB15: =IFERROR(W15*DASHBOARD!$C$2,0) -> 0 | AE15: =IFERROR(N15+IFERROR(SUMIFS(PROGRAMA_DETALLE!$M$4:$M$503,PROGRAMA_DETALLE!$A$4:$A$503,A15),0)+IFERROR(SUMIFS(PROGRAMA_DETALLE!$Z$4:$Z$503,PROGRAMA_DETALLE!$A$4:$A$503,A15),0)+AB15,0) -> 0 | AF15: =IFERROR(AE15/W15,0) -> 0 | AG15: =IFERROR(AD15-B15,"") -> 0
K16: =IFERROR(SUMIFS(PROGRAMA_DETALLE!$E$4:$E$503,PROGRAMA_DETALLE!$A$4:$A$503,A16),0) -> 0 | L16: =IFERROR(SUMIFS(PROGRAMA_DETALLE!$F$4:$F$503,PROGRAMA_DETALLE!$A$4:$A$503,A16),0) -> 0 | M16: =IF(A16="","",IFERROR(SUMIFS(COMPRAS_HILO!$D$4:$D$203,COMPRAS_HILO!$B$4:$B$203,A16),0)) | N16: =IF(A16="","",IFERROR(SUMIFS(COMPRAS_HILO!$H$4:$H$203,COMPRAS_HILO!$B$4:$B$203,A16),0)) | O16: =IFERROR(IF(SUMPRODUCT((COMPRAS_HILO!$B$4:$B$203=A16)*1)=0,"",LOOKUP(2,1/((COMPRAS_HILO!$B$4:$B$203=A16)*(COMPRAS_HILO!$J$4:$J$203<>"")),COMPRAS_HILO!$J$4:$J$203)),"") | Q16: =IF(A16="","",IFERROR(SUMIFS(PROGRAMA_DETALLE!$H$4:$H$503,PROGRAMA_DETALLE!$A$4:$A$503,A16),0)) | R16: =IF(A16="","",IFERROR(SUMIFS(PROGRAMA_DETALLE!$I$4:$I$503,PROGRAMA_DETALLE!$A$4:$A$503,A16),0)) | T16: =IFERROR(Q16-R16-S16,0) -> 0 | U16: =IFERROR(T16/Q16,0) -> 0 | V16: =IF(A16="","",IFERROR(SUMIFS(PROGRAMA_DETALLE!$R$4:$R$503,PROGRAMA_DETALLE!$A$4:$A$503,A16),0)) | W16: =IF(A16="","",IFERROR(SUMIFS(PROGRAMA_DETALLE!$S$4:$S$503,PROGRAMA_DETALLE!$A$4:$A$503,A16),0)) | X16: =IFERROR(V16-W16,0) -> 0 | Y16: =IFERROR(X16/V16,0) -> 0 | Z16: =IFERROR(Q16-W16-S16,0) -> 0 | AA16: =IFERROR(Z16/Q16,0) -> 0 | AB16: =IFERROR(W16*DASHBOARD!$C$2,0) -> 0 | AE16: =IFERROR(N16+IFERROR(SUMIFS(PROGRAMA_DETALLE!$M$4:$M$503,PROGRAMA_DETALLE!$A$4:$A$503,A16),0)+IFERROR(SUMIFS(PROGRAMA_DETALLE!$Z$4:$Z$503,PROGRAMA_DETALLE!$A$4:$A$503,A16),0)+AB16,0) -> 0 | AF16: =IFERROR(AE16/W16,0) -> 0 | AG16: =IFERROR(AD16-B16,"") -> 0
K17: =IFERROR(SUMIFS(PROGRAMA_DETALLE!$E$4:$E$503,PROGRAMA_DETALLE!$A$4:$A$503,A17),0) -> 0 | L17: =IFERROR(SUMIFS(PROGRAMA_DETALLE!$F$4:$F$503,PROGRAMA_DETALLE!$A$4:$A$503,A17),0) -> 0 | M17: =IF(A17="","",IFERROR(SUMIFS(COMPRAS_HILO!$D$4:$D$203,COMPRAS_HILO!$B$4:$B$203,A17),0)) | N17: =IF(A17="","",IFERROR(SUMIFS(COMPRAS_HILO!$H$4:$H$203,COMPRAS_HILO!$B$4:$B$203,A17),0)) | O17: =IFERROR(IF(SUMPRODUCT((COMPRAS_HILO!$B$4:$B$203=A17)*1)=0,"",LOOKUP(2,1/((COMPRAS_HILO!$B$4:$B$203=A17)*(COMPRAS_HILO!$J$4:$J$203<>"")),COMPRAS_HILO!$J$4:$J$203)),"") | Q17: =IF(A17="","",IFERROR(SUMIFS(PROGRAMA_DETALLE!$H$4:$H$503,PROGRAMA_DETALLE!$A$4:$A$503,A17),0)) | R17: =IF(A17="","",IFERROR(SUMIFS(PROGRAMA_DETALLE!$I$4:$I$503,PROGRAMA_DETALLE!$A$4:$A$503,A17),0)) | T17: =IFERROR(Q17-R17-S17,0) -> 0 | U17: =IFERROR(T17/Q17,0) -> 0 | V17: =IF(A17="","",IFERROR(SUMIFS(PROGRAMA_DETALLE!$R$4:$R$503,PROGRAMA_DETALLE!$A$4:$A$503,A17),0)) | W17: =IF(A17="","",IFERROR(SUMIFS(PROGRAMA_DETALLE!$S$4:$S$503,PROGRAMA_DETALLE!$A$4:$A$503,A17),0)) | X17: =IFERROR(V17-W17,0) -> 0 | Y17: =IFERROR(X17/V17,0) -> 0 | Z17: =IFERROR(Q17-W17-S17,0) -> 0 | AA17: =IFERROR(Z17/Q17,0) -> 0 | AB17: =IFERROR(W17*DASHBOARD!$C$2,0) -> 0 | AE17: =IFERROR(N17+IFERROR(SUMIFS(PROGRAMA_DETALLE!$M$4:$M$503,PROGRAMA_DETALLE!$A$4:$A$503,A17),0)+IFERROR(SUMIFS(PROGRAMA_DETALLE!$Z$4:$Z$503,PROGRAMA_DETALLE!$A$4:$A$503,A17),0)+AB17,0) -> 0 | AF17: =IFERROR(AE17/W17,0) -> 0 | AG17: =IFERROR(AD17-B17,"") -> 0
K18: =IFERROR(SUMIFS(PROGRAMA_DETALLE!$E$4:$E$503,PROGRAMA_DETALLE!$A$4:$A$503,A18),0) -> 0 | L18: =IFERROR(SUMIFS(PROGRAMA_DETALLE!$F$4:$F$503,PROGRAMA_DETALLE!$A$4:$A$503,A18),0) -> 0 | M18: =IF(A18="","",IFERROR(SUMIFS(COMPRAS_HILO!$D$4:$D$203,COMPRAS_HILO!$B$4:$B$203,A18),0)) | N18: =IF(A18="","",IFERROR(SUMIFS(COMPRAS_HILO!$H$4:$H$203,COMPRAS_HILO!$B$4:$B$203,A18),0)) | O18: =IFERROR(IF(SUMPRODUCT((COMPRAS_HILO!$B$4:$B$203=A18)*1)=0,"",LOOKUP(2,1/((COMPRAS_HILO!$B$4:$B$203=A18)*(COMPRAS_HILO!$J$4:$J$203<>"")),COMPRAS_HILO!$J$4:$J$203)),"") | Q18: =IF(A18="","",IFERROR(SUMIFS(PROGRAMA_DETALLE!$H$4:$H$503,PROGRAMA_DETALLE!$A$4:$A$503,A18),0)) | R18: =IF(A18="","",IFERROR(SUMIFS(PROGRAMA_DETALLE!$I$4:$I$503,PROGRAMA_DETALLE!$A$4:$A$503,A18),0)) | T18: =IFERROR(Q18-R18-S18,0) -> 0 | U18: =IFERROR(T18/Q18,0) -> 0 | V18: =IF(A18="","",IFERROR(SUMIFS(PROGRAMA_DETALLE!$R$4:$R$503,PROGRAMA_DETALLE!$A$4:$A$503,A18),0)) | W18: =IF(A18="","",IFERROR(SUMIFS(PROGRAMA_DETALLE!$S$4:$S$503,PROGRAMA_DETALLE!$A$4:$A$503,A18),0)) | X18: =IFERROR(V18-W18,0) -> 0 | Y18: =IFERROR(X18/V18,0) -> 0 | Z18: =IFERROR(Q18-W18-S18,0) -> 0 | AA18: =IFERROR(Z18/Q18,0) -> 0 | AB18: =IFERROR(W18*DASHBOARD!$C$2,0) -> 0 | AE18: =IFERROR(N18+IFERROR(SUMIFS(PROGRAMA_DETALLE!$M$4:$M$503,PROGRAMA_DETALLE!$A$4:$A$503,A18),0)+IFERROR(SUMIFS(PROGRAMA_DETALLE!$Z$4:$Z$503,PROGRAMA_DETALLE!$A$4:$A$503,A18),0)+AB18,0) -> 0 | AF18: =IFERROR(AE18/W18,0) -> 0 | AG18: =IFERROR(AD18-B18,"") -> 0
K19: =IFERROR(SUMIFS(PROGRAMA_DETALLE!$E$4:$E$503,PROGRAMA_DETALLE!$A$4:$A$503,A19),0) -> 0 | L19: =IFERROR(SUMIFS(PROGRAMA_DETALLE!$F$4:$F$503,PROGRAMA_DETALLE!$A$4:$A$503,A19),0) -> 0 | M19: =IF(A19="","",IFERROR(SUMIFS(COMPRAS_HILO!$D$4:$D$203,COMPRAS_HILO!$B$4:$B$203,A19),0)) | N19: =IF(A19="","",IFERROR(SUMIFS(COMPRAS_HILO!$H$4:$H$203,COMPRAS_HILO!$B$4:$B$203,A19),0)) | O19: =IFERROR(IF(SUMPRODUCT((COMPRAS_HILO!$B$4:$B$203=A19)*1)=0,"",LOOKUP(2,1/((COMPRAS_HILO!$B$4:$B$203=A19)*(COMPRAS_HILO!$J$4:$J$203<>"")),COMPRAS_HILO!$J$4:$J$203)),"") | Q19: =IF(A19="","",IFERROR(SUMIFS(PROGRAMA_DETALLE!$H$4:$H$503,PROGRAMA_DETALLE!$A$4:$A$503,A19),0)) | R19: =IF(A19="","",IFERROR(SUMIFS(PROGRAMA_DETALLE!$I$4:$I$503,PROGRAMA_DETALLE!$A$4:$A$503,A19),0)) | T19: =IFERROR(Q19-R19-S19,0) -> 0 | U19: =IFERROR(T19/Q19,0) -> 0 | V19: =IF(A19="","",IFERROR(SUMIFS(PROGRAMA_DETALLE!$R$4:$R$503,PROGRAMA_DETALLE!$A$4:$A$503,A19),0)) | W19: =IF(A19="","",IFERROR(SUMIFS(PROGRAMA_DETALLE!$S$4:$S$503,PROGRAMA_DETALLE!$A$4:$A$503,A19),0)) | X19: =IFERROR(V19-W19,0) -> 0 | Y19: =IFERROR(X19/V19,0) -> 0 | Z19: =IFERROR(Q19-W19-S19,0) -> 0 | AA19: =IFERROR(Z19/Q19,0) -> 0 | AB19: =IFERROR(W19*DASHBOARD!$C$2,0) -> 0 | AE19: =IFERROR(N19+IFERROR(SUMIFS(PROGRAMA_DETALLE!$M$4:$M$503,PROGRAMA_DETALLE!$A$4:$A$503,A19),0)+IFERROR(SUMIFS(PROGRAMA_DETALLE!$Z$4:$Z$503,PROGRAMA_DETALLE!$A$4:$A$503,A19),0)+AB19,0) -> 0 | AF19: =IFERROR(AE19/W19,0) -> 0 | AG19: =IFERROR(AD19-B19,"") -> 0
K20: =IFERROR(SUMIFS(PROGRAMA_DETALLE!$E$4:$E$503,PROGRAMA_DETALLE!$A$4:$A$503,A20),0) -> 0 | L20: =IFERROR(SUMIFS(PROGRAMA_DETALLE!$F$4:$F$503,PROGRAMA_DETALLE!$A$4:$A$503,A20),0) -> 0 | M20: =IF(A20="","",IFERROR(SUMIFS(COMPRAS_HILO!$D$4:$D$203,COMPRAS_HILO!$B$4:$B$203,A20),0)) | N20: =IF(A20="","",IFERROR(SUMIFS(COMPRAS_HILO!$H$4:$H$203,COMPRAS_HILO!$B$4:$B$203,A20),0)) | O20: =IFERROR(IF(SUMPRODUCT((COMPRAS_HILO!$B$4:$B$203=A20)*1)=0,"",LOOKUP(2,1/((COMPRAS_HILO!$B$4:$B$203=A20)*(COMPRAS_HILO!$J$4:$J$203<>"")),COMPRAS_HILO!$J$4:$J$203)),"") | Q20: =IF(A20="","",IFERROR(SUMIFS(PROGRAMA_DETALLE!$H$4:$H$503,PROGRAMA_DETALLE!$A$4:$A$503,A20),0)) | R20: =IF(A20="","",IFERROR(SUMIFS(PROGRAMA_DETALLE!$I$4:$I$503,PROGRAMA_DETALLE!$A$4:$A$503,A20),0)) | T20: =IFERROR(Q20-R20-S20,0) -> 0 | U20: =IFERROR(T20/Q20,0) -> 0 | V20: =IF(A20="","",IFERROR(SUMIFS(PROGRAMA_DETALLE!$R$4:$R$503,PROGRAMA_DETALLE!$A$4:$A$503,A20),0)) | W20: =IF(A20="","",IFERROR(SUMIFS(PROGRAMA_DETALLE!$S$4:$S$503,PROGRAMA_DETALLE!$A$4:$A$503,A20),0)) | X20: =IFERROR(V20-W20,0) -> 0 | Y20: =IFERROR(X20/V20,0) -> 0 | Z20: =IFERROR(Q20-W20-S20,0) -> 0 | AA20: =IFERROR(Z20/Q20,0) -> 0 | AB20: =IFERROR(W20*DASHBOARD!$C$2,0) -> 0 | AE20: =IFERROR(N20+IFERROR(SUMIFS(PROGRAMA_DETALLE!$M$4:$M$503,PROGRAMA_DETALLE!$A$4:$A$503,A20),0)+IFERROR(SUMIFS(PROGRAMA_DETALLE!$Z$4:$Z$503,PROGRAMA_DETALLE!$A$4:$A$503,A20),0)+AB20,0) -> 0 | AF20: =IFERROR(AE20/W20,0) -> 0 | AG20: =IFERROR(AD20-B20,"") -> 0
... K103: =IFERROR(SUMIFS(PROGRAMA_DETALLE!$E$4:$E$503,PROGRAMA_DETALLE!$A$4:$A$503,A103),0) -> 0 | L103: =IFERROR(SUMIFS(PROGRAMA_DETALLE!$F$4:$F$503,PROGRAMA_DETALLE!$A$4:$A$503,A103),0) -> 0 | M103: =IF(A103="","",IFERROR(SUMIFS(COMPRAS_HILO!$D$4:$D$203,COMPRAS_HILO!$B$4:$B$203,A103),0)) | N103: =IF(A103="","",IFERROR(SUMIFS(COMPRAS_HILO!$H$4:$H$203,COMPRAS_HILO!$B$4:$B$203,A103),0)) | O103: =IFERROR(IF(SUMPRODUCT((COMPRAS_HILO!$B$4:$B$203=A103)*1)=0,"",LOOKUP(2,1/((COMPRAS_HILO!$B$4:$B$203=A103)*(COMPRAS_HILO!$J$4:$J$203<>"")),COMPRAS_HILO!$J$4:$J$203)),"") | Q103: =IF(A103="","",IFERROR(SUMIFS(PROGRAMA_DETALLE!$H$4:$H$503,PROGRAMA_DETALLE!$A$4:$A$503,A103),0)) | R103: =IF(A103="","",IFERROR(SUMIFS(PROGRAMA_DETALLE!$I$4:$I$503,PROGRAMA_DETALLE!$A$4:$A$503,A103),0)) | T103: =IFERROR(Q103-R103-S103,0) -> 0 | U103: =IFERROR(T103/Q103,0) -> 0 | V103: =IF(A103="","",IFERROR(SUMIFS(PROGRAMA_DETALLE!$R$4:$R$503,PROGRAMA_DETALLE!$A$4:$A$503,A103),0)) | W103: =IF(A103="","",IFERROR(SUMIFS(PROGRAMA_DETALLE!$S$4:$S$503,PROGRAMA_DETALLE!$A$4:$A$503,A103),0)) | X103: =IFERROR(V103-W103,0) -> 0 | Y103: =IFERROR(X103/V103,0) -> 0 | Z103: =IFERROR(Q103-W103-S103,0) -> 0 | AA103: =IFERROR(Z103/Q103,0) -> 0 | AB103: =IFERROR(W103*DASHBOARD!$C$2,0) -> 0 | AE103: =IFERROR(N103+IFERROR(SUMIFS(PROGRAMA_DETALLE!$M$4:$M$503,PROGRAMA_DETALLE!$A$4:$A$503,A103),0)+IFERROR(SUMIFS(PROGRAMA_DETALLE!$Z$4:$Z$503,PROGRAMA_DETALLE!$A$4:$A$503,A103),0)+AB103,0) -> 0 | AF103: =IFERROR(AE103/W103,0) -> 0 | AG103: =IFERROR(AD103-B103,"") -> 0

Sheet COMPRAS_HILO
A1: COMPRAS DE HILO — Asignaciones de factura a programas + estado pago
A2: 1 fila = asignación de factura a un programa. Para USD pon MONEDA=USD y TC. ESTADO PAGO permite control contable: PAGADO/PENDIENTE/PARCIAL/ANULADO.
A3: FECHA | B3: PROGRAMA | C3: TIPO HILO | D3: KG ASIGNADOS | E3: PRECIO/KG | F3: MONEDA | G3: TC | H3: TOTAL S/. | I3: PROVEEDOR | J3: N° FACTURA | K3: COSTO REAL FACT. | L3: DIFERENCIA | M3: ESTADO PAGO | N3: FECHA PAGO | O3: MONTO PAGADO S/. | P3: SALDO S/. | Q3: NOTAS
A4: 46113 | B4: PIQUE-001 | C4: Hilo 30/1 PC | D4: 1000 | E4: 3 | F4: USD | G4: 3.5 | H4: =IFERROR(D4*E4*IF(F4="USD",G4,1),0) -> 10500 | I4: COTTON MIX | J4: COTTOON-001 | K4: 10500 | L4: =IFERROR(K4-H4,0) -> 0 | M4: PAGADO | N4: 46113 | O4: 10500 | P4: =IFERROR(H4-O4,0) -> 0
A5: 46152 | B5: FULL LYCRA 50/1-001 | C5: hilo 50/1 cotton +lycra 4% | D5: 500 | E5: 5.5 | F5: USD | G5: 3.5 | H5: =IFERROR(D5*E5*IF(F5="USD",G5,1),0) -> 9625 | I5: COTTON MIX | J5: f002-4472 | K5: 9625 | L5: =IFERROR(K5-H5,0) -> 0 | M5: PAGADO | N5: 46152 | O5: 9525 | P5: =IFERROR(H5-O5,0) -> 100
B6: frecnh terry - 001 | C6: Hilo 30/1 PC | D6: 3000 | E6: 3 | F6: USD | G6: 3.45 | H6: =IFERROR(D6*E6*IF(F6="USD",G6,1),0) -> 31050 | I6: COTTON MIX | K6: 31050 | L6: =IFERROR(K6-H6,0) -> 0 | M6: PAGADO | P6: =IFERROR(H6-O6,0) -> 31050
B7: jersey algodon - 001 | C7: Hilo 30/1 ALGODON | D7: 660 | E7: 4 | F7: USD | G7: 3.45 | H7: =IFERROR(D7*E7*IF(F7="USD",G7,1),0) -> 9108 | I7: COTTON MIX | K7: 9108 | L7: =IFERROR(K7-H7,0) -> 0 | M7: PAGADO | P7: =IFERROR(H7-O7,0) -> 9108
H8: =IFERROR(D8*E8*IF(F8="USD",G8,1),0) -> 0 | L8: =IFERROR(K8-H8,0) -> 0 | P8: =IFERROR(H8-O8,0) -> 0
H9: =IFERROR(D9*E9*IF(F9="USD",G9,1),0) -> 0 | L9: =IFERROR(K9-H9,0) -> 0 | P9: =IFERROR(H9-O9,0) -> 0
H10: =IFERROR(D10*E10*IF(F10="USD",G10,1),0) -> 0 | L10: =IFERROR(K10-H10,0) -> 0 | P10: =IFERROR(H10-O10,0) -> 0
H11: =IFERROR(D11*E11*IF(F11="USD",G11,1),0) -> 0 | L11: =IFERROR(K11-H11,0) -> 0 | P11: =IFERROR(H11-O11,0) -> 0
H12: =IFERROR(D12*E12*IF(F12="USD",G12,1),0) -> 0 | L12: =IFERROR(K12-H12,0) -> 0 | P12: =IFERROR(H12-O12,0) -> 0
H13: =IFERROR(D13*E13*IF(F13="USD",G13,1),0) -> 0 | L13: =IFERROR(K13-H13,0) -> 0 | P13: =IFERROR(H13-O13,0) -> 0
H14: =IFERROR(D14*E14*IF(F14="USD",G14,1),0) -> 0 | L14: =IFERROR(K14-H14,0) -> 0 | P14: =IFERROR(H14-O14,0) -> 0
H15: =IFERROR(D15*E15*IF(F15="USD",G15,1),0) -> 0 | L15: =IFERROR(K15-H15,0) -> 0 | P15: =IFERROR(H15-O15,0) -> 0
H16: =IFERROR(D16*E16*IF(F16="USD",G16,1),0) -> 0 | L16: =IFERROR(K16-H16,0) -> 0 | P16: =IFERROR(H16-O16,0) -> 0
H17: =IFERROR(D17*E17*IF(F17="USD",G17,1),0) -> 0 | L17: =IFERROR(K17-H17,0) -> 0 | P17: =IFERROR(H17-O17,0) -> 0
H18: =IFERROR(D18*E18*IF(F18="USD",G18,1),0) -> 0 | L18: =IFERROR(K18-H18,0) -> 0 | P18: =IFERROR(H18-O18,0) -> 0
H19: =IFERROR(D19*E19*IF(F19="USD",G19,1),0) -> 0 | L19: =IFERROR(K19-H19,0) -> 0 | P19: =IFERROR(H19-O19,0) -> 0
... H203: =IFERROR(D203*E203*IF(F203="USD",G203,1),0) -> 0 | L203: =IFERROR(K203-H203,0) -> 0 | P203: =IFERROR(H203-O203,0) -> 0

Sheet PROGRAMA_DETALLE
A1: PROGRAMA DETALLE — Plan + Tejeduría + Tintorería + Costos por color
A2: 1 fila = 1 color de un programa. Precio tej y tint salen automáticos del catálogo. Llenas: KG enviado/retornado, factura, guía, pago, fecha tint, moneda/TC.
A3: ID PROGRAMA | B3: COLOR | C3: CATEG. | D3: TIPO SERVICIO | E3: ROLLOS PLAN | F3: KG PLAN | G3: PRIORIDAD | H3: KG TEJ ENVIADO | I3: KG TEJ RETORNADO | J3: PRECIO/KG TEJ (auto) | K3: MONEDA TEJ | L3: TC TEJ | M3: TOTAL TEJ (auto) | N3: FACTURA TEJ | O3: GUÍA TEJ | P3: ESTADO PAGO TEJ | Q3: FECHA ENVÍO TINT | R3: KG ENVIADO TINT | S3: KG RETORNADO TINT | T3: ROLLOS FINAL | U3: KG MERMA TINT | V3: % MERMA TINT | W3: PRECIO/KG TINT (auto) | X3: MONEDA TINT | Y3: TC TINT | Z3: COSTO TINT (auto) | AA3: GUÍA TRASLADO TINT | AB3: FACTURA TINT | AC3: ESTADO PAGO TINT | AD3: COSTO HILO (prorr.) | AE3: COSTO TEJ COLOR | AF3: COSTO TINT COLOR | AG3: COSTO TOTAL COLOR | AH3: COSTO/KG COLOR | AI3: NOTAS
A4: PIQUE-001 | B4: Negro | C4: =IFERROR(VLOOKUP(B4,COLORES!$A$4:$B$52,2,FALSE()),"") -> OSCURO | D4: REACTIVO (oscuros) | E4: 20 | F4: 400 | G4: URGENTE | H4: 400 | I4: 395 | J4: =IFERROR(VLOOKUP(VLOOKUP(A4,PROGRAMAS!$A$4:$G$103,7,FALSE()),PRECIOS_TEJEDURIA!$A$4:$B$22,2,FALSE()),0) -> 0.5 | K4: USD | L4: 3.55 | M4: =IFERROR(H4*J4*IF(K4="USD",L4,1),0) -> 710 | N4: TEJ-001 | O4: TEJ-001 | P4: PAGADO | Q4: 46114 | R4: 395 | S4: 380 | T4: 20 | U4: =IFERROR(R4-S4,0) -> 15 | V4: =IFERROR(U4/R4,0) -> 0.037974684 | W4: {=IFERROR(INDEX(PRECIOS_TINTORERIA!$B$4:$U$15,MATCH(D4,PRECIOS_TINTORERIA!$A$4:$A$15,0),MATCH(VLOOKUP(A4,PROGRAMAS!$A$4:$G$103,7,FALSE()),PRECIOS_TINTORERIA!$B$3:$U$3,0)),0)} -> 2.7 | X4: USD | Y4: 3.55 | Z4: =IFERROR(R4*W4*IF(X4="USD",Y4,1),0) -> 3786.075 | AA4: TIN-001 | AB4: TIN-001 | AC4: PAGADO | AD4: =IFERROR((SUMIFS(COMPRAS_HILO!$H$4:$H$203,COMPRAS_HILO!$B$4:$B$203,A4))*F4/SUMIFS($F$4:$F$503,$A$4:$A$503,A4),0) -> 4200 | AE4: =M4 -> 710 | AF4: =Z4 -> 3786.075 | AG4: =AD4+AE4+AF4 -> 8696.075 | AH4: =IFERROR(AG4/S4,0) -> 22.884408
A5: PIQUE-001 | B5: Perla | C5: =IFERROR(VLOOKUP(B5,COLORES!$A$4:$B$52,2,FALSE()),"") -> PPT | D5: PPT (perla/blanco) | E5: 10 | F5: 200 | G5: MEDIA | H5: 200 | I5: 195 | J5: =IFERROR(VLOOKUP(VLOOKUP(A5,PROGRAMAS!$A$4:$G$103,7,FALSE()),PRECIOS_TEJEDURIA!$A$4:$B$22,2,FALSE()),0) -> 0.5 | K5: USD | L5: 3.55 | M5: =IFERROR(H5*J5*IF(K5="USD",L5,1),0) -> 355 | N5: TEJ-002 | O5: TEJ-002 | P5: PAGADO | Q5: 46114 | R5: 195 | S5: 170 | T5: 10 | U5: =IFERROR(R5-S5,0) -> 25 | V5: =IFERROR(U5/R5,0) -> 0.12820513 | W5: {=IFERROR(INDEX(PRECIOS_TINTORERIA!$B$4:$U$15,MATCH(D5,PRECIOS_TINTORERIA!$A$4:$A$15,0),MATCH(VLOOKUP(A5,PROGRAMAS!$A$4:$G$103,7,FALSE()),PRECIOS_TINTORERIA!$B$3:$U$3,0)),0)} -> 1.1 | X5: USD | Y5: 3.55 | Z5: =IFERROR(R5*W5*IF(X5="USD",Y5,1),0) -> 761.475 | AA5: TIN-002 | AB5: TIN-002 | AC5: PAGADO | AD5: =IFERROR((SUMIFS(COMPRAS_HILO!$H$4:$H$203,COMPRAS_HILO!$B$4:$B$203,A5))*F5/SUMIFS($F$4:$F$503,$A$4:$A$503,A5),0) -> 2100 | AE5: =M5 -> 355 | AF5: =Z5 -> 761.475 | AG5: =AD5+AE5+AF5 -> 3216.475 | AH5: =IFERROR(AG5/S5,0) -> 18.920441
A6: PIQUE-001 | B6: Beige | C6: =IFERROR(VLOOKUP(B6,COLORES!$A$4:$B$52,2,FALSE()),"") -> CLARO | D6: DIRECTO (claros) | E6: 10 | F6: 200 | G6: ALTA | H6: 200 | I6: 195 | J6: =IFERROR(VLOOKUP(VLOOKUP(A6,PROGRAMAS!$A$4:$G$103,7,FALSE()),PRECIOS_TEJEDURIA!$A$4:$B$22,2,FALSE()),0) -> 0.5 | K6: USD | L6: 3.55 | M6: =IFERROR(H6*J6*IF(K6="USD",L6,1),0) -> 355 | N6: TEJ-003 | O6: TEJ-003 | P6: PAGADO | Q6: 46114 | R6: 195 | S6: 170 | T6: 10 | U6: =IFERROR(R6-S6,0) -> 25 | V6: =IFERROR(U6/R6,0) -> 0.12820513 | W6: {=IFERROR(INDEX(PRECIOS_TINTORERIA!$B$4:$U$15,MATCH(D6,PRECIOS_TINTORERIA!$A$4:$A$15,0),MATCH(VLOOKUP(A6,PROGRAMAS!$A$4:$G$103,7,FALSE()),PRECIOS_TINTORERIA!$B$3:$U$3,0)),0)} -> 1.95 | X6: USD | Y6: 3.5 | Z6: =IFERROR(R6*W6*IF(X6="USD",Y6,1),0) -> 1330.875 | AA6: TIN-003 | AB6: TIN-003 | AC6: PAGADO | AD6: =IFERROR((SUMIFS(COMPRAS_HILO!$H$4:$H$203,COMPRAS_HILO!$B$4:$B$203,A6))*F6/SUMIFS($F$4:$F$503,$A$4:$A$503,A6),0) -> 2100 | AE6: =M6 -> 355 | AF6: =Z6 -> 1330.875 | AG6: =AD6+AE6+AF6 -> 3785.875 | AH6: =IFERROR(AG6/S6,0) -> 22.269853
A7: PIQUE-001 | B7: Melange | C7: =IFERROR(VLOOKUP(B7,COLORES!$A$4:$B$52,2,FALSE()),"") -> MELANGE | D7: LAVADO (melange) | E7: 10 | F7: 200 | G7: OPCIONAL | H7: 200 | I7: 195 | J7: =IFERROR(VLOOKUP(VLOOKUP(A7,PROGRAMAS!$A$4:$G$103,7,FALSE()),PRECIOS_TEJEDURIA!$A$4:$B$22,2,FALSE()),0) -> 0.5 | K7: USD | L7: 3.55 | M7: =IFERROR(H7*J7*IF(K7="USD",L7,1),0) -> 355 | N7: TEJ-004 | O7: TEJ-004 | P7: PAGADO | Q7: 46114 | R7: 195 | S7: 170 | T7: 10 | U7: =IFERROR(R7-S7,0) -> 25 | V7: =IFERROR(U7/R7,0) -> 0.12820513 | W7: {=IFERROR(INDEX(PRECIOS_TINTORERIA!$B$4:$U$15,MATCH(D7,PRECIOS_TINTORERIA!$A$4:$A$15,0),MATCH(VLOOKUP(A7,PROGRAMAS!$A$4:$G$103,7,FALSE()),PRECIOS_TINTORERIA!$B$3:$U$3,0)),0)} -> 1.1 | X7: USD | Y7: 3.5 | Z7: =IFERROR(R7*W7*IF(X7="USD",Y7,1),0) -> 750.75 | AA7: TIN-004 | AB7: TIN-004 | AC7: PAGADO | AD7: =IFERROR((SUMIFS(COMPRAS_HILO!$H$4:$H$203,COMPRAS_HILO!$B$4:$B$203,A7))*F7/SUMIFS($F$4:$F$503,$A$4:$A$503,A7),0) -> 2100 | AE7: =M7 -> 355 | AF7: =Z7 -> 750.75 | AG7: =AD7+AE7+AF7 -> 3205.75 | AH7: =IFERROR(AG7/S7,0) -> 18.857353
C8: =IFERROR(VLOOKUP(B8,COLORES!$A$4:$B$52,2,FALSE()),"") | J8: =IFERROR(VLOOKUP(VLOOKUP(A8,PROGRAMAS!$A$4:$G$103,7,FALSE()),PRECIOS_TEJEDURIA!$A$4:$B$22,2,FALSE()),0) -> 0 | M8: =IFERROR(H8*J8*IF(K8="USD",L8,1),0) -> 0 | U8: =IFERROR(R8-S8,0) -> 0 | V8: =IFERROR(U8/R8,0) -> 0 | W8: {=IFERROR(INDEX(PRECIOS_TINTORERIA!$B$4:$U$15,MATCH(D8,PRECIOS_TINTORERIA!$A$4:$A$15,0),MATCH(VLOOKUP(A8,PROGRAMAS!$A$4:$G$103,7,FALSE()),PRECIOS_TINTORERIA!$B$3:$U$3,0)),0)} -> 0 | Z8: =IFERROR(R8*W8*IF(X8="USD",Y8,1),0) -> 0 | AD8: =IFERROR((SUMIFS(COMPRAS_HILO!$H$4:$H$203,COMPRAS_HILO!$B$4:$B$203,A8))*F8/SUMIFS($F$4:$F$503,$A$4:$A$503,A8),0) -> 0 | AE8: =M8 -> 0 | AF8: =Z8 -> 0 | AG8: =AD8+AE8+AF8 -> 0 | AH8: =IFERROR(AG8/S8,0) -> 0
C9: =IFERROR(VLOOKUP(B9,COLORES!$A$4:$B$52,2,FALSE()),"") | J9: =IFERROR(VLOOKUP(VLOOKUP(A9,PROGRAMAS!$A$4:$G$103,7,FALSE()),PRECIOS_TEJEDURIA!$A$4:$B$22,2,FALSE()),0) -> 0 | M9: =IFERROR(H9*J9*IF(K9="USD",L9,1),0) -> 0 | U9: =IFERROR(R9-S9,0) -> 0 | V9: =IFERROR(U9/R9,0) -> 0 | W9: {=IFERROR(INDEX(PRECIOS_TINTORERIA!$B$4:$U$15,MATCH(D9,PRECIOS_TINTORERIA!$A$4:$A$15,0),MATCH(VLOOKUP(A9,PROGRAMAS!$A$4:$G$103,7,FALSE()),PRECIOS_TINTORERIA!$B$3:$U$3,0)),0)} -> 0 | Z9: =IFERROR(R9*W9*IF(X9="USD",Y9,1),0) -> 0 | AD9: =IFERROR((SUMIFS(COMPRAS_HILO!$H$4:$H$203,COMPRAS_HILO!$B$4:$B$203,A9))*F9/SUMIFS($F$4:$F$503,$A$4:$A$503,A9),0) -> 0 | AE9: =M9 -> 0 | AF9: =Z9 -> 0 | AG9: =AD9+AE9+AF9 -> 0 | AH9: =IFERROR(AG9/S9,0) -> 0
A10: FULL LYCRA 50/1-001 | B10: Negro | C10: =IFERROR(VLOOKUP(B10,COLORES!$A$4:$B$52,2,FALSE()),"") -> OSCURO | D10: REACTIVO (oscuros) | E10: 8 | F10: 160 | G10: MEDIA | H10: 160 | J10: =IFERROR(VLOOKUP(VLOOKUP(A10,PROGRAMAS!$A$4:$G$103,7,FALSE()),PRECIOS_TEJEDURIA!$A$4:$B$22,2,FALSE()),0) -> 0.7 | K10: USD | M10: =IFERROR(H10*J10*IF(K10="USD",L10,1),0) -> 0 | U10: =IFERROR(R10-S10,0) -> 0 | V10: =IFERROR(U10/R10,0) -> 0 | W10: {=IFERROR(INDEX(PRECIOS_TINTORERIA!$B$4:$U$15,MATCH(D10,PRECIOS_TINTORERIA!$A$4:$A$15,0),MATCH(VLOOKUP(A10,PROGRAMAS!$A$4:$G$103,7,FALSE()),PRECIOS_TINTORERIA!$B$3:$U$3,0)),0)} -> 0 | Z10: =IFERROR(R10*W10*IF(X10="USD",Y10,1),0) -> 0 | AD10: =IFERROR((SUMIFS(COMPRAS_HILO!$H$4:$H$203,COMPRAS_HILO!$B$4:$B$203,A10))*F10/SUMIFS($F$4:$F$503,$A$4:$A$503,A10),0) -> 3080 | AE10: =M10 -> 0 | AF10: =Z10 -> 0 | AG10: =AD10+AE10+AF10 -> 3080 | AH10: =IFERROR(AG10/S10,0) -> 0
A11: FULL LYCRA 50/1-001 | B11: Perla | C11: =IFERROR(VLOOKUP(B11,COLORES!$A$4:$B$52,2,FALSE()),"") -> PPT | D11: PPT (perla/blanco) | E11: 9 | F11: 180 | G11: MEDIA | H11: 180 | J11: =IFERROR(VLOOKUP(VLOOKUP(A11,PROGRAMAS!$A$4:$G$103,7,FALSE()),PRECIOS_TEJEDURIA!$A$4:$B$22,2,FALSE()),0) -> 0.7 | K11: USD | M11: =IFERROR(H11*J11*IF(K11="USD",L11,1),0) -> 0 | U11: =IFERROR(R11-S11,0) -> 0 | V11: =IFERROR(U11/R11,0) -> 0 | W11: {=IFERROR(INDEX(PRECIOS_TINTORERIA!$B$4:$U$15,MATCH(D11,PRECIOS_TINTORERIA!$A$4:$A$15,0),MATCH(VLOOKUP(A11,PROGRAMAS!$A$4:$G$103,7,FALSE()),PRECIOS_TINTORERIA!$B$3:$U$3,0)),0)} -> 0 | Z11: =IFERROR(R11*W11*IF(X11="USD",Y11,1),0) -> 0 | AD11: =IFERROR((SUMIFS(COMPRAS_HILO!$H$4:$H$203,COMPRAS_HILO!$B$4:$B$203,A11))*F11/SUMIFS($F$4:$F$503,$A$4:$A$503,A11),0) -> 3465 | AE11: =M11 -> 0 | AF11: =Z11 -> 0 | AG11: =AD11+AE11+AF11 -> 3465 | AH11: =IFERROR(AG11/S11,0) -> 0
A12: FULL LYCRA 50/1-001 | B12: Colegial | C12: =IFERROR(VLOOKUP(B12,COLORES!$A$4:$B$52,2,FALSE()),"") -> OSCURO | D12: REACTIVO (oscuros) | E12: 8 | F12: 160 | G12: MEDIA | H12: 160 | J12: =IFERROR(VLOOKUP(VLOOKUP(A12,PROGRAMAS!$A$4:$G$103,7,FALSE()),PRECIOS_TEJEDURIA!$A$4:$B$22,2,FALSE()),0) -> 0.7 | K12: USD | M12: =IFERROR(H12*J12*IF(K12="USD",L12,1),0) -> 0 | U12: =IFERROR(R12-S12,0) -> 0 | V12: =IFERROR(U12/R12,0) -> 0 | W12: {=IFERROR(INDEX(PRECIOS_TINTORERIA!$B$4:$U$15,MATCH(D12,PRECIOS_TINTORERIA!$A$4:$A$15,0),MATCH(VLOOKUP(A12,PROGRAMAS!$A$4:$G$103,7,FALSE()),PRECIOS_TINTORERIA!$B$3:$U$3,0)),0)} -> 0 | Z12: =IFERROR(R12*W12*IF(X12="USD",Y12,1),0) -> 0 | AD12: =IFERROR((SUMIFS(COMPRAS_HILO!$H$4:$H$203,COMPRAS_HILO!$B$4:$B$203,A12))*F12/SUMIFS($F$4:$F$503,$A$4:$A$503,A12),0) -> 3080 | AE12: =M12 -> 0 | AF12: =Z12 -> 0 | AG12: =AD12+AE12+AF12 -> 3080 | AH12: =IFERROR(AG12/S12,0) -> 0
C13: =IFERROR(VLOOKUP(B13,COLORES!$A$4:$B$52,2,FALSE()),"") | J13: =IFERROR(VLOOKUP(VLOOKUP(A13,PROGRAMAS!$A$4:$G$103,7,FALSE()),PRECIOS_TEJEDURIA!$A$4:$B$22,2,FALSE()),0) -> 0 | M13: =IFERROR(H13*J13*IF(K13="USD",L13,1),0) -> 0 | U13: =IFERROR(R13-S13,0) -> 0 | V13: =IFERROR(U13/R13,0) -> 0 | W13: {=IFERROR(INDEX(PRECIOS_TINTORERIA!$B$4:$U$15,MATCH(D13,PRECIOS_TINTORERIA!$A$4:$A$15,0),MATCH(VLOOKUP(A13,PROGRAMAS!$A$4:$G$103,7,FALSE()),PRECIOS_TINTORERIA!$B$3:$U$3,0)),0)} -> 0 | Z13: =IFERROR(R13*W13*IF(X13="USD",Y13,1),0) -> 0 | AD13: =IFERROR((SUMIFS(COMPRAS_HILO!$H$4:$H$203,COMPRAS_HILO!$B$4:$B$203,A13))*F13/SUMIFS($F$4:$F$503,$A$4:$A$503,A13),0) -> 0 | AE13: =M13 -> 0 | AF13: =Z13 -> 0 | AG13: =AD13+AE13+AF13 -> 0 | AH13: =IFERROR(AG13/S13,0) -> 0
A14: frecnh terry - 001 | B14: Negro | C14: =IFERROR(VLOOKUP(B14,COLORES!$A$4:$B$52,2,FALSE()),"") -> OSCURO | D14: REACTIVO (oscuros) | E14: 40 | F14: 800 | G14: ALTA | J14: =IFERROR(VLOOKUP(VLOOKUP(A14,PROGRAMAS!$A$4:$G$103,7,FALSE()),PRECIOS_TEJEDURIA!$A$4:$B$22,2,FALSE()),0) -> 0.4 | M14: =IFERROR(H14*J14*IF(K14="USD",L14,1),0) -> 0 | U14: =IFERROR(R14-S14,0) -> 0 | V14: =IFERROR(U14/R14,0) -> 0 | W14: {=IFERROR(INDEX(PRECIOS_TINTORERIA!$B$4:$U$15,MATCH(D14,PRECIOS_TINTORERIA!$A$4:$A$15,0),MATCH(VLOOKUP(A14,PROGRAMAS!$A$4:$G$103,7,FALSE()),PRECIOS_TINTORERIA!$B$3:$U$3,0)),0)} -> 0 | Z14: =IFERROR(R14*W14*IF(X14="USD",Y14,1),0) -> 0 | AD14: =IFERROR((SUMIFS(COMPRAS_HILO!$H$4:$H$203,COMPRAS_HILO!$B$4:$B$203,A14))*F14/SUMIFS($F$4:$F$503,$A$4:$A$503,A14),0) -> 8565.5172 | AE14: =M14 -> 0 | AF14: =Z14 -> 0 | AG14: =AD14+AE14+AF14 -> 8565.5172 | AH14: =IFERROR(AG14/S14,0) -> 0
A15: frecnh terry - 001 | B15: Perla | C15: =IFERROR(VLOOKUP(B15,COLORES!$A$4:$B$52,2,FALSE()),"") -> PPT | D15: PPT (perla/blanco) | E15: 10 | F15: 200 | G15: BAJA | J15: =IFERROR(VLOOKUP(VLOOKUP(A15,PROGRAMAS!$A$4:$G$103,7,FALSE()),PRECIOS_TEJEDURIA!$A$4:$B$22,2,FALSE()),0) -> 0.4 | M15: =IFERROR(H15*J15*IF(K15="USD",L15,1),0) -> 0 | U15: =IFERROR(R15-S15,0) -> 0 | V15: =IFERROR(U15/R15,0) -> 0 | W15: {=IFERROR(INDEX(PRECIOS_TINTORERIA!$B$4:$U$15,MATCH(D15,PRECIOS_TINTORERIA!$A$4:$A$15,0),MATCH(VLOOKUP(A15,PROGRAMAS!$A$4:$G$103,7,FALSE()),PRECIOS_TINTORERIA!$B$3:$U$3,0)),0)} -> 0 | Z15: =IFERROR(R15*W15*IF(X15="USD",Y15,1),0) -> 0 | AD15: =IFERROR((SUMIFS(COMPRAS_HILO!$H$4:$H$203,COMPRAS_HILO!$B$4:$B$203,A15))*F15/SUMIFS($F$4:$F$503,$A$4:$A$503,A15),0) -> 2141.3793 | AE15: =M15 -> 0 | AF15: =Z15 -> 0 | AG15: =AD15+AE15+AF15 -> 2141.3793 | AH15: =IFERROR(AG15/S15,0) -> 0
A16: frecnh terry - 001 | B16: Azul Marino | C16: =IFERROR(VLOOKUP(B16,COLORES!$A$4:$B$52,2,FALSE()),"") -> OSCURO | D16: REACTIVO (oscuros) | E16: 25 | F16: 500 | G16: ALTA | J16: =IFERROR(VLOOKUP(VLOOKUP(A16,PROGRAMAS!$A$4:$G$103,7,FALSE()),PRECIOS_TEJEDURIA!$A$4:$B$22,2,FALSE()),0) -> 0.4 | M16: =IFERROR(H16*J16*IF(K16="USD",L16,1),0) -> 0 | U16: =IFERROR(R16-S16,0) -> 0 | V16: =IFERROR(U16/R16,0) -> 0 | W16: {=IFERROR(INDEX(PRECIOS_TINTORERIA!$B$4:$U$15,MATCH(D16,PRECIOS_TINTORERIA!$A$4:$A$15,0),MATCH(VLOOKUP(A16,PROGRAMAS!$A$4:$G$103,7,FALSE()),PRECIOS_TINTORERIA!$B$3:$U$3,0)),0)} -> 0 | Z16: =IFERROR(R16*W16*IF(X16="USD",Y16,1),0) -> 0 | AD16: =IFERROR((SUMIFS(COMPRAS_HILO!$H$4:$H$203,COMPRAS_HILO!$B$4:$B$203,A16))*F16/SUMIFS($F$4:$F$503,$A$4:$A$503,A16),0) -> 5353.4483 | AE16: =M16 -> 0 | AF16: =Z16 -> 0 | AG16: =AD16+AE16+AF16 -> 5353.4483 | AH16: =IFERROR(AG16/S16,0) -> 0
A17: frecnh terry - 001 | B17: Vino | C17: =IFERROR(VLOOKUP(B17,COLORES!$A$4:$B$52,2,FALSE()),"") -> OSCURO | D17: REACTIVO (oscuros) | E17: 20 | F17: 400 | G17: ALTA | J17: =IFERROR(VLOOKUP(VLOOKUP(A17,PROGRAMAS!$A$4:$G$103,7,FALSE()),PRECIOS_TEJEDURIA!$A$4:$B$22,2,FALSE()),0) -> 0.4 | M17: =IFERROR(H17*J17*IF(K17="USD",L17,1),0) -> 0 | U17: =IFERROR(R17-S17,0) -> 0 | V17: =IFERROR(U17/R17,0) -> 0 | W17: {=IFERROR(INDEX(PRECIOS_TINTORERIA!$B$4:$U$15,MATCH(D17,PRECIOS_TINTORERIA!$A$4:$A$15,0),MATCH(VLOOKUP(A17,PROGRAMAS!$A$4:$G$103,7,FALSE()),PRECIOS_TINTORERIA!$B$3:$U$3,0)),0)} -> 0 | Z17: =IFERROR(R17*W17*IF(X17="USD",Y17,1),0) -> 0 | AD17: =IFERROR((SUMIFS(COMPRAS_HILO!$H$4:$H$203,COMPRAS_HILO!$B$4:$B$203,A17))*F17/SUMIFS($F$4:$F$503,$A$4:$A$503,A17),0) -> 4282.7586 | AE17: =M17 -> 0 | AF17: =Z17 -> 0 | AG17: =AD17+AE17+AF17 -> 4282.7586 | AH17: =IFERROR(AG17/S17,0) -> 0
A18: frecnh terry - 001 | B18: Denim | C18: =IFERROR(VLOOKUP(B18,COLORES!$A$4:$B$52,2,FALSE()),"") -> CLARO | D18: DIRECTO (claros) | E18: 10 | F18: 200 | G18: MEDIA | J18: =IFERROR(VLOOKUP(VLOOKUP(A18,PROGRAMAS!$A$4:$G$103,7,FALSE()),PRECIOS_TEJEDURIA!$A$4:$B$22,2,FALSE()),0) -> 0.4 | M18: =IFERROR(H18*J18*IF(K18="USD",L18,1),0) -> 0 | U18: =IFERROR(R18-S18,0) -> 0 | V18: =IFERROR(U18/R18,0) -> 0 | W18: {=IFERROR(INDEX(PRECIOS_TINTORERIA!$B$4:$U$15,MATCH(D18,PRECIOS_TINTORERIA!$A$4:$A$15,0),MATCH(VLOOKUP(A18,PROGRAMAS!$A$4:$G$103,7,FALSE()),PRECIOS_TINTORERIA!$B$3:$U$3,0)),0)} -> 0 | Z18: =IFERROR(R18*W18*IF(X18="USD",Y18,1),0) -> 0 | AD18: =IFERROR((SUMIFS(COMPRAS_HILO!$H$4:$H$203,COMPRAS_HILO!$B$4:$B$203,A18))*F18/SUMIFS($F$4:$F$503,$A$4:$A$503,A18),0) -> 2141.3793 | AE18: =M18 -> 0 | AF18: =Z18 -> 0 | AG18: =AD18+AE18+AF18 -> 2141.3793 | AH18: =IFERROR(AG18/S18,0) -> 0
A19: frecnh terry - 001 | B19: Pacay | C19: =IFERROR(VLOOKUP(B19,COLORES!$A$4:$B$52,2,FALSE()),"") -> CLARO | D19: DIRECTO (claros) | E19: 10 | F19: 200 | G19: MEDIA | J19: =IFERROR(VLOOKUP(VLOOKUP(A19,PROGRAMAS!$A$4:$G$103,7,FALSE()),PRECIOS_TEJEDURIA!$A$4:$B$22,2,FALSE()),0) -> 0.4 | M19: =IFERROR(H19*J19*IF(K19="USD",L19,1),0) -> 0 | U19: =IFERROR(R19-S19,0) -> 0 | V19: =IFERROR(U19/R19,0) -> 0 | W19: {=IFERROR(INDEX(PRECIOS_TINTORERIA!$B$4:$U$15,MATCH(D19,PRECIOS_TINTORERIA!$A$4:$A$15,0),MATCH(VLOOKUP(A19,PROGRAMAS!$A$4:$G$103,7,FALSE()),PRECIOS_TINTORERIA!$B$3:$U$3,0)),0)} -> 0 | Z19: =IFERROR(R19*W19*IF(X19="USD",Y19,1),0) -> 0 | AD19: =IFERROR((SUMIFS(COMPRAS_HILO!$H$4:$H$203,COMPRAS_HILO!$B$4:$B$203,A19))*F19/SUMIFS($F$4:$F$503,$A$4:$A$503,A19),0) -> 2141.3793 | AE19: =M19 -> 0 | AF19: =Z19 -> 0 | AG19: =AD19+AE19+AF19 -> 2141.3793 | AH19: =IFERROR(AG19/S19,0) -> 0
A20: frecnh terry - 001 | B20: Topo | C20: =IFERROR(VLOOKUP(B20,COLORES!$A$4:$B$52,2,FALSE()),"") -> CLARO | D20: DIRECTO (claros) | E20: 10 | F20: 200 | G20: MEDIA | J20: =IFERROR(VLOOKUP(VLOOKUP(A20,PROGRAMAS!$A$4:$G$103,7,FALSE()),PRECIOS_TEJEDURIA!$A$4:$B$22,2,FALSE()),0) -> 0.4 | M20: =IFERROR(H20*J20*IF(K20="USD",L20,1),0) -> 0 | U20: =IFERROR(R20-S20,0) -> 0 | V20: =IFERROR(U20/R20,0) -> 0 | W20: {=IFERROR(INDEX(PRECIOS_TINTORERIA!$B$4:$U$15,MATCH(D20,PRECIOS_TINTORERIA!$A$4:$A$15,0),MATCH(VLOOKUP(A20,PROGRAMAS!$A$4:$G$103,7,FALSE()),PRECIOS_TINTORERIA!$B$3:$U$3,0)),0)} -> 0 | Z20: =IFERROR(R20*W20*IF(X20="USD",Y20,1),0) -> 0 | AD20: =IFERROR((SUMIFS(COMPRAS_HILO!$H$4:$H$203,COMPRAS_HILO!$B$4:$B$203,A20))*F20/SUMIFS($F$4:$F$503,$A$4:$A$503,A20),0) -> 2141.3793 | AE20: =M20 -> 0 | AF20: =Z20 -> 0 | AG20: =AD20+AE20+AF20 -> 2141.3793 | AH20: =IFERROR(AG20/S20,0) -> 0
A21: frecnh terry - 001 | B21: Palo Rosa | C21: =IFERROR(VLOOKUP(B21,COLORES!$A$4:$B$52,2,FALSE()),"") -> CLARO | D21: DIRECTO (claros) | E21: 10 | F21: 200 | G21: MEDIA | J21: =IFERROR(VLOOKUP(VLOOKUP(A21,PROGRAMAS!$A$4:$G$103,7,FALSE()),PRECIOS_TEJEDURIA!$A$4:$B$22,2,FALSE()),0) -> 0.4 | M21: =IFERROR(H21*J21*IF(K21="USD",L21,1),0) -> 0 | U21: =IFERROR(R21-S21,0) -> 0 | V21: =IFERROR(U21/R21,0) -> 0 | W21: {=IFERROR(INDEX(PRECIOS_TINTORERIA!$B$4:$U$15,MATCH(D21,PRECIOS_TINTORERIA!$A$4:$A$15,0),MATCH(VLOOKUP(A21,PROGRAMAS!$A$4:$G$103,7,FALSE()),PRECIOS_TINTORERIA!$B$3:$U$3,0)),0)} -> 0 | Z21: =IFERROR(R21*W21*IF(X21="USD",Y21,1),0) -> 0 | AD21: =IFERROR((SUMIFS(COMPRAS_HILO!$H$4:$H$203,COMPRAS_HILO!$B$4:$B$203,A21))*F21/SUMIFS($F$4:$F$503,$A$4:$A$503,A21),0) -> 2141.3793 | AE21: =M21 -> 0 | AF21: =Z21 -> 0 | AG21: =AD21+AE21+AF21 -> 2141.3793 | AH21: =IFERROR(AG21/S21,0) -> 0
A22: frecnh terry - 001 | B22: Beige | C22: =IFERROR(VLOOKUP(B22,COLORES!$A$4:$B$52,2,FALSE()),"") -> CLARO | D22: DIRECTO (claros) | E22: 10 | F22: 200 | G22: MEDIA | J22: =IFERROR(VLOOKUP(VLOOKUP(A22,PROGRAMAS!$A$4:$G$103,7,FALSE()),PRECIOS_TEJEDURIA!$A$4:$B$22,2,FALSE()),0) -> 0.4 | M22: =IFERROR(H22*J22*IF(K22="USD",L22,1),0) -> 0 | U22: =IFERROR(R22-S22,0) -> 0 | V22: =IFERROR(U22/R22,0) -> 0 | W22: {=IFERROR(INDEX(PRECIOS_TINTORERIA!$B$4:$U$15,MATCH(D22,PRECIOS_TINTORERIA!$A$4:$A$15,0),MATCH(VLOOKUP(A22,PROGRAMAS!$A$4:$G$103,7,FALSE()),PRECIOS_TINTORERIA!$B$3:$U$3,0)),0)} -> 0 | Z22: =IFERROR(R22*W22*IF(X22="USD",Y22,1),0) -> 0 | AD22: =IFERROR((SUMIFS(COMPRAS_HILO!$H$4:$H$203,COMPRAS_HILO!$B$4:$B$203,A22))*F22/SUMIFS($F$4:$F$503,$A$4:$A$503,A22),0) -> 2141.3793 | AE22: =M22 -> 0 | AF22: =Z22 -> 0 | AG22: =AD22+AE22+AF22 -> 2141.3793 | AH22: =IFERROR(AG22/S22,0) -> 0
C23: =IFERROR(VLOOKUP(B23,COLORES!$A$4:$B$52,2,FALSE()),"") | J23: =IFERROR(VLOOKUP(VLOOKUP(A23,PROGRAMAS!$A$4:$G$103,7,FALSE()),PRECIOS_TEJEDURIA!$A$4:$B$22,2,FALSE()),0) -> 0 | M23: =IFERROR(H23*J23*IF(K23="USD",L23,1),0) -> 0 | U23: =IFERROR(R23-S23,0) -> 0 | V23: =IFERROR(U23/R23,0) -> 0 | W23: {=IFERROR(INDEX(PRECIOS_TINTORERIA!$B$4:$U$15,MATCH(D23,PRECIOS_TINTORERIA!$A$4:$A$15,0),MATCH(VLOOKUP(A23,PROGRAMAS!$A$4:$G$103,7,FALSE()),PRECIOS_TINTORERIA!$B$3:$U$3,0)),0)} -> 0 | Z23: =IFERROR(R23*W23*IF(X23="USD",Y23,1),0) -> 0 | AD23: =IFERROR((SUMIFS(COMPRAS_HILO!$H$4:$H$203,COMPRAS_HILO!$B$4:$B$203,A23))*F23/SUMIFS($F$4:$F$503,$A$4:$A$503,A23),0) -> 0 | AE23: =M23 -> 0 | AF23: =Z23 -> 0 | AG23: =AD23+AE23+AF23 -> 0 | AH23: =IFERROR(AG23/S23,0) -> 0
A24: jersey algodon - 001 | B24: Negro | C24: =IFERROR(VLOOKUP(B24,COLORES!$A$4:$B$52,2,FALSE()),"") -> OSCURO | D24: REACTIVO (oscuros) | J24: =IFERROR(VLOOKUP(VLOOKUP(A24,PROGRAMAS!$A$4:$G$103,7,FALSE()),PRECIOS_TEJEDURIA!$A$4:$B$22,2,FALSE()),0) -> 0 | M24: =IFERROR(H24*J24*IF(K24="USD",L24,1),0) -> 0 | U24: =IFERROR(R24-S24,0) -> 0 | V24: =IFERROR(U24/R24,0) -> 0 | W24: {=IFERROR(INDEX(PRECIOS_TINTORERIA!$B$4:$U$15,MATCH(D24,PRECIOS_TINTORERIA!$A$4:$A$15,0),MATCH(VLOOKUP(A24,PROGRAMAS!$A$4:$G$103,7,FALSE()),PRECIOS_TINTORERIA!$B$3:$U$3,0)),0)} -> 0 | Z24: =IFERROR(R24*W24*IF(X24="USD",Y24,1),0) -> 0 | AD24: =IFERROR((SUMIFS(COMPRAS_HILO!$H$4:$H$203,COMPRAS_HILO!$B$4:$B$203,A24))*F24/SUMIFS($F$4:$F$503,$A$4:$A$503,A24),0) -> 0 | AE24: =M24 -> 0 | AF24: =Z24 -> 0 | AG24: =AD24+AE24+AF24 -> 0 | AH24: =IFERROR(AG24/S24,0) -> 0
A25: rib 1x1- jersey algodon -001 | B25: Negro | C25: =IFERROR(VLOOKUP(B25,COLORES!$A$4:$B$52,2,FALSE()),"") -> OSCURO | D25: REACTIVO (oscuros) | J25: =IFERROR(VLOOKUP(VLOOKUP(A25,PROGRAMAS!$A$4:$G$103,7,FALSE()),PRECIOS_TEJEDURIA!$A$4:$B$22,2,FALSE()),0) -> 0.6 | M25: =IFERROR(H25*J25*IF(K25="USD",L25,1),0) -> 0 | U25: =IFERROR(R25-S25,0) -> 0 | V25: =IFERROR(U25/R25,0) -> 0 | W25: {=IFERROR(INDEX(PRECIOS_TINTORERIA!$B$4:$U$15,MATCH(D25,PRECIOS_TINTORERIA!$A$4:$A$15,0),MATCH(VLOOKUP(A25,PROGRAMAS!$A$4:$G$103,7,FALSE()),PRECIOS_TINTORERIA!$B$3:$U$3,0)),0)} -> 3 | Z25: =IFERROR(R25*W25*IF(X25="USD",Y25,1),0) -> 0 | AD25: =IFERROR((SUMIFS(COMPRAS_HILO!$H$4:$H$203,COMPRAS_HILO!$B$4:$B$203,A25))*F25/SUMIFS($F$4:$F$503,$A$4:$A$503,A25),0) -> 0 | AE25: =M25 -> 0 | AF25: =Z25 -> 0 | AG25: =AD25+AE25+AF25 -> 0 | AH25: =IFERROR(AG25/S25,0) -> 0
A26: jersey algodon - 001 | B26: Perla | C26: =IFERROR(VLOOKUP(B26,COLORES!$A$4:$B$52,2,FALSE()),"") -> PPT | D26: REACTIVO (oscuros) | J26: =IFERROR(VLOOKUP(VLOOKUP(A26,PROGRAMAS!$A$4:$G$103,7,FALSE()),PRECIOS_TEJEDURIA!$A$4:$B$22,2,FALSE()),0) -> 0 | M26: =IFERROR(H26*J26*IF(K26="USD",L26,1),0) -> 0 | U26: =IFERROR(R26-S26,0) -> 0 | V26: =IFERROR(U26/R26,0) -> 0 | W26: {=IFERROR(INDEX(PRECIOS_TINTORERIA!$B$4:$U$15,MATCH(D26,PRECIOS_TINTORERIA!$A$4:$A$15,0),MATCH(VLOOKUP(A26,PROGRAMAS!$A$4:$G$103,7,FALSE()),PRECIOS_TINTORERIA!$B$3:$U$3,0)),0)} -> 0 | Z26: =IFERROR(R26*W26*IF(X26="USD",Y26,1),0) -> 0 | AD26: =IFERROR((SUMIFS(COMPRAS_HILO!$H$4:$H$203,COMPRAS_HILO!$B$4:$B$203,A26))*F26/SUMIFS($F$4:$F$503,$A$4:$A$503,A26),0) -> 0 | AE26: =M26 -> 0 | AF26: =Z26 -> 0 | AG26: =AD26+AE26+AF26 -> 0 | AH26: =IFERROR(AG26/S26,0) -> 0
A27: rib 1x1- jersey algodon -001 | B27: Perla | C27: =IFERROR(VLOOKUP(B27,COLORES!$A$4:$B$52,2,FALSE()),"") -> PPT | D27: REACTIVO (oscuros) | J27: =IFERROR(VLOOKUP(VLOOKUP(A27,PROGRAMAS!$A$4:$G$103,7,FALSE()),PRECIOS_TEJEDURIA!$A$4:$B$22,2,FALSE()),0) -> 0.6 | M27: =IFERROR(H27*J27*IF(K27="USD",L27,1),0) -> 0 | U27: =IFERROR(R27-S27,0) -> 0 | V27: =IFERROR(U27/R27,0) -> 0 | W27: {=IFERROR(INDEX(PRECIOS_TINTORERIA!$B$4:$U$15,MATCH(D27,PRECIOS_TINTORERIA!$A$4:$A$15,0),MATCH(VLOOKUP(A27,PROGRAMAS!$A$4:$G$103,7,FALSE()),PRECIOS_TINTORERIA!$B$3:$U$3,0)),0)} -> 3 | Z27: =IFERROR(R27*W27*IF(X27="USD",Y27,1),0) -> 0 | AD27: =IFERROR((SUMIFS(COMPRAS_HILO!$H$4:$H$203,COMPRAS_HILO!$B$4:$B$203,A27))*F27/SUMIFS($F$4:$F$503,$A$4:$A$503,A27),0) -> 0 | AE27: =M27 -> 0 | AF27: =Z27 -> 0 | AG27: =AD27+AE27+AF27 -> 0 | AH27: =IFERROR(AG27/S27,0) -> 0
A28: jersey algodon - 001 | B28: Beige | C28: =IFERROR(VLOOKUP(B28,COLORES!$A$4:$B$52,2,FALSE()),"") -> CLARO | J28: =IFERROR(VLOOKUP(VLOOKUP(A28,PROGRAMAS!$A$4:$G$103,7,FALSE()),PRECIOS_TEJEDURIA!$A$4:$B$22,2,FALSE()),0) -> 0 | M28: =IFERROR(H28*J28*IF(K28="USD",L28,1),0) -> 0 | U28: =IFERROR(R28-S28,0) -> 0 | V28: =IFERROR(U28/R28,0) -> 0 | W28: {=IFERROR(INDEX(PRECIOS_TINTORERIA!$B$4:$U$15,MATCH(D28,PRECIOS_TINTORERIA!$A$4:$A$15,0),MATCH(VLOOKUP(A28,PROGRAMAS!$A$4:$G$103,7,FALSE()),PRECIOS_TINTORERIA!$B$3:$U$3,0)),0)} -> 0 | Z28: =IFERROR(R28*W28*IF(X28="USD",Y28,1),0) -> 0 | AD28: =IFERROR((SUMIFS(COMPRAS_HILO!$H$4:$H$203,COMPRAS_HILO!$B$4:$B$203,A28))*F28/SUMIFS($F$4:$F$503,$A$4:$A$503,A28),0) -> 0 | AE28: =M28 -> 0 | AF28: =Z28 -> 0 | AG28: =AD28+AE28+AF28 -> 0 | AH28: =IFERROR(AG28/S28,0) -> 0
A29: rib 1x1- jersey algodon -001 | B29: Beige | C29: =IFERROR(VLOOKUP(B29,COLORES!$A$4:$B$52,2,FALSE()),"") -> CLARO | J29: =IFERROR(VLOOKUP(VLOOKUP(A29,PROGRAMAS!$A$4:$G$103,7,FALSE()),PRECIOS_TEJEDURIA!$A$4:$B$22,2,FALSE()),0) -> 0.6 | M29: =IFERROR(H29*J29*IF(K29="USD",L29,1),0) -> 0 | U29: =IFERROR(R29-S29,0) -> 0 | V29: =IFERROR(U29/R29,0) -> 0 | W29: {=IFERROR(INDEX(PRECIOS_TINTORERIA!$B$4:$U$15,MATCH(D29,PRECIOS_TINTORERIA!$A$4:$A$15,0),MATCH(VLOOKUP(A29,PROGRAMAS!$A$4:$G$103,7,FALSE()),PRECIOS_TINTORERIA!$B$3:$U$3,0)),0)} -> 0 | Z29: =IFERROR(R29*W29*IF(X29="USD",Y29,1),0) -> 0 | AD29: =IFERROR((SUMIFS(COMPRAS_HILO!$H$4:$H$203,COMPRAS_HILO!$B$4:$B$203,A29))*F29/SUMIFS($F$4:$F$503,$A$4:$A$503,A29),0) -> 0 | AE29: =M29 -> 0 | AF29: =Z29 -> 0 | AG29: =AD29+AE29+AF29 -> 0 | AH29: =IFERROR(AG29/S29,0) -> 0
A30: jersey algodon - 001 | B30: Acero | C30: =IFERROR(VLOOKUP(B30,COLORES!$A$4:$B$52,2,FALSE()),"") -> OSCURO | J30: =IFERROR(VLOOKUP(VLOOKUP(A30,PROGRAMAS!$A$4:$G$103,7,FALSE()),PRECIOS_TEJEDURIA!$A$4:$B$22,2,FALSE()),0) -> 0 | M30: =IFERROR(H30*J30*IF(K30="USD",L30,1),0) -> 0 | U30: =IFERROR(R30-S30,0) -> 0 | V30: =IFERROR(U30/R30,0) -> 0 | W30: {=IFERROR(INDEX(PRECIOS_TINTORERIA!$B$4:$U$15,MATCH(D30,PRECIOS_TINTORERIA!$A$4:$A$15,0),MATCH(VLOOKUP(A30,PROGRAMAS!$A$4:$G$103,7,FALSE()),PRECIOS_TINTORERIA!$B$3:$U$3,0)),0)} -> 0 | Z30: =IFERROR(R30*W30*IF(X30="USD",Y30,1),0) -> 0 | AD30: =IFERROR((SUMIFS(COMPRAS_HILO!$H$4:$H$203,COMPRAS_HILO!$B$4:$B$203,A30))*F30/SUMIFS($F$4:$F$503,$A$4:$A$503,A30),0) -> 0 | AE30: =M30 -> 0 | AF30: =Z30 -> 0 | AG30: =AD30+AE30+AF30 -> 0 | AH30: =IFERROR(AG30/S30,0) -> 0
A31: rib 1x1- jersey algodon -001 | B31: Acero | C31: =IFERROR(VLOOKUP(B31,COLORES!$A$4:$B$52,2,FALSE()),"") -> OSCURO | J31: =IFERROR(VLOOKUP(VLOOKUP(A31,PROGRAMAS!$A$4:$G$103,7,FALSE()),PRECIOS_TEJEDURIA!$A$4:$B$22,2,FALSE()),0) -> 0.6 | M31: =IFERROR(H31*J31*IF(K31="USD",L31,1),0) -> 0 | U31: =IFERROR(R31-S31,0) -> 0 | V31: =IFERROR(U31/R31,0) -> 0 | W31: {=IFERROR(INDEX(PRECIOS_TINTORERIA!$B$4:$U$15,MATCH(D31,PRECIOS_TINTORERIA!$A$4:$A$15,0),MATCH(VLOOKUP(A31,PROGRAMAS!$A$4:$G$103,7,FALSE()),PRECIOS_TINTORERIA!$B$3:$U$3,0)),0)} -> 0 | Z31: =IFERROR(R31*W31*IF(X31="USD",Y31,1),0) -> 0 | AD31: =IFERROR((SUMIFS(COMPRAS_HILO!$H$4:$H$203,COMPRAS_HILO!$B$4:$B$203,A31))*F31/SUMIFS($F$4:$F$503,$A$4:$A$503,A31),0) -> 0 | AE31: =M31 -> 0 | AF31: =Z31 -> 0 | AG31: =AD31+AE31+AF31 -> 0 | AH31: =IFERROR(AG31/S31,0) -> 0
C32: =IFERROR(VLOOKUP(B32,COLORES!$A$4:$B$52,2,FALSE()),"") | J32: =IFERROR(VLOOKUP(VLOOKUP(A32,PROGRAMAS!$A$4:$G$103,7,FALSE()),PRECIOS_TEJEDURIA!$A$4:$B$22,2,FALSE()),0) -> 0 | M32: =IFERROR(H32*J32*IF(K32="USD",L32,1),0) -> 0 | U32: =IFERROR(R32-S32,0) -> 0 | V32: =IFERROR(U32/R32,0) -> 0 | W32: {=IFERROR(INDEX(PRECIOS_TINTORERIA!$B$4:$U$15,MATCH(D32,PRECIOS_TINTORERIA!$A$4:$A$15,0),MATCH(VLOOKUP(A32,PROGRAMAS!$A$4:$G$103,7,FALSE()),PRECIOS_TINTORERIA!$B$3:$U$3,0)),0)} -> 0 | Z32: =IFERROR(R32*W32*IF(X32="USD",Y32,1),0) -> 0 | AD32: =IFERROR((SUMIFS(COMPRAS_HILO!$H$4:$H$203,COMPRAS_HILO!$B$4:$B$203,A32))*F32/SUMIFS($F$4:$F$503,$A$4:$A$503,A32),0) -> 0 | AE32: =M32 -> 0 | AF32: =Z32 -> 0 | AG32: =AD32+AE32+AF32 -> 0 | AH32: =IFERROR(AG32/S32,0) -> 0
C33: =IFERROR(VLOOKUP(B33,COLORES!$A$4:$B$52,2,FALSE()),"") | J33: =IFERROR(VLOOKUP(VLOOKUP(A33,PROGRAMAS!$A$4:$G$103,7,FALSE()),PRECIOS_TEJEDURIA!$A$4:$B$22,2,FALSE()),0) -> 0 | M33: =IFERROR(H33*J33*IF(K33="USD",L33,1),0) -> 0 | U33: =IFERROR(R33-S33,0) -> 0 | V33: =IFERROR(U33/R33,0) -> 0 | W33: {=IFERROR(INDEX(PRECIOS_TINTORERIA!$B$4:$U$15,MATCH(D33,PRECIOS_TINTORERIA!$A$4:$A$15,0),MATCH(VLOOKUP(A33,PROGRAMAS!$A$4:$G$103,7,FALSE()),PRECIOS_TINTORERIA!$B$3:$U$3,0)),0)} -> 0 | Z33: =IFERROR(R33*W33*IF(X33="USD",Y33,1),0) -> 0 | AD33: =IFERROR((SUMIFS(COMPRAS_HILO!$H$4:$H$203,COMPRAS_HILO!$B$4:$B$203,A33))*F33/SUMIFS($F$4:$F$503,$A$4:$A$503,A33),0) -> 0 | AE33: =M33 -> 0 | AF33: =Z33 -> 0 | AG33: =AD33+AE33+AF33 -> 0 | AH33: =IFERROR(AG33/S33,0) -> 0
C34: =IFERROR(VLOOKUP(B34,COLORES!$A$4:$B$52,2,FALSE()),"") | J34: =IFERROR(VLOOKUP(VLOOKUP(A34,PROGRAMAS!$A$4:$G$103,7,FALSE()),PRECIOS_TEJEDURIA!$A$4:$B$22,2,FALSE()),0) -> 0 | M34: =IFERROR(H34*J34*IF(K34="USD",L34,1),0) -> 0 | U34: =IFERROR(R34-S34,0) -> 0 | V34: =IFERROR(U34/R34,0) -> 0 | W34: {=IFERROR(INDEX(PRECIOS_TINTORERIA!$B$4:$U$15,MATCH(D34,PRECIOS_TINTORERIA!$A$4:$A$15,0),MATCH(VLOOKUP(A34,PROGRAMAS!$A$4:$G$103,7,FALSE()),PRECIOS_TINTORERIA!$B$3:$U$3,0)),0)} -> 0 | Z34: =IFERROR(R34*W34*IF(X34="USD",Y34,1),0) -> 0 | AD34: =IFERROR((SUMIFS(COMPRAS_HILO!$H$4:$H$203,COMPRAS_HILO!$B$4:$B$203,A34))*F34/SUMIFS($F$4:$F$503,$A$4:$A$503,A34),0) -> 0 | AE34: =M34 -> 0 | AF34: =Z34 -> 0 | AG34: =AD34+AE34+AF34 -> 0 | AH34: =IFERROR(AG34/S34,0) -> 0
